Workbook
Name CT5_: 系数参数!$M$2:$M$11
Name CT6_: 系数参数!$N$2:$N$8
Name XT4_: 系数参数!$P$2:$P$8
Name XT6_: 系数参数!$Q$2:$Q$12
Name 车系: 系数参数!$L$2:$L$6
Name 车系1: 系数参数!$K$2:$K$7
Name 车系参数: '[1]参数-车系车型 利率'!$P$2:$P$8
Name 车系参数: '[1]参数-车系车型 利率'!$P$2:$P$8
Name 车系参数: '[1]参数-车系车型 利率'!$P$2:$P$8
Name 阶梯贷车系参数: '[1]参数-车系车型 利率'!$I$2:$I$6
Name 阶梯贷车系参数: '[1]参数-车系车型 利率'!$I$2:$I$5
Name 阶梯贷车系参数: '[1]参数-车系车型 利率'!$I$2:$I$5
Name 全新XT5: 系数参数!$O$2:$O$5
Name 新CT6_: 系数参数!$R$2:$R$4

Sheet 试算路径及方案简述
B9: 注：1）本试算工具仅供试算参考，因精度问题客户月供及利息与实际情况可能存在差异，请以《汽车（抵押）贷款合同》所附的《还款计划表》为准； 2）在提交申请和签约时，请注意比对申请系统与试算表的方案名称，以免因选错方案导致最终还款金额与试算金额出现较大差异。
C13: 厂贴方案说明 | J13: 非厂贴方案
C14: 厂贴方案 有效期 | D14: 厂贴车型 | F14: 厂贴方案简述 | G14: 试算页链接 | H14: 合同年化利率 | J14: 方案有效期 | K14: 适用车系 | L14: 非厂贴试算页链接 | M14: 说明 | N14: 合同 年化利率
C15: 申请截止至：2026/4/30 放款截止至：2026/5/31 | D15: CT5、CT6、 全新XT5、 XT4、XT6 | E15: 具体车型详见 ‘厂贴车型明细’ | F15: 0首付常规低息(12期/24期) 常规低息 (24-60期) 0.99% 12万定额贷(12期） 1.99% 8万定额贷(24期） 5050智慧贷(12期） 20%/30%首付 智慧式(36期） 双优贷2.0(60期) | G15: 厂贴_常规贴息(燃油车） | H15: 常规 5.99% 5050智慧贷 5.99% 36期智慧式 5.99% 双优贷2.0 11.60% | J15: 申请截止至：2026/4/30 放款截止至：2026/5/31 | K15: 凯迪拉克品牌 所有新车 （具体请以系统设置为准） | L15: 新通用-非厂商贴息 | M15: 不支持经销商贴息 | N15: 0.0898
L16: 新通用-经销商贴息 | M16: 经销商贴息100元起
G17: 厂贴_双优贷2.0 | L17: 双优贷-非厂商贴息 | M17: 不支持经销商贴息 | N17: 0.097
D18: 新CT6 | F18: 0首付常规低息(12期/24期) 常规低息 (24-60期) 0.99% 10万定额贷(24期） 5050智慧贷(12期） 20%/30%首付 智慧式(36期） 双优贷2.0(60期) | G18: 厂贴_常规贴息(新CT6） | H18: 常规 5.99% 5050智慧贷 5.99% 36期智慧式 5.99% 双优贷2.0 11.60% | L18: 双优贷-经销商贴息 | M18: 经销商贴息100元起
G19: 厂贴_双优贷2.0 | K19: 仅适用于不享受厂家贴息政策的车型 以及 傲歌 （具体请以系统设置为准） | L19: 双优贷2.0-非厂商贴息 | M19: 不支持经销商贴息 | N19: 0.116
D20: 傲歌 | E20: 四驱长续航版 纯电动 新能源 / 标准续航版 纯电动 新能源 | F20: 常规低息 (24-60期) 5050智慧贷(12期） | G20: 厂贴_常规贴息（新能源） | H20: 常规 5.99% 5050智慧贷 5.99% | L20: 双优贷2.0-经销商贴息 | M20: 经销商贴息100元起
C23: 参考链接 | D23: 厂贴车型明细&贷款金额说明
D24: 产品基础参数&准入政策
D25: 新能源首付低于20%时 最高贷款金额测算

Sheet 厂贴车型明细&贷款金额说明
C1: 返回
B2: 注意： 1、请注意E速通系统所选车型与DOSS系统上报车型配置、年款、指导价保持一致，尤其要注意区分新旧款车型（如贴息政策不一致），若因车型配置不一致导致超出厂商贴息上限的情况，需由经销商承担，将从其他客户放款金额中扣除，后续会开具经销商贴息发票；（贴息车型配置请参考“车型明细”） 2、对于凯迪拉克厂商端下线的经销商，以及特殊折扣车辆（如试驾车、集团采购车辆等）不享受厂商贴息支持； 3、贴息方式：厂商直接贴息（无需经销商承担贴息费用，不扣减放款金额），关于具体的贴息结算，请以厂商公告为准或者与区域营销中心MAC进行确认
I8: 常规低息贷 （个人&公户） | N8: 0首付低息贷 （个人） | P8: 定额贷 （个人） | R8: 5050 （个人） | S8: 智慧贷 （个人） | T8: 双优贷2.0 （个人）
C9: 厂家车系 | D9: 厂家车型配置 | E9: E速通系统车型名称 | F9: 市场指导价 | H9: 车系 | I9: 60期 贷款金额下限 | J9: 48期 贷款金额下限 | K9: 36期 贷款金额下限 | L9: 24期 贷款金额下限 | M9: 12期 贷款金额下限 | N9: 24期 贷款金额下限 | O9: 12期 贷款金额下限 | P9: 12期 贷款金额 | Q9: 24期 贷款金额 | R9: 12期 贷款金额下限 | S9: 36期 贷款金额下限 | T9: 60期 贷款金额下限
B10: 新款CT5 | C10: CT5 MCM MY25 | D10: 28T 城市风尚版 | E10: 全新CT5 城市风尚版 | F10: 289900 | H10: 全新CT5 | I10: 30000 | J10: 30000 | K10: 30000 | L10: 30000 | M10: 30000 | N10: 30000 | O10: 150000 | P10: 120000 | Q10: 80000 | R10: 30000 | S10: 30000 | T10: 50000
C11: CT5 MCM MY25 | D11: 28T 城市运动版 | E11: 全新CT5 城市运动版 | F11: 299900 | H11: 全新XT5
E12: 全新CT5 28T 尊贵型 | F12: 320700 | H12: 全新XT6
C13: CT5 MCM MY25 | D13: 28T 赛道性能版 | E13: 全新CT5 赛道性能版 | F13: 320900 | H13: CT6
C14: CT5 MCM MY25 | D14: 28T 赛道性能版+巅峰赛道选装包 | E14: 全新CT5 赛道性能版 巅峰赛道选装包 | F14: 345900 | H14: XT4
B15: 新款XT5 | C15: 全新XT5 | E15: 全新XT5 大都会型 | F15: 379900 | H15: CT5
C16: 全新XT5 | D16: 28T 豪华型 | E16: 全新XT5 四驱豪华版 | F16: 399900 | H16: XT6
C17: 全新XT5 | D17: 28T 尊贵型 | E17: 全新XT5 四驱尊贵版 | F17: 419900 | H17: 新CT6 | I17: 30000 | J17: 30000 | K17: 30000 | L17: 30000 | N17: 30000 | O17: 150000 | P17: 无方案 | Q17: 100000 | R17: 30000 | S17: 30000 | T17: 50000
C18: 全新XT5 | D18: 28T 铂金型 | E18: 全新XT5 四驱铂金版 | F18: 459900 | H18: 傲歌 | I18: 30000 | J18: 30000 | K18: 30000 | L18: 30000 | M18: 30000 | N18: 无方案 | O18: 无方案 | P18: 无方案 | Q18: 无方案 | R18: 30000 | S18: 无方案 | T18: 无方案
B19: 新款XT6 | C19: XT6 | D19: 28T 豪华行政经典版 | E19: 新XT6 豪华行政经典版 | F19: 449900
C20: XT6 | D20: 28T 尊贵行政黑标版 | E20: 新XT6 尊贵行政黑标版 | F20: 469900
C21: XT6 | D21: 28T 铂金行政黑标版 | E21: 新XT6 铂金行政黑标版 | F21: 509900
B22: 新CT6 | C22: 新CT6（MY23.6） | D22: 28T 臻享版 | E22: 新CT6 28T 臻享版 | F22: 369900
C23: 新CT6（MY23.6） | D23: 28T 奢享版 | E23: 新CT6 28T 奢享版 | F23: 399900
C24: 新CT6（MY23.6） | D24: 28T 旗舰版 | E24: 新CT6 28T 旗舰版 | F24: 429900
B25: CT6 | C25: NG CT6 | D25: 28T 风尚型 | E25: 全新CT6 28T 风尚型 | F25: 359700
C26: NG CT6 | D26: 28T 豪华型 | E26: 全新CT6 28T 豪华型 | F26: 389700
C27: NG CT6 | D27: 28T 豪华型 SC | E27: 全新CT6 28T 豪华型(SC版) | F27: 409700
C28: NG CT6 | D28: 28T 尊贵型 | E28: 全新CT6 28T 尊贵型 | F28: 409700
C29: NG CT6 | D29: 28T 尊贵型 SC | E29: 全新CT6 28T 尊贵型Super Cruise版 | F29: 429700
C30: NG CT6 | D30: 28T 铂金型 | E30: 全新CT6 28T 铂金型 | F30: 469700
C31: NG CT6 | D31: 28T 铂金型 SC | E31: 全新CT6 28T 铂金型Super Cruise版 | F31: 489700
B32: XT4 | C32: XT4 MCM | D32: 1.5T Comfort FWD (w/o Sunroof) | E32: XT4 1.5T Comfort 前驱 | F32: 223700
C33: XT4 MCM | D33: 1.5T Lux FWD | E33: XT4 1.5T Lux 前驱 | F33: 252700
C34: XT4 MCM | D34: 2.0T Lux FWD (w/o AKG) | E34: XT4 2.0T Lux 前驱 | F34: 257700
C35: XT4 MCM | D35: 28T 两驱豪华型 | E35: XT4 豪华型 2025年款 | F35: 262700
C36: XT4 MCM | D36: 28T 两驱尊贵型 | E36: XT4 尊贵型 2025年款 | F36: 275700
E37: XT4智驭尊贵型 | F37: 275700
C38: XT4 MCM | D38: 2.0T Sport AWD | E38: XT4 2.0T Sport 四驱 | F38: 286700
B39: 老款CT5 | C39: CT5 MCM MY24 | D39: 1.5T Fashion | E39: CT5 MY24 1.5T Fashion | F39: 269700
C40: CT5 MCM MY24 | D40: 2.0T Fashion | E40: CT5 MY24 2.0T Fashion | F40: 289700
C41: CT5 MCM MY24 | D41: 2.0T Elite | E41: CT5 MY24 2.0T Elite | F41: 299700
C42: CT5 MCM MY24 | D42: 2.0T Luxury (18 inch) | E42: CT5 MY24 2.0T Luxury (18 inch) | F42: 320700
C43: CT5 MCM MY24 | D43: 2.0T Premium (19 inch) | E43: CT5 MY24 2.0T Premium (19 inch) | F43: 341700
C44: CT5 MCM MY24 | D44: 2.0T Prem+Super Cruise 19”&Recorder | E44: CT5 MY24 2.0T Prem Super Cruise 19inch Recorder | F44: 361700
B45: 老款XT6 | C45: XT6 | D45: FWD Lux (6/7 Seats) | E45: XT6 前驱 Lux | F45: 429900
...

Sheet 系数参数
K1: 车系1 | L1: 车系 | M1: CT5 | N1: CT6 | O1: 全新XT5 | P1: XT4 | Q1: XT6 | R1: 新CT6
A2: 合同利率 | B2: 0.0599 | F2: 合同利率 | G2: 0.0599 | H2: 傲歌 | K2: 新CT6_ | L2: CT5_ | M2: 全新CT5 城市风尚版 | N2: 全新CT6 28T 风尚型 | O2: 全新XT5 大都会型 | P2: XT4 1.5T Comfort 前驱 | Q2: 新XT6 豪华行政经典版 | R2: 新CT6 28T 臻享版
A3: 方案类型 | B3: 期限 | C3: 客户利率 | D3: 厂贴系数 | F3: 方案类型 | G3: 期限 | H3: 客户利率 | I3: 厂贴系数 | K3: CT5_ | L3: CT6_ | M3: 全新CT5 城市运动版 | N3: 全新CT6 28T 豪华型 | O3: 全新XT5 四驱豪华版 | P3: XT4 1.5T Lux 前驱 | Q3: 新XT6 尊贵行政黑标版 | R3: 新CT6 28T 奢享版
A4: 首付20%起 | B4: 60期 | C4: 0.0529 | D4: 0.019427 | F4: 首付15%起 | G4: 60期 | H4: 0.0588 | I4: 0.003067 | K4: CT6_ | L4: 全新XT5 | M4: 全新CT5 赛道性能版 | N4: 全新CT6 28T 豪华型(SC版) | O4: 全新XT5 四驱尊贵版 | P4: XT4 2.0T Lux 前驱 | Q4: 新XT6 铂金行政黑标版 | R4: 新CT6 28T 旗舰版
B5: 48期 | C5: 0.0499 | D5: 0.021873 | G5: 48期 | H5: 0.0588 | I5: 0.002419 | K5: 全新XT5 | L5: XT4_ | M5: 全新CT5 赛道性能版 巅峰赛道选装包 | N5: 全新CT6 28T 尊贵型 | O5: 全新XT5 四驱铂金版 | P5: XT4 豪华型 2025年款 | Q5: XT6 前驱 Lux
B6: 36期 | C6: 0.0499 | D6: 0.016236 | G6: 36期 | H6: 0.0588 | I6: 0.001794 | K6: XT4_ | L6: XT6_ | M6: CT5 MY24 1.5T Fashion | N6: 全新CT6 28T 尊贵型Super Cruise版 | P6: XT4 尊贵型 2025年款 | Q6: XT6 前驱 Lux
B7: 24期 | C7: 0.0399 | D7: 0.021496 | G7: 24期 | H7: 0.0588 | I7: 0.00119 | K7: XT6_ | M7: CT5 MY24 2.0T Fashion | N7: 全新CT6 28T 铂金型 | P7: XT4智驭尊贵型 | Q7: XT6 四驱 Lux
B8: 12期 | C8: 0.0299 | G8: 12期 | H8: 0.0588 | M8: CT5 MY24 2.0T Elite | N8: 全新CT6 28T 铂金型Super Cruise版 | P8: XT4 2.0T Sport 四驱 | Q8: XT6 四驱 Lux
A9: 5050 | B9: 1-11期 | C9: 0.0299 | D9: 0.03 | F9: 5050 | G9: 12期 | H9: 0.0599 | I9: 0.0011 | M9: CT5 MY24 2.0T Luxury (18 inch) | Q9: XT6 四驱 Lux sport
A10: 智慧式36期 | B10: 0.2 | C10: 0.0588 | D10: 0.002359 | M10: CT5 MY24 2.0T Premium (19 inch) | Q10: XT6 四驱 Lux sport
B11: 0.3 | C11: 0.0588 | D11: 0.002439 | M11: CT5 MY24 2.0T Prem Super Cruise 19inch Recorder | Q11: XT6 四驱 Plati sport
A12: 双优贷 | B12: 60期 | C12: 0.11 | D12: 0.018026 | Q12: XT6 四驱 Plati sport Super Cruise
A14: 方案类型 | B14: 期限 | C14: 客户利率 | D14: 厂贴金额
A15: 12万定额 | B15: 12期 | C15: 0.0099 | D15: 3285
A16: 10万定额 | B16: 24期 | C16: 0.0099 | D16: 5324.15
A17: 8万定额 | B17: 24期 | C17: 0.0199 | D17: 3418.05
A19: 合同利率 | B19: 0.0599
A20: 20%以下首付比例 | B20: 24期 | C20: 0.0399 | D20: 0.021495
B21: 12期 | C21: 0.0299 | D21: 0.016472

Sheet 厂贴_1+4阶梯贷
J1: 返回
A2: 第一步：修改贷款参数
A3: 车系 | B3: 全新XT5
A4: 车型 | B4: 全新XT5 大都会型
A5: 市场指导价(MSRP) | B5: =VLOOKUP(B4,'厂贴车型明细&贷款金额说明'!E9:F62,2,0) -> 379900
A6: 车辆开票价(TP)* | B6: 265900 | F6: 说明： 1、表格中蓝底白字的单元格，为可修改项。可直接输入或从下拉菜单中进行选择。 2、系统录入选择贷款方案时，注意选择带有“方案名称关键字”的方案名称 3、1+4阶梯贷方案不支持附加品贷
A8: 总价 | B8: =B6+B7 -> 265900
A9: (固定)贷款金额* | B9: 80000
A12: 第二步：查看试算结果
A13: 贷款方案 | B13: 首付金额 | C13: 首付比例
A14: 首年0息 （定额1+4阶梯贷） | B14: =B6-B9 -> 185900 | C14: =B14/B6 -> 0.69913501 | M14: 提前还款测算参考：
B15: 期限 | C15: 客户试算月供 | D15: 客户试算 总利息 | E15: 客户试算 年化利率 | F15: 客户试算 年化费率 | G15: 客户试算 总费率 | H15: 合同综合 年化利率 | I15: 厂商贴息 金额参考 | J15: 系统方案名称关键字 | L15: 提前还款期数 | M15: 12 | O15: 还满12期免提前还款手续费
B16: 1-12期 | C16: =PMT(0%/12,12,-B9*4.48%) -> 298.66667 | D16: 0 | E16: 0 | F16: 0 | G16: 0 | H16: 0.0523 | I16: 6254.8 | J16: 个人申请：厂贴_常规贴息_60期8万定额贷_1+4阶梯贷_凯迪油车 | L16: 剩余本金 | M16: =IF(M15<13,B9-C16*M15,B9-(C17*(M15-12)+C16*12-M18)) -> 76416
B17: 13-60期 | C17: =ROUNDUP(PMT(7.98%/12,48,-(B9-C16*12)),2) -> 1864.83 | D17: =C17*48-(B9-C16*12) -> 13095.84 | E17: =RATE(48,-C17,B9-(C16*12))*12 -> 0.079802632 | F17: =D17/(B9-C16*12)/4 -> 0.042843907 | G17: =D17/(B9-C16*12) -> 0.17137563 | L17: 可节省利息 | M17: =D17-M18 -> 13095.84
J18: 注：通过小管家报单的申请，请先任选一个方案提交到E速通后，修改为“1+4阶梯贷”方案再正式发送申请 | L18: 已还利息 | M18: =IF(M15<13,0,(B9*(E17/12)-C17)*((1+(E17/12))^(M15-12)-1)/(E17/12)+(C17)*(M15-12)) -> 0

Sheet 厂贴_双优贷2.0
J1: 返回
A2: 第一步：修改贷款参数
A3: 车系 | B3: 新CT6_
A4: 车型 | B4: 新CT6 28T 奢享版
A5: 市场指导价(MSRP) | B5: =VLOOKUP(B4,'厂贴车型明细&贷款金额说明'!E9:F62,2,0) -> 399900
A6: 车辆开票价(TP)* | B6: 280000 | F6: 说明： 1、表格中蓝底白字的单元格，为可修改项。可直接输入或从下拉菜单中进行选择。 2、当“贷款金额下限”或“贷款金额上限数值项变为 红字且黄色高亮时，需调整第7行“贷款金额”输入的数值 3、系统录入选择贷款方案时，注意选择带有“方案名称关键字”的方案名称 4、双优贷方案仅可附加购置税及保险费
A7: 附加品金额* （仅限购置税&保费） | B7: 0
A8: 总价 | B8: =B6+B7 -> 280000 | D8: 注：总价不得超过车辆市场指导价*115%
A9: 贷款金额* | B9: 100000
A12: 第二步：查看试算结果
A13: 贷款方案 | B13: 首付比例 | C13: 首付金额 | D13: 首付比例不得低于： | E13: 0.2
A14: 双优贷2.0 （等额本息类） | B14: =C14/B8 -> 0.64285714 | C14: =B8-B9 -> 180000 | M14: 60期提前还款测算参考：
B15: 期限 | C15: 客户试算月供 | D15: 客户试算 总利息 | E15: 客户试算 年化利率 | F15: 客户试算 年化费率 | G15: 客户试算 总费率 | H15: 厂商贴息 金额参考 | I15: 贷款金额 下限 | J15: 系统方案名称关键字 | L15: 提前还款期数 | M15: 12 | O15: 还满30期免提前还款手续费
B16: 60期 | C16: =PMT(E16/12,60,-B9) -> 2174.741 | D16: =C16*60-B9 -> 30484.463 | E16: =ROUNDUP(RATE(60,-C17,B9)*12,4) -> 0.1101 | F16: =D16/B9/5 -> 0.060968926 | G16: =D16/$B$9 -> 0.30484463 | H16: =$B$9*VLOOKUP(B16,系数参数!$B$12:$D$12,3,0) -> 1802.6 | I16: 50000 | J16: 个人申请：厂贴_新双优贷2.0_新优速贷_60期11%_凯迪油车 | L16: 剩余本金 | M16: =B9-(C16*M15-M18) -> 84128.014
C17: =ROUNDUP(PMT(11.6%/12,60,-$B$9)-H16/60,2) -> 2174.25 | L17: 可节省利息 | M17: =D16-M18 -> 20259.557
L18: 已还利息 | M18: =(B9*(E16/12)-C16)*((1+(E16/12))^(M15)-1)/(E16/12)+(C16)*M15 -> 10224.906

Sheet 厂贴_常规贴息（新CT6）
J1: 返回
A2: 第一步：修改贷款参数
A3: 车系 | B3: 新CT6
A4: 车型 | B4: 新CT6 28T 奢享版
A5: 市场指导价(MSRP) | B5: =VLOOKUP(B4,'厂贴车型明细&贷款金额说明'!E9:F62,2,0) -> 399900
A6: 车辆开票价(TP)* | B6: 265900 | F6: 说明： 1、表格中蓝底白字的单元格，为可修改项。可直接输入或从下拉菜单中进行选择。 2、系统录入选择贷款方案时，注意选择带有“方案名称关键字”的方案名称 3、"0首付”方案不支持附加品贷
A7: 附加品金额 | B7: 0
A8: 总价 | B8: =B6+B7 -> 265900 | D8: 注：总价不得超过车辆市场指导价*115%
A9: 贷款金额* | B9: 200000
A12: 第二步：查看试算结果
A13: 贷款方案-1 | B13: 首付比例 | C13: 首付金额 | D13: 首付比例不得低于： | E13: 0.2
A14: 低首付低利率 （等额本息类） | B14: =C14/B8 -> 0.24783753 | C14: =B8-B9 -> 65900 | D14: 注：公牌/个体户类 首付30%起 | M14: 60期提前还款测算参考：
B15: 期限 | C15: 客户试算月供 | D15: 客户试算 总利息 | E15: 客户试算 年化利率 | F15: 客户试算 年化费率 | G15: 客户试算 总费率 | H15: 厂商贴息 金额参考 | I15: 贷款金额 下限 | J15: 系统方案名称关键字 | L15: 提前还款期数 | M15: 24 | O15: 还满24期免提前还款手续费
B16: 60期 | C16: =ROUNDUP(PMT(系数参数!B2/12,60,-$B$9)-H16/60,2) -> 3800.88 | D16: =C16*60-B9 -> 28052.8 | E16: =RATE(60,-C16,B9)*12 -> 0.052900356 | F16: =D16/B9/5 -> 0.0280528 | G16: =D16/$B$9 -> 0.140264 | H16: =$B$9*VLOOKUP(B16,系数参数!$B$4:$D$8,3,0) -> 3885.4 | I16: 30000 | J16: 个人申请：厂贴_5.99贴息 新优速贷/个体工商户升级 24期3.99%/36期4.99%/48期4.99%/60期5.29% 企业申请：厂贴_5.99贴息 新公牌易贷/个体工商户 24期3.99%/36期4.99%/48期4.99%/60期5.29% | L16: 剩余本金 | M16: =B9-(C16*M15-M18) -> 126269.67
B17: 48期 | C17: =ROUNDUP(PMT(系数参数!B2/12,48,-$B$9)-H17/48,2) -> 4604.96 | D17: =C17*48-B9 -> 21038.08 | E17: =RATE(48,-C17,B9)*12 -> 0.049900796 | F17: =D17/B9/4 -> 0.0262976 | G17: =D17/$B$9 -> 0.1051904 | H17: =$B$9*VLOOKUP(B17,系数参数!$B$4:$D$8,3,0) -> 4374.6 | I17: 30000 | L17: 可节省利息 | M17: =D16-M18 -> 10562.009
B18: 36期 | C18: =ROUNDUP(PMT(系数参数!B2/12,36,-$B$9)-H18/36,2) -> 5993.29 | D18: =C18*36-B9 -> 15758.44 | E18: =RATE(36,-C18,B9)*12 -> 0.049900946 | F18: =D18/B9/3 -> 0.026264067 | G18: =D18/$B$9 -> 0.0787922 | H18: =$B$9*VLOOKUP(B18,系数参数!$B$4:$D$8,3,0) -> 3247.2 | I18: 30000 | L18: 已还利息 | M18: =(B9*(E16/12)-C16)*((1+(E16/12))^(M15)-1)/(E16/12)+(C16)*M15 -> 17490.791
B19: 24期 | C19: =ROUNDUP(PMT(系数参数!B2/12,24,-$B$9)-H19/24,2) -> 8684.09 | D19: =C19*24-B9 -> 8418.16 | E19: =RATE(24,-C19,B9)*12 -> 0.039899519 | F19: =D19/B9/2 -> 0.0210454 | G19: =D19/$B$9 -> 0.0420908 | H19: =$B$9*VLOOKUP(B19,系数参数!$B$4:$D$8,3,0) -> 4299.2 | I19: 30000
B20: 12期 | C20: =ROUNDUP(PMT(系数参数!B2/12,12,-$B$9)-H20/12,2) -> 17212.37 | D20: =C20*12-B9 -> 6548.44 | E20: =RATE(12,-C20,B9)*12 -> 0.05990036 | F20: =D20/B9/1 -> 0.0327422 | G20: =D20/$B$9 -> 0.0327422 | H20: =$B$9*VLOOKUP(B20,系数参数!$B$4:$D$8,3,0) -> 0 | I20: 30000
A23: 贷款方案-2 | B23: 贷款金额* | C23: 首付金额 | D23: 首付比例 | E23: 首付比例不得低于： | F23: 0.2
A24: 定额 超低利率 （等额本息类） | B24: 100000 | C24: =B8-B24 -> 165900 | D24: =C24/B8 -> 0.62391877 | E24: 注：公牌/个体户类 首付30%起
B25: 期限 | C25: 客户试算月供 | D25: 客户试算 总利息 | E25: 客户试算 年化利率 | F25: 客户试算 年化费率 | G25: 客户试算 总费率 | H25: 厂商贴息 金额参考 | I25: 系统方案名称关键字
B26: 24期 | C26: =ROUNDUP(PMT(系数参数!B2/12,24,-B24)-H26/24,2) -> 4209.78 | D26: =C26*24-B24 -> 1034.72 | E26: =RATE(24,-C26,B24)*12 -> 0.0099020037 | F26: =D26/B24/2 -> 0.0051736 | G26: =D26/B24 -> 0.0103472 | H26: =系数参数!D16 -> 5324.15 | I26: 个人申请：厂贴_5.99贴息 新优速贷/个体工商户升级 24期10万0.99% 企业申请：厂贴_5.99贴息 新公牌易贷/个体工商户 24期10万0.99%
A29: 贷款方案-3 | B29: 贷款金额* (=总价*50%） | C29: 首付金额 | D29: 首付比例
A30: 半付半贷 超低月供 （5050智慧贷） | B30: =B8*50% -> 132950 | C30: =B8-B30 -> 132950 | D30: =C30/B8 -> 0.5
B31: 期限 | C31: 客户试算月供 | D31: 客户试算 总利息 | E31: 客户试算 年化利率 | F31: 客户试算 年化费率 | G31: 客户试算 总费率 | H31: 厂商贴息 金额参考 | I31: 系统方案名称关键字
B32: 1-11期 | C32: =ROUNDUP(PMT(系数参数!B2/12,12,-B30,C34)-H32/12,2) -> 331.27 | D32: =C32*12 -> 3975.24 | E32: =RATE(12,-C32,B30,-C34)*12 -> 0.029900263 | F32: =D32/B30/1 -> 0.029900263 | G32: =D32/B30 -> 0.029900263 | H32: =B30*VLOOKUP(B32,系数参数!$B$9:$D$10,3,0) -> 3988.5 | I32: 个人申请：厂贴_5.99贴息_5050_12期2.99%
B33: 12期（尾款） | C33: =B30+C32 -> 133281.27
C34: =B30 -> 132950
A36: 贷款方案-4 | B36: 贷款金额* (=总价*80%或70%） | C36: 首付金额 | D36: (固定)首付比例
A37: 留尾款享更低月供 (智慧式） | B37: =B8-C37 -> 212720 | C37: =B8*D37 -> 53180 | D37: 0.2
B38: 期限 | C38: 客户试算月供 | D38: 客户试算 总利息 | E38: 客户试算 年化利率 | F38: 客户试算 年化费率 | G38: 客户试算 总费率 | H38: 厂商贴息 金额参考 | I38: 系统方案名称关键字
B39: 1-35期 | C39: =ROUNDUP(PMT(系数参数!B2/12,36,-B37,C41)-H39/36,2) -> 4428.25 | D39: =C39*36-(B37-C41) -> 26467 | E39: =RATE(36,-C39,B37,-C41)*12 -> 0.058800415 | F39: =D39/B37/3 -> 0.041473925 | G39: =D39/B37 -> 0.12442178 | H39: =B37*VLOOKUP(D37,系数参数!B10:D11,3,0) -> 501.80648 | I39: 个人申请：厂贴_5.99贴息_智慧式 20%/30% 首付36期5.88%
B40: 36期（尾款） | C40: =B8*30%+C39 -> 84198.25
C41: =B8*30% -> 79770
A43: 贷款方案-5 | B43: 首付比例 | C43: 首付金额 | D43: 首付比例不得高于： | E43: 0.1999
A44: 0首付超低利率 （等额本息类） | B44: =C44/B6 -> 0.24783753 | C44: =B6-B9 -> 65900
B45: 期限 | C45: 客户试算月供 | D45: 客户试算 总利息 | E45: 客户试算 年化利率 | F45: 客户试算 年化费率 | G45: 客户试算 总费率 | H45: 厂商贴息 金额参考 | I45: 贷款金额 下限 | J45: 系统方案名称关键字
B46: 24期 | C46: =ROUNDUP(PMT(系数参数!B19/12,24,-$B$9)-H46/24,2) -> 8684.1 | D46: =C46*24-B9 -> 8418.4 | E46: =RATE(24,-C46,B9)*12 -> 0.039900642 | F46: =D46/B9/2 -> 0.021046 | G46: =D46/$B$9 -> 0.042092 | H46: =$B$9*VLOOKUP(B46,系数参数!$B$20:$D$21,3,0) -> 4299 | I46: 30000 | J46: 个人申请：厂贴_5.99贴息 新优速贷 0首付 24期 3.99%
B47: 12期 | C47: =ROUNDUP(PMT(系数参数!B19/12,12,-$B$9)-H47/12,2) -> 16937.84 | D47: =C47*12-B9 -> 3254.08 | E47: =RATE(12,-C47,B9)*12 -> 0.029901237 | F47: =D47/B9/1 -> 0.0162704 | G47: =D47/$B$9 -> 0.0162704 | H47: =$B$9*VLOOKUP(B47,系数参数!$B$20:$D$21,3,0) -> 3294.4 | I47: 150000 | J47: 个人申请：厂贴_5.99贴息 新优速贷 0首付 12期 2.99%

Sheet 厂贴_常规贴息（燃油车）
J1: 返回
A2: 第一步：修改贷款参数
A3: 车系 | B3: XT4_
A4: 车型 | B4: XT4智驭尊贵型
A5: 市场指导价(MSRP) | B5: =VLOOKUP(B4,'厂贴车型明细&贷款金额说明'!E9:F62,2,0) -> 275700
A6: 车辆开票价(TP)* | B6: 265900 | F6: 说明： 1、表格中蓝底白字的单元格，为可修改项。可直接输入或从下拉菜单中进行选择。 2、系统录入选择贷款方案时，注意选择带有“方案名称关键字”的方案名称 3、"0首付”方案不支持附加品贷
A7: 附加品金额 | B7: 0
A8: 总价 | B8: =B6+B7 -> 265900 | D8: 注：总价不得超过车辆市场指导价*115%
A9: 贷款金额* | B9: 265900
A12: 第二步：查看试算结果
A13: 贷款方案-1 | B13: 首付比例 | C13: 首付金额 | D13: 首付比例不得低于： | E13: 0.2
A14: 低首付低利率 （等额本息类） | B14: =C14/B8 -> 0 | C14: =B8-B9 -> 0 | D14: 注：公牌/个体户类 首付30%起 | M14: 60期提前还款测算参考：
B15: 期限 | C15: 客户试算月供 | D15: 客户试算 总利息 | E15: 客户试算 年化利率 | F15: 客户试算 年化费率 | G15: 客户试算 总费率 | H15: 厂商贴息 金额参考 | I15: 贷款金额 下限 | J15: 系统方案名称关键字 | L15: 提前还款期数 | M15: 24 | O15: 还满24期免提前还款手续费
B16: 60期 | C16: =ROUNDUP(PMT(系数参数!B2/12,60,-$B$9)-H16/60,2) -> 5053.27 | D16: =C16*60-B9 -> 37296.2 | E16: =RATE(60,-C16,B9)*12 -> 0.052900359 | F16: =D16/B9/5 -> 0.028052802 | G16: =D16/$B$9 -> 0.14026401 | H16: =$B$9*VLOOKUP(B16,系数参数!$B$4:$D$8,3,0) -> 5165.6393 | I16: 30000 | J16: 个人申请：厂贴_5.99贴息 新优速贷/个体工商户升级 24期3.99%/36期4.99%/48期4.99%/60期5.29% 企业申请：厂贴_5.99贴息 新公牌易贷/个体工商户 24期3.99%/36期4.99%/48期4.99%/60期5.29% | L16: 剩余本金 | M16: =B9-(C16*M15-M18) -> 167875.53
B17: 48期 | C17: =ROUNDUP(PMT(系数参数!B2/12,48,-$B$9)-H17/48,2) -> 6122.29 | D17: =C17*48-B9 -> 27969.92 | E17: =RATE(48,-C17,B9)*12 -> 0.049900437 | F17: =D17/B9/4 -> 0.026297405 | G17: =D17/$B$9 -> 0.10518962 | H17: =$B$9*VLOOKUP(B17,系数参数!$B$4:$D$8,3,0) -> 5816.0307 | I17: 30000 | L17: 可节省利息 | M17: =D16-M18 -> 14042.192
B18: 36期 | C18: =ROUNDUP(PMT(系数参数!B2/12,36,-$B$9)-H18/36,2) -> 7968.07 | D18: =C18*36-B9 -> 20950.52 | E18: =RATE(36,-C18,B9)*12 -> 0.049900187 | F18: =D18/B9/3 -> 0.026263658 | G18: =D18/$B$9 -> 0.078790974 | H18: =$B$9*VLOOKUP(B18,系数参数!$B$4:$D$8,3,0) -> 4317.1524 | I18: 30000 | L18: 已还利息 | M18: =(B9*(E16/12)-C16)*((1+(E16/12))^(M15)-1)/(E16/12)+(C16)*M15 -> 23254.008
B19: 24期 | C19: =ROUNDUP(PMT(系数参数!B2/12,24,-$B$9)-H19/24,2) -> 11545.5 | D19: =C19*24-B9 -> 11192 | E19: =RATE(24,-C19,B9)*12 -> 0.039899717 | F19: =D19/B9/2 -> 0.021045506 | G19: =D19/$B$9 -> 0.042091012 | H19: =$B$9*VLOOKUP(B19,系数参数!$B$4:$D$8,3,0) -> 5715.7864 | I19: 30000
B20: 12期 | C20: =ROUNDUP(PMT(系数参数!B2/12,12,-$B$9)-H20/12,2) -> 22883.85 | D20: =C20*12-B9 -> 8706.2 | E20: =RATE(12,-C20,B9)*12 -> 0.059900694 | F20: =D20/B9/1 -> 0.032742384 | G20: =D20/$B$9 -> 0.032742384 | H20: =$B$9*VLOOKUP(B20,系数参数!$B$4:$D$8,3,0) -> 0 | I20: 30000
A23: 贷款方案-2 | B23: 贷款金额* | C23: 首付金额 | D23: 首付比例 | E23: 首付比例不得低于： | F23: 0.2
A24: 定额 超低利率 （等额本息类） | B24: 120000 | C24: =B8-B24 -> 145900 | D24: =C24/B8 -> 0.54870252 | E24: 注：公牌/个体户类 首付30%起
B25: 期限 | C25: 客户试算月供 | D25: 客户试算 总利息 | E25: 客户试算 年化利率 | F25: 客户试算 年化费率 | G25: 客户试算 总费率 | H25: 厂商贴息 金额参考 | I25: 系统方案名称关键字
B26: 12期 | C26: =ROUNDUP(PMT(系数参数!B2/12,12,-B24)-H26/12,2) -> 10053.68 | D26: =C26*12-B24 -> 644.16 | E26: =RATE(12,-C26,B24)*12 -> 0.0098952008 | F26: =D26/B24/1 -> 0.005368 | G26: =D26/B24 -> 0.005368 | H26: =系数参数!D15 -> 3285 | I26: 个人申请：厂贴_5.99贴息 新优速贷/个体工商户升级 12期12万0.99% 企业申请：厂贴_5.99贴息 新公牌易贷/个体工商户 12期12万0.99%
A29: 贷款方案-3 | B29: 贷款金额* | C29: 首付金额 | D29: 首付比例 | E29: 首付比例不得低于： | F29: 0.2
A30: 定额 超低利率 （等额本息类） | B30: 80000 | C30: =B8-B30 -> 185900 | D30: =C30/B8 -> 0.69913501 | E30: 注：公牌/个体户类 首付30%起
B31: 期限 | C31: 客户试算月供 | D31: 客户试算 总利息 | E31: 客户试算 年化利率 | F31: 客户试算 年化费率 | G31: 客户试算 总费率 | H31: 厂商贴息 金额参考 | I31: 系统方案名称关键字
B32: 24期 | C32: =ROUNDUP(PMT(系数参数!B2/12,24,-B30)-H32/24,2) -> 3402.87 | D32: =C32*24-B30 -> 1668.88 | E32: =RATE(24,-C32,B30)*12 -> 0.019900163 | F32: =D32/B30/2 -> 0.0104305 | G32: =D32/B30 -> 0.020861 | H32: =系数参数!D17 -> 3418.05 | I32: 个人申请：厂贴_5.99贴息 新优速贷/个体工商户升级 24期8万1.99% 企业申请：厂贴_5.99贴息 新公牌易贷/个体工商户 24期8万1.99%
A35: 贷款方案-4 | B35: 贷款金额* (=总价*50%） | C35: 首付金额 | D35: 首付比例 | E35: 系统录入尾款金额
A36: 半付半贷 超低月供 （5050智慧贷） | B36: =B8*50% -> 132950 | C36: =B8-B36 -> 132950 | D36: =C36/B8 -> 0.5 | E36: =B8*50% -> 132950
B37: 期限 | C37: 客户试算月供 | D37: 客户试算 总利息 | E37: 客户试算 年化利率 | F37: 客户试算 年化费率 | G37: 客户试算 总费率 | H37: 厂商贴息 金额参考 | I37: 系统方案名称关键字
B38: 1-11期 | C38: =ROUNDUP(PMT(系数参数!B2/12,12,-B36,C40)-H38/12,2) -> 331.27 | D38: =C38*12 -> 3975.24 | E38: =RATE(12,-C38,B36,-C40)*12 -> 0.029900263 | F38: =D38/B36/1 -> 0.029900263 | G38: =D38/B36 -> 0.029900263 | H38: =B36*VLOOKUP(B38,系数参数!$B$9:$D$10,3,0) -> 3988.5 | I38: 个人申请：厂贴_5.99贴息_5050_12期2.99%
B39: 12期（含尾款） | C39: =B36+C38 -> 133281.27
C40: =B36 -> 132950
A42: 贷款方案-5 | B42: 贷款金额* (=总价*80%或70%） | C42: 首付金额 | D42: (固定)首付比例 | E42: 系统录入尾款金额
A43: 留尾款享更低月供 (智慧式） | B43: =B8-C43 -> 212720 | C43: =B8*D43 -> 53180 | D43: 0.2 | E43: =B8*30% -> 79770
B44: 期限 | C44: 客户试算月供 | D44: 客户试算 总利息 | E44: 客户试算 年化利率 | F44: 客户试算 年化费率 | G44: 客户试算 总费率 | H44: 厂商贴息 金额参考 | I44: 系统方案名称关键字
B45: 1-35期 | C45: =ROUNDUP(PMT(系数参数!B2/12,36,-B43,C47)-H45/36,2) -> 4428.25 | D45: =C45*36-(B43-C47) -> 26467 | E45: =RATE(36,-C45,B43,-C47)*12 -> 0.058800415 | F45: =D45/B43/3 -> 0.041473925 | G45: =D45/B43 -> 0.12442178 | H45: =B43*VLOOKUP(D43,系数参数!B10:D11,3,0) -> 501.80648 | I45: 个人申请：厂贴_5.99贴息_智慧式 20%/30% 首付36期5.88%
B46: 36期（含尾款） | C46: =B8*30%+C45 -> 84198.25
C47: =B8*30% -> 79770
A49: 贷款方案-6 | B49: 首付比例 | C49: 首付金额 | D49: 首付比例不得高于： | E49: 0.1999
A50: 0首付超低利率 （等额本息类） | B50: =C50/B6 -> 0 | C50: =B6-B9 -> 0
...

Sheet 厂贴_常规贴息（新能源）
J1: 返回
A2: 第一步：修改贷款参数
A3: 车系 | B3: 傲歌
A4: 车型 | B4: IQ 傲歌 标准续航版 纯电动 新能源
A5: 市场指导价(MSRP) | B5: =VLOOKUP(B4,'厂贴车型明细&贷款金额说明'!E9:F62,2,0) -> 239700
A6: 车辆开票价(TP)* | B6: 265900 | F6: 说明： 1、表格中蓝底白字的单元格，为可修改项。可直接输入或从下拉菜单中进行选择。 2、系统录入选择贷款方案时，注意选择带有“方案名称关键字”的方案名称 3、"0首付”方案不支持附加品贷
A7: 附加品金额 | B7: 0
A8: 总价 | B8: =B6+B7 -> 265900 | D8: 注：总价不得超过车辆市场指导价*115%
A9: 贷款金额* | B9: 150000
A12: 第二步：查看试算结果
A13: 贷款方案-1 | B13: 首付比例 | C13: 首付金额 | D13: 首付比例不得低于： | E13: 0.15
A14: 低首付低利率 （等额本息类） | B14: =C14/B8 -> 0.43587815 | C14: =B8-B9 -> 115900 | D14: 注：公牌/个体户类 首付25%起 | M14: 60期提前还款测算参考：
B15: 期限 | C15: 客户试算月供 | D15: 客户试算 总利息 | E15: 客户试算 年化利率 | F15: 客户试算 年化费率 | G15: 客户试算 总费率 | H15: 厂商贴息 金额参考 | I15: 贷款金额 下限 | J15: 系统方案名称关键字 | L15: 提前还款期数 | M15: 24 | O15: 还满24期免提前还款手续费
B16: 60期 | C16: =ROUNDUP(PMT(系数参数!G2/12,60,-$B$9)-H16/60,2) -> 2891.56 | D16: =C16*60-B9 -> 23493.6 | E16: =RATE(60,-C16,B9)*12 -> 0.058800311 | F16: =D16/B9/5 -> 0.0313248 | G16: =D16/$B$9 -> 0.156624 | H16: =$B$9*VLOOKUP(B16,系数参数!$G$4:$I$8,3,0) -> 460.05 | I16: 30000 | J16: 个人申请：厂贴_5.99贴息 新优速贷/个体工商户升级 24期/36期/48期/60期 5.88% 企业申请：厂贴_5.99贴息 新公牌易贷/个体工商户 24期/36期/48期/60期 5.88% | L16: 剩余本金 | M16: =B9-(C16*M15-M18) -> 95218.56
B17: 48期 | C17: =ROUNDUP(PMT(系数参数!G2/12,48,-$B$9)-H17/48,2) -> 3514.51 | D17: =C17*48-B9 -> 18696.48 | E17: =RATE(48,-C17,B9)*12 -> 0.05880034 | F17: =D17/B9/4 -> 0.0311608 | G17: =D17/$B$9 -> 0.1246432 | H17: =$B$9*VLOOKUP(B17,系数参数!$G$4:$I$8,3,0) -> 362.85 | I17: 30000 | L17: 可节省利息 | M17: =D16-M18 -> 8877.6
B18: 36期 | C18: =ROUNDUP(PMT(系数参数!G2/12,36,-$B$9)-H18/36,2) -> 4555.14 | D18: =C18*36-B9 -> 13985.04 | E18: =RATE(36,-C18,B9)*12 -> 0.058800112 | F18: =D18/B9/3 -> 0.031077867 | G18: =D18/$B$9 -> 0.0932336 | H18: =$B$9*VLOOKUP(B18,系数参数!$G$4:$I$8,3,0) -> 269.1 | I18: 30000 | L18: 已还利息 | M18: =(B9*(E16/12)-C16)*((1+(E16/12))^(M15)-1)/(E16/12)+(C16)*M15 -> 14616
B19: 24期 | C19: =ROUNDUP(PMT(系数参数!G2/12,24,-$B$9)-H19/24,2) -> 6639.98 | D19: =C19*24-B9 -> 9359.52 | E19: =RATE(24,-C19,B9)*12 -> 0.058799439 | F19: =D19/B9/2 -> 0.0311984 | G19: =D19/$B$9 -> 0.0623968 | H19: =$B$9*VLOOKUP(B19,系数参数!$G$4:$I$8,3,0) -> 178.5 | I19: 30000
B20: 12期 | C20: =ROUNDUP(PMT(6.98%/12,12,-$B$9)-H20/12,2) -> 12977.63 | D20: =C20*12-B9 -> 5731.56 | E20: =RATE(12,-C20,B9)*12 -> 0.069800151 | F20: =D20/B9/1 -> 0.0382104 | G20: =D20/$B$9 -> 0.0382104 | H20: =$B$9*VLOOKUP(B20,系数参数!$G$4:$I$8,3,0) -> 0 | I20: 25000
A23: 贷款方案-2 | B23: 贷款金额* (=总价*50%） | C23: 首付金额 | D23: 首付比例
A24: 半付半贷 超低月供 （5050智慧式） | B24: =B8*50% -> 132950 | C24: =B8-B24 -> 132950 | D24: =C24/B8 -> 0.5
B25: 期限 | C25: 客户试算月供 | D25: 尾款(=总价*50%） (与末期月供一起支付） | E25: 客户试算 总利息 | F25: 客户试算 年化利率 | G25: 客户试算 年化费率 | H25: 客户试算 总费率 | I25: 厂商贴息 金额参考 | J25: 系统方案名称关键字
B26: 12期 | C26: =ROUNDUP(PMT(系数参数!G2/12,12,-B24,D26)-I26/12,2) -> 651.46 | D26: =B24 -> 132950 | E26: =C26*12 -> 7817.52 | F26: =RATE(12,-C26,B24,-D26)*12 -> 0.058800451 | G26: =E26/B24/1 -> 0.058800451 | H26: =E26/B24 -> 0.058800451 | I26: =B24*VLOOKUP(B26,系数参数!$G$9:$I$10,3,0) -> 146.245 | J26: 个人申请：厂贴_5.99贴息_5050_12期5.88%

Sheet 双优贷2.0_非厂贴
I1: 返回
B2: 第一步：修改贷款参数
B3: 年化利率* | C3: 0.116
B4: 车辆开票价(TP)* | C4: 356300 | E4: 注：非厂贴双优贷方案仅适用于不享受厂家贴息政策的车型 以及 傲歌，具体请以系统设置为准
B5: 附加品金额* （仅限购置税&保费） | C5: 42000
B6: 总价 | C6: =C4+C5 -> 398300
B7: 贷款金额* （5万起） | C7: 200000 | D7: *请将贷款金额调整至低于车辆开票价
B8: 首付金额 | C8: =C6-C7 -> 198300
B9: 首付比例 | C9: =C8/C6 -> 0.49786593 | D9: 新能源15%起，燃油车20%起
B11: 第二步：查看试算结果 | L11: 提前还款测算参考：
B12: 贷款方案-1 | C12: 期限 | D12: 客户试算月供 | E12: 客户试算总利息 | F12: 客户试算年化利率 | G12: 客户试算年化费率 | H12: 客户试算总费率 | I12: 系统方案名称关键字 | K12: 提前还款期数 | L12: 12 | N12: 还满30期免提前还款手续费
B13: 双优贷2.0 （非贴息） | C13: 60期 | D13: =ROUNDUP(PMT($C$3/12,60,-$C$7),2) -> 4408.57 | E13: =D13*60-C7 -> 64514.2 | F13: =RATE(60,-D13,$C$7)*12 -> 0.11600014 | G13: =E13/$C$7/5 -> 0.0645142 | H13: =E13/$C$7 -> 0.322571 | I13: 个人申请：11.6双优贷2.0_新优速贷_非贴息_60期_通用 | K13: 剩余本金 | L13: =C7-(D13*L12-L15) -> 168665.98
K14: 可节省利息 | L14: =E13-L15 -> 42945.384
K15: 已还利息 | L15: =(C7*(F13/12)-D13)*((1+(F13/12))^(L12)-1)/(F13/12)+(D13)*L12 -> 21568.816
L17: 提前还款测算参考：
B18: 贷款方案2 | C18: 期限 | D18: 客户试算月供 | E18: 客户试算总利息 | F18: 客户试算年化利率 | G18: 客户试算年化费率 | H18: 客户试算总费率 | I18: 系统方案名称关键字 | K18: 提前还款期数 | L18: 12 | N18: 还满30期免提前还款手续费
B19: 双优贷2.0 （经销商贴息） | C19: 60期 | D19: =ROUNDUP(PMT($C$3/12,60,-$C$7)-G20/60,2) -> 4406.91 | E19: =D19*60-C7 -> 64414.6 | F19: =RATE(60,-D19,$C$7)*12 -> 0.11583501 | G19: =E19/$C$7/5 -> 0.0644146 | H19: =E19/$C$7 -> 0.322073 | I19: 个人申请：2025_11.6双优贷2.0_新优速贷_经销商贴息_60期_通用 | K19: 剩余本金 | L19: =C7-(D19*L18-L21) -> 168654.55
F20: 经销商贴息 （100元起） | G20: 100 | H20: *经销商贴息需填写在E速通系统的 ‘经销商补贴金额’处 | K20: 可节省利息 | L20: =E19-L21 -> 42877.131
L21: =(C7*(F19/12)-D19)*((1+(F19/12))^(L18)-1)/(F19/12)+(D19)*L18 -> 21537.469

Sheet 双优贷1.0_非厂贴
I1: 返回
B2: 第一步：修改贷款参数
B3: 年化利率* | C3: 0.097
B4: 车辆开票价(TP)* | C4: 356300
B5: 附加品金额* （仅限购置税&保费） | C5: 42000
B6: 总价 | C6: =C4+C5 -> 398300
B7: 贷款金额* （5万起） | C7: 200000 | D7: *请将贷款金额调整至低于车辆开票价
B8: 首付金额 | C8: =C6-C7 -> 198300
B9: 首付比例 | C9: =C8/C6 -> 0.49786593 | D9: 新能源15%起，燃油车20%起
B11: 第二步：查看试算结果 | L11: 提前还款测算参考：
B12: 贷款方案-1 | C12: 期限 | D12: 客户试算月供 | E12: 客户试算总利息 | F12: 客户试算年化利率 | G12: 客户试算年化费率 | H12: 客户试算总费率 | I12: 系统方案名称关键字 | K12: 提前还款期数 | L12: 12 | N12: 还满30期免提前还款手续费
B13: 双优贷1.0 （非贴息） | C13: 60期 | D13: =ROUNDUP(PMT($C$3/12,60,-$C$7),2) -> 4219.95 | E13: =D13*60-C7 -> 53197 | F13: =RATE(60,-D13,$C$7)*12 -> 0.097000333 | G13: =E13/$C$7/5 -> 0.053197 | H13: =E13/$C$7 -> 0.265985 | I13: 个人申请：9.7双优贷_新优速贷_非贴息_60期_通用 | K13: 剩余本金 | L13: =C7-(D13*L12-L15) -> 167333.7
K14: 可节省利息 | L14: =E13-L15 -> 35223.898
K15: 已还利息 | L15: =(C7*(F13/12)-D13)*((1+(F13/12))^(L12)-1)/(F13/12)+(D13)*L12 -> 17973.102
L17: 提前还款测算参考：
B18: 贷款方案2 | C18: 期限 | D18: 客户试算月供 | E18: 客户试算总利息 | F18: 客户试算年化利率 | G18: 客户试算年化费率 | H18: 客户试算总费率 | I18: 系统方案名称关键字 | K18: 提前还款期数 | L18: 12 | N18: 还满30期免提前还款手续费
B19: 双优贷1.0 （经销商贴息） | C19: 60期 | D19: =ROUNDUP(PMT($C$3/12,60,-$C$7)-G20/60,2) -> 4218.29 | E19: =D19*60-C7 -> 53097.4 | F19: =RATE(60,-D19,$C$7)*12 -> 0.096830937 | G19: =E19/$C$7/5 -> 0.0530974 | H19: =E19/$C$7 -> 0.265487 | I19: 个人申请：2025_11.6双优贷2.0_新优速贷_经销商贴息_60期_通用 | K19: 剩余本金 | L19: =C7-(D19*L18-L21) -> 167321.67
F20: 经销商贴息 （100元起） | G20: 100 | H20: *经销商贴息需填写在E速通系统的 ‘经销商补贴金额’处 | K20: 可节省利息 | L20: =E19-L21 -> 35156.254
L21: =(C7*(F19/12)-D19)*((1+(F19/12))^(L18)-1)/(F19/12)+(D19)*L18 -> 17941.146

Sheet 新通用_非贴息
P1: 返回
B2: 第一步：修改贷款参数 | E2: 第二步：查看试算结果
B3: 车辆开票价(TP)* | C3: 275900 | E3: 还款方式-1 | F3: 首付比例 | G3: 首付金额 | H3: 贷款金额* （5万起贷） | I3: 期限 | J3: 客户试算月供 | K3: 客户试算总利息 | L3: 客户试算年化利率 | M3: 客户试算年化费率 | N3: 客户试算总费率 | O3: 系统方案名称关键字 | AA3: 60期提前还款测算参考：
E4: 等额本息类 | F4: =G4/C9 -> 0.81877492 | G4: =C9-H4 -> 225900 | H4: 50000 | I4: 60期 | J4: =ROUNDUP(PMT($C$7/12,60,-$H$4)-C16/60,2) -> 1037.44 | K4: =J4*60-H4 -> 12246.4 | L4: =RATE(60,-J4,$H$4)*12 -> 0.089803093 | M4: =K4/$H$4/5 -> 0.0489856 | N4: =K4/$H$4 -> 0.244928 | O4: =VLOOKUP(C7,'参数-非厂贴方案配置'!A4:I6,2,0) -> 个人申请：8.98新通用 新优速贷/个体工商户升级 非贴息_12-60期 企业申请：8.98新通用 新公牌易贷/个体工商户 非贴息_12-60期 企业商用：8.98新通用_营运租赁_非贴息_12-36期 | Z4: 提前还款期数 | AA4: 24 | AC4: 还满24期免提前还款手续费
B5: 附加品金额* | C5: 0 | I5: 48期 | J5: =ROUNDUP(PMT($C$7/12,48,-$H$4)-C16/48,2) -> 1243.78 | K5: =J5*48-H4 -> 9701.44 | L5: =RATE(48,-J5,$H$4)*12 -> 0.089801121 | M5: =K5/$H$4/4 -> 0.0485072 | N5: =K5/$H$4 -> 0.1940288 | Z5: 剩余本金 | AA5: =H4-(J4*AA4-AA7) -> 32633.577
I6: 36期 | J6: =ROUNDUP(PMT($C$7/12,36,-$H$4)-C16/36,2) -> 1589.53 | K6: =J6*36-H4 -> 7223.08 | L6: =RATE(36,-J6,$H$4)*12 -> 0.089803756 | M6: =K6/$H$4/3 -> 0.048153867 | N6: =K6/$H$4 -> 0.1444616 | Z6: 可节省利息 | AA6: =K4-AA7 -> 4714.2626
B7: 年化利率* （点选切换） | C7: 0.0898 | I7: 24期 | J7: =ROUNDUP(PMT($C$7/12,24,-$H$4)-C16/24,2) -> 2283.78 | K7: =J7*24-H4 -> 4810.72 | L7: =RATE(24,-J7,$H$4)*12 -> 0.089800731 | M7: =K7/$H$4/2 -> 0.0481072 | N7: =K7/$H$4 -> 0.0962144 | Z7: 已还利息 | AA7: =(H4*(L4/12)-J4)*((1+(L4/12))^(AA4)-1)/(L4/12)+(J4)*AA4 -> 7532.1374
I8: 18期 | J8: =ROUNDUP(PMT($C$7/12,18,-$H$4)-C16/18,2) -> 2979.43 | K8: =J8*18-H4 -> 3629.74 | L8: =RATE(18,-J8,$H$4)*12 -> 0.08980225 | M8: =K8/$H$4/1.5 -> 0.048396533 | N8: =K8/$H$4 -> 0.0725948
B9: 总价 注：总价不得超过车辆市场指导价*115% | C9: =C3+C5 -> 275900 | I9: 12期 | J9: =ROUNDUP(PMT($C$7/12,12,-$H$4)-C16/12,2) -> 4372.12 | K9: =J9*12-H4 -> 2465.44 | L9: =RATE(12,-J9,$H$4)*12 -> 0.08980426 | M9: =K9/$H$4/1 -> 0.0493088 | N9: =K9/$H$4 -> 0.0493088
B16: 经销商贴息 （不支持） | C16: 0 | E16: 还款方式-2 | F16: 首付比例 | G16: 首付金额 | H16: 贷款金额* | I16: 期限 | J16: 客户试算月供 | K16: 尾款 (与末期月供一起支付） | L16: 客户总利息 | M16: 客户试算年化利率 | O16: 客户试算年化费率 | P16: 系统操作产品选项 | Z16: 60期智慧贷还满24期提前还款测算参考：
E17: 智慧式 | F17: =G17/C9 -> 0.71003987 | G17: =C9-H17 -> 195900 | H17: 80000 | I17: 60期 | J17: =ROUNDUP(PMT(C7/12,60,-H17,K17)-C16/60,2) -> 927.92 | K17: =C9*20% -> 55180 | L17: =J17*60-(H17-K17) -> 30855.2 | M17: =RATE(60,-J17,$H$17,-$K$17)*12 -> 0.089801409 | O17: =L17/$H$17/5 -> 0.077138 | P17: =VLOOKUP(C7,'参数-非厂贴方案配置'!A4:I6,3,0) -> 无方案 | Z17: 提前还款期数 | AA17: 24 | AC17: 从24期开始填写（同期结清）
I18: 48期 | J18: =ROUNDUP(PMT(C7/12,48,-H17,K17)-C16/48,2) -> 1030.35 | L18: =J18*48-(H17-K17) -> 24636.8 | M18: =RATE(48,-J18,$H$17,-$K$17)*12 -> 0.089801488 | O18: =L18/$H$17/4 -> 0.07699 | Z18: 剩余本金 | AA18: =H17-(J17*AA17-AA20) -> 71379.284
I19: 36期 | J19: =ROUNDUP(PMT(C7/12,36,-H17,K19)-C16/36,2) -> 531.34 | K19: =C9*30% -> 82770 | L19: =J19*36-(H17-K19) -> 21898.24 | M19: =RATE(36,-J19,$H$17,-$K$19)*12 -> 0.089800588 | O19: =L19/$H$17/3 -> 0.091242667 | Z19: 可节省利息 | AA19: =L17-AA20 -> 17205.836
I20: 24期 | J20: =ROUNDUP(PMT(C7/12,24,-H17,K19)-C16/24,2) -> 492.88 | L20: =J20*24-(H17-K19) -> 14599.12 | M20: =RATE(24,-J20,$H$17,-$K$19)*12 -> 0.089800859 | O20: =L20/$H$17/2 -> 0.0912445 | Z20: 已还利息 | AA20: =(H17*(M17/12)-J17)*((1+(M17/12))^(AA17)-1)/(M17/12)+(J17)*AA17 -> 13649.364
I21: 18期 | J21: =ROUNDUP(PMT(C7/12,18,-H17,K19)-C16/18,2) -> 454.34 | L21: =J21*18-(H17-K19) -> 10948.12 | M21: =RATE(18,-J21,$H$17,-$K$19)*12 -> 0.089800685 | O21: =L21/$H$17/1.5 -> 0.091234333
I22: 12期 | J22: =ROUNDUP(PMT(C7/12,12,-H17,K19)-C16/12,2) -> 377.19 | L22: =J22*12-(H17-K19) -> 7296.28 | M22: =RATE(12,-J22,$H$17,-$K$19)*12 -> 0.089801389 | O22: =L22/$H$17/1 -> 0.0912035
E24: 还款方式-3 | F24: 首付比例 | G24: 首付金额 | H24: 贷款金额 (=总价*50%） | I24: 期限 | J24: 客户试算月供 | K24: 尾款 (与末期月供一起支付） | L24: 客户总利息 | M24: 客户试算年化利率 | O24: 客户试算年化费率 | P24: 系统操作产品选项
E25: 5050 智慧式 | F25: 0.5 | G25: =C9*F25 -> 137950 | H25: =C9-G25 -> 137950 | I25: 12期 | J25: =ROUNDUP(L25/12,2) -> 1032.33 | K25: =C9*50% -> 137950 | L25: =H25*C7-C16 -> 12387.91 | M25: =RATE(12,-J25,H25,-K25)*12 -> 0.089800362 | O25: =L25/H25/1 -> 0.0898 | P25: =VLOOKUP(C7,'参数-非厂贴方案配置'!A4:I6,4,0) -> 无方案
E27: 还款方式-4 | F27: 首付比例 | G27: 首付金额 | H27: 贷款金额 (=总价*60%） | I27: 期限 | J27: 客户试算月供 | K27: 客户总利息 | L27: 客户试算年化利率 | M27: 客户试算年化费率 | O27: 系统操作产品选项 | U27: 本金 | V27: 月利息
E28: 433 分段式 | F28: 0.4 | G28: =C9*F28 -> 110360 | H28: =C9*60% -> 165540 | I28: 1-11期 | J28: =V28 -> 1238.791 | K28: =(V28+V30)*12 -> 22298.238 | L28: =C7 -> 0.0898 | M28: =K28/H28/2 -> 0.06735 | O28: =VLOOKUP(C7,'参数-非厂贴方案配置'!A4:I6,5,0) -> 无方案 | U28: 0 | V28: =L28/12*H28 -> 1238.791
I29: 12期 | J29: =V29+U29 -> 84008.791 | U29: =H28*50% -> 82770 | V29: =L28/12*H28 -> 1238.791
I30: 13-23期 | J30: =V30 -> 619.3955 | U30: 0 | V30: =L28/12*(H28-U29) -> 619.3955
I31: 24期 | J31: =V31+U31 -> 83389.395 | U31: =H28*50% -> 82770 | V31: =L28/12*(H28-U29) -> 619.3955
E33: 还款方式-5 | F33: 首付比例 | G33: 首付 | H33: 贷款金额* | I33: 期限 | J33: 客户试算月供 | K33: 客户总利息 | L33: 客户试算年化利率 | M33: 客户试算年化费率 | O33: 系统操作产品选项 | U33: 本金 | V33: 月利息
E34: X-433 分段式 | F34: =G34/C9 -> 0.71003987 | G34: =C9-H34 -> 195900 | H34: 80000 | I34: 1-11期 | J34: =V34+U34 -> 598.66667 | K34: =(V34+V36+V38)*12 -> 13649.6 | L34: =C7 -> 0.0898 | M34: =K34/H34/3 -> 0.056873333 | O34: =VLOOKUP(C7,'参数-非厂贴方案配置'!A4:I6,6,0) -> 无方案 | U34: 0 | V34: =L34/12*H34 -> 598.66667
I35: 12期 | J35: =V35+U35 -> 32598.667 | U35: =H34*40% -> 32000 | V35: =L34/12*H34 -> 598.66667
I36: 13-23期 | J36: =V36+U36 -> 359.2 | U36: 0 | V36: =L34/12*(H34-U35) -> 359.2
I37: 24期 | J37: =U37+V37 -> 24359.2 | U37: =H34*30% -> 24000 | V37: =L34/12*(H34-U35) -> 359.2
I38: 25-35期 | J38: =V38+U38 -> 179.6 | U38: 0 | V38: =L34/12*(H34-U35-U37) -> 179.6
I39: 36期 | J39: =U39+V39 -> 24179.6 | U39: =H34*30% -> 24000 | V39: =L34/12*(H34-U35-U37) -> 179.6

Sheet 新通用_经销商贴息
P1: 返回
B2: 第一步：输入修改参数 | E2: 第二步：查看试算结果
B3: 车辆开票价(TP)* | C3: 100000 | E3: 还款方式-1 | F3: 首付比例 | G3: 首付金额 | H3: 贷款金额* （5万起贷） | I3: 期限 | J3: 客户试算月供 | K3: 客户试算总利息 | L3: 客户试算年化利率 | M3: 客户试算年化费率 | N3: 客户试算总费率 | O3: 系统方案名称关键字 | T3: 60期提前还款测算参考：
E4: 等额本息类 | F4: =G4/C9 -> 0.2 | G4: =C9-H4 -> 20000 | H4: 80000 | I4: 60期 | J4: =ROUNDUP(PMT($C$7/12,60,-$H$4)-C11/60,2) -> 1658.23 | K4: =J4*60-H4 -> 19493.8 | L4: =RATE(60,-J4,$H$4)*12 -> 0.089371697 | M4: =K4/$H$4/5 -> 0.0487345 | N4: =K4/$H$4 -> 0.2436725 | O4: =VLOOKUP(C7,'参数-非厂贴方案配置'!A4:I6,7,0) -> 个人申请：8.98新通用 新优速贷/个体工商户升级 经销商贴息_12-60期 企业申请：8.98新通用 新公牌易贷/个体工商户 经销商贴息_12-60期 企业商用：8.98新通用_营运租赁_经销商贴息_12-36期 | S4: 提前还款期数 | T4: 24 | V4: 还满24期免提前还款手续费
B5: 附加品金额* | C5: 0 | I5: 48期 | J5: =ROUNDUP(PMT($C$7/12,48,-$H$4)-C11/48,2) -> 1987.97 | K5: =J5*48-H4 -> 15422.56 | L5: =RATE(48,-J5,$H$4)*12 -> 0.089253793 | M5: =K5/$H$4/4 -> 0.0481955 | N5: =K5/$H$4 -> 0.192782 | S5: 剩余本金 | T5: =H4-(J4*T4-T7) -> 52194.019
I6: 36期 | J6: =ROUNDUP(PMT($C$7/12,36,-$H$4)-C11/36,2) -> 2540.46 | K6: =J6*36-H4 -> 11456.56 | L6: =RATE(36,-J6,$H$4)*12 -> 0.089054583 | M6: =K6/$H$4/3 -> 0.047735667 | N6: =K6/$H$4 -> 0.143207 | S6: 可节省利息 | T6: =K4-T7 -> 7502.2614
B7: 年化利率* （点选切换） | C7: 0.0898 | I7: 24期 | J7: =ROUNDUP(PMT($C$7/12,24,-$H$4)-C11/24,2) -> 3649.88 | K7: =J7*24-H4 -> 7597.12 | L7: =RATE(24,-J7,$H$4)*12 -> 0.088664686 | M7: =K7/$H$4/2 -> 0.047482 | N7: =K7/$H$4 -> 0.094964 | S7: 已还利息 | T7: =(H4*(L4/12)-J4)*((1+(L4/12))^(T4)-1)/(L4/12)+(J4)*T4 -> 11991.539
I8: 18期 | J8: =ROUNDUP(PMT($C$7/12,18,-$H$4)-C11/18,2) -> 4761.53 | K8: =J8*18-H4 -> 5707.54 | L8: =RATE(18,-J8,$H$4)*12 -> 0.088285975 | M8: =K8/$H$4/1.5 -> 0.047562833 | N8: =K8/$H$4 -> 0.07134425
B9: 总价 注：总价不得超过车辆市场指导价*115% | C9: =C3+C5 -> 100000 | I9: 12期 | J9: =ROUNDUP(PMT($C$7/12,12,-$H$4)-C11/12,2) -> 6987.05 | K9: =J9*12-H4 -> 3844.6 | L9: =RATE(12,-J9,$H$4)*12 -> 0.08755477 | M9: =K9/$H$4/1 -> 0.0480575 | N9: =K9/$H$4 -> 0.0480575
B11: 经销商贴息* （100元起） | C11: 100
C13: *经销商贴息需填写在E速通系统的‘经销商补贴金额’处
E18: 还款方式-2 | F18: 首付比例 | G18: 首付金额 | H18: 贷款金额* | I18: 期限 | J18: 客户试算月供 | K18: 尾款 (与末期月供一起支付） | L18: 客户总利息 | M18: 客户试算年化利率 | O18: 客户试算年化费率 | P18: 系统操作产品选项 | S18: 60期智慧贷还满24期提前还款测算参考：
E19: 智慧式 | F19: =G19/C9 -> 0.2 | G19: =C9-H19 -> 20000 | H19: 80000 | I19: 60期 | J19: =ROUNDUP(PMT(C7/12,60,-H19,K19)-C11/60,2) -> 1392.92 | K19: =C9*20% -> 20000 | L19: =J19*60-(H19-K19) -> 23575.2 | M19: =RATE(60,-J19,$H$19,-$K$19)*12 -> 0.089436089 | O19: =L19/$H$19/5 -> 0.058938 | P19: =VLOOKUP(C7,'参数-非厂贴方案配置'!A4:I6,8,0) -> 无方案 | S19: 提前还款期数 | T19: 24 | V19: 从24期开始填写（同期结清）
I20: 48期 | J20: =ROUNDUP(PMT(C7/12,48,-H19,K19)-C11/48,2) -> 1640.12 | L20: =J20*48-(H19-K19) -> 18725.76 | M20: =RATE(48,-J20,$H$19,-$K$19)*12 -> 0.089339356 | O20: =L20/$H$19/4 -> 0.058518 | S20: 剩余本金 | T20: =H19-(J19*T19-T22) -> 59147.72
I21: 36期 | J21: =ROUNDUP(PMT(C7/12,36,-H19,K21)-C11/36,2) -> 1811.25 | K21: =C9*30% -> 30000 | L21: =J21*36-(H19-K21) -> 15205 | M21: =RATE(36,-J21,$H$19,-$K$21)*12 -> 0.089225773 | O21: =L21/$H$19/3 -> 0.063354167 | S21: 可节省利息 | T21: =L19-T22 -> 10997.4
I22: 24期 | J22: =ROUNDUP(PMT(C7/12,24,-H19,K21)-C11/24,2) -> 2504.12 | L22: =J22*24-(H19-K21) -> 10098.88 | M22: =RATE(24,-J22,$H$19,-$K$21)*12 -> 0.088932458 | O22: =L22/$H$19/2 -> 0.063118 | S22: 已还利息 | T22: =(H19*(M19/12)-J19)*((1+(M19/12))^(T19)-1)/(M19/12)+(J19)*T19 -> 12577.8
I23: 18期 | J23: =ROUNDUP(PMT(C7/12,18,-H19,K21)-C11/18,2) -> 3198.37 | L23: =J23*18-(H19-K21) -> 7570.66 | M23: =RATE(18,-J23,$H$19,-$K$21)*12 -> 0.088640605 | O23: =L23/$H$19/1.5 -> 0.063088833
I24: 12期 | J24: =ROUNDUP(PMT(C7/12,12,-H19,K21)-C11/12,2) -> 4588.28 | L24: =J24*12-(H19-K21) -> 5059.36 | M24: =RATE(12,-J24,$H$19,-$K$21)*12 -> 0.088071013 | O24: =L24/$H$19/1 -> 0.063242
E26: 还款方式-3 | F26: 首付比例 | G26: 首付金额 | H26: 贷款金额 (=总价*50%） | I26: 期限 | J26: 客户试算月供 | K26: 尾款 (与末期月供一起支付） | L26: 客户总利息 | M26: 客户试算年化利率 | O26: 客户试算年化费率 | P26: 系统操作产品选项
E27: 5050 智慧式 | F27: 0.5 | G27: =C9*F27 -> 50000 | H27: =C9-G27 -> 50000 | I27: 12期 | J27: =ROUNDUP(L27/12,2) -> 365.84 | K27: =C9*50% -> 50000 | L27: =H27*C7-C11 -> 4390 | M27: =RATE(12,-J27,H27,-K27)*12 -> 0.0878016 | O27: =L27/H27/1 -> 0.0878 | P27: =VLOOKUP(C7,'参数-非厂贴方案配置'!A4:I6,9,0) -> 无方案

Sheet 新能源首付低于20%时 最高贷款金额测算
B1: 返回
A3: 新能源 首付低于20% 附加贷 最高贷款金额 测算 | B3: MSRP （市场指导价） | C3: 112800
B4: TP （车辆开票价） | C4: 98000
B5: 加融车辆保险金额 | C5: 4500
B6: 加融经销商附加品金额 | C6: 15000 | D6: 不含“保值焕新”上限： | E6: =MIN(C4*15%,30000) -> 14700
D7: 含“保值焕新”上限： | E7: =MIN(C4*18%,35000) -> 17640
B8: 总价金额 | C8: =C4+C5+C6 -> 117500 | D8: 总价上限MSRP*115%： | E8: =C3*115% -> 129720
B9: 车辆最高贷款金额 | C9: =C4*D9 -> 83300 | D9: 0.85
B10: 附加品最高贷款金额 | C10: =(C5+C6)*D10 -> 15600 | D10: 0.8
B11: 最高贷款金额 | C11: =C9+C10 -> 98900
B12: 首付比例 | C12: =(C8-C11)/C8 -> 0.15829787
B13: * 本工具测算仅支持：新能源车个人自用且首付比例低于20%的附加贷

Sheet 参数-非厂贴方案配置
A2: 新通用 | B2: 非厂商贴息 | G2: 经销商贴息
A3: 利率 | B3: 等额本息类 | C3: 智慧式 | D3: 5050 | E3: 433 | F3: X433 | G3: 等额本息类 | H3: 智慧式 | I3: 5050 | J3: 433 | K3: X433
A4: 0.109 | B4: 个人申请：10.9新通用 新优速贷/个体工商户升级 非贴息_12-60期 企业申请：10.9新通用 新公牌易贷/个体工商户 非贴息_12-60期 企业商用：10.9新通用_营运租赁_非贴息_12-36期 | C4: 无方案 | D4: 无方案 | E4: 无方案 | F4: 无方案 | G4: 个人申请：10.9新通用 新优速贷/个体工商户升级 经销商贴息_12-60期 企业申请：10.9新通用 新公牌易贷/个体工商户 经销商贴息_12-60期 企业商用：10.9新通用_营运租赁_经销商贴息_12-36期 | H4: 无方案 | I4: 无方案 | J4: 无方案 | K4: 无方案
A5: 0.099 | B5: 个人申请：9.9新通用 新优速贷/个体工商户升级 非贴息_12-60期 企业申请：9.9新通用 新公牌易贷/个体工商户 非贴息_12-60期 企业商用：9.9新通用_营运租赁_非贴息_12-36期 | C5: 无方案 | D5: 无方案 | E5: 无方案 | F5: 无方案 | G5: 个人申请：9.9新通用 新优速贷/个体工商户升级 经销商贴息_12-60期 企业申请：9.9新通用 新公牌易贷/个体工商户 经销商贴息_12-60期 企业商用：9.9新通用_营运租赁_经销商贴息_12-36期 | H5: 无方案 | I5: 无方案 | J5: 无方案 | K5: 无方案
A6: 0.0898 | B6: 个人申请：8.98新通用 新优速贷/个体工商户升级 非贴息_12-60期 企业申请：8.98新通用 新公牌易贷/个体工商户 非贴息_12-60期 企业商用：8.98新通用_营运租赁_非贴息_12-36期 | C6: 无方案 | D6: 无方案 | E6: 无方案 | F6: 无方案 | G6: 个人申请：8.98新通用 新优速贷/个体工商户升级 经销商贴息_12-60期 企业申请：8.98新通用 新公牌易贷/个体工商户 经销商贴息_12-60期 企业商用：8.98新通用_营运租赁_经销商贴息_12-36期 | H6: 无方案 | I6: 无方案 | J6: 无方案 | K6: 无方案
A12: 双优贷
A13: 60期 | B13: 新双优贷_SGM非贴息_新优速贷_60期利率9.7%_全国
A14: 60期 | B14: 新双优贷_SGM经销商贴息_新优速贷_60期利率9.7%_全国
A20: 马卡龙 | B20: A | C20: B
A21: 60期 | B21: 个人申请：8.98马卡龙A 新优速贷/标准产品/个体工商户升级 自主贴息_60期 | C21: 个人申请：9.98马卡龙B 新优速贷/标准产品/个体工商户升级 自主贴息_60期
A22: 36期 | B22: 个人申请：9.48马卡龙A 新优速贷/标准产品/个体工商户升级 自主贴息_36期 | C22: 个人申请：10.48马卡龙B 新优速贷/标准产品/个体工商户升级 自主贴息_36期
A23: 60期 | B23: 个人申请：2025_别克 自主贴息 马卡龙A 个人常规智慧贷 60期低息 20%尾款 | C23: 个人申请：2025_别克 自主贴息 马卡龙B 个人常规智慧贷 60期低息 20%尾款
A24: 36期 | B24: 个人申请：2025_别克 自主贴息 马卡龙A 个人常规智慧贷 36期低息 30%尾款 | C24: 个人申请：2025_别克 自主贴息 马卡龙B 个人常规智慧贷 36期低息 30%尾款

Sheet 产品准入政策&基础参数
C2: 返回
C4: 准入政策参考：
C5: 个人自用（个人申请，上个人牌照）-准入政策汇总 | H5: 企业自用（公司申请，上公司牌照）-新公牌易贷/新公牌易贷5050 产品准入政策同新公牌易贷50万以内方案
C6: 产品类别 | D6: 客户准入政策 | H6: 产品类别 | I6: 累计贷款金额 | J6: 客户准入要求 | K6: 基本资料 | L6: 预审资料
C7: 新优速贷/智慧贷/5050 6666/X-433/433 | D7: 客户有近期不少于六个月的良好信用记录， 或 满足我司对于“本地人”的信贷要求 （免房产） | H7: 新公牌易贷 （企业申请、上公牌） | I7: <=50万 | J7: - 合法经营半年以上 - 持有有效证照，如《营业执照》 - 添加法定代表人或持股大于等于25%的股东做担保 | K7: - 公司营业执照+公章 - 法定代表人身份证（股东担保时，可接受法人签章代替法人签字） - 担保人身份证 - 持股大于等于25%的股东身份证件（如股东为非自然人 ，提供营业执照）及受益所有人身份证件 | L7: /
I9: 50-75万 （>50万，且<=75万） | L9: 银行流水、房产资料
C10: 标准产品 （即等额本息） | D10: 自有房产，或提供有本地房产的亲朋做担保 （需提供收入及房产证明类材料）
I11: 75-170万 （>75万，且<=170万） | L11: 银行流水、房产资料、 财务报表、完税凭证、 公司章程或验资报告等
C13: 个体户-自用（个体户公司申请，上个体户公司牌照）-准入政策 | H13: 注：公司申请支持企业名下招行/农行/工行的账号进行扣款授权，同时也可支持使用担保人名下（工农建招邮储）银行卡进行扣款授权（客户可根据自身需要二选其一）
C14: “个体工商户注册地”、“担保人工作地”及“担保人居住地”在同一省份， 需添加个体户经营者担保。（个体户经营者名下驾照，免房产） 暂不支持以下省市申请：西藏；苏州、南京、常州、宁波、福州、厦门、莆田、石家庄、郑州、乌鲁木齐（具体以系统为准）
H15: 企业商用（个人/公司申请，上公司牌照）-营运贷产品准入政策：
H16: 产品类别 | I16: 累计台数及贷款金额 | J16: 客户准入要求 | L16: 基本资料 | M16: 预审资料
C17: 个体户升级-自用（个体户经营者申请，上个体户公司牌照）-准入政策： | H17: 营运_客运 （客运公司申请、上公牌） | I17: <=5台， 且累计贷款金额<=50万 | J17: - 公司合法经营半年以上 - 持有有效《营业执照》， 且经营范围需包含与购车用途相关的描述（如客运） - 添加法人或持股大于等于25%的股东做担保 | L17: - 公司营业执照+公章 - 法定代表人身份证（股东担保时，可接受法人签章代替法人签字） - 担保人身份证、持股大于等于25%的股东身份证件（如股东为非自然人 ，提供营业执照）及受益所有人身份证件 注：“客运公司”还需提供道路运输经营许可证 | M17: /
C18: 个体户经营者居住地、个体户经营者工作地，以及经销商所在地在同一省份。（申请人须与个体户经营者保持一致，个体户经营者名下驾照） 注：1、个体工商户升级产品政策仅适用江苏省、宁波、福州、厦门、莆田、石家庄、郑州、乌鲁木齐（具体以系统为准） 2、个体工商户升级促销产品与个体工商户促销产品的厂商贴息政策一致 （个体工商户升级产品是个体户经营者个人申请贷款，上个体户牌照，请注意在E速通系统中选择带有“个体工商户升级”字样的方案） 3、不支持公务员/政府工作人员/军人等相关单位/职业申请该方案 | I18: >5台， 且累计贷款金额<=50万 | J18: - 公司合法经营1年以上 - 持有有效《营业执照》， 且经营范围需包含与购车用途相关的描述（如客运） - 添加法人或持股大于等于25%的股东做担保 | M18: 银行流水、房产资料
I19: 累计贷款金额>50万 （但不超过170万） | M19: 银行流水、房产资料、 财务报表、完税凭证、 公司章程或验资报告等
H20: 营运_租赁 （租赁公司申请、上公牌） | I20: 不区分台次或贷款金额 （但累计贷款金额需在170万以内） | J20: - 公司合法经营1年以上 - 持有有效《营业执照》， 且经营范围需包含与购车用途相关的描述（如租赁） - 添加法人或持股大于等于25%的股东做担保 | L20: - 公司营业执照+公章 - 法定代表人身份证（股东担保时，可接受法人签章代替法人签字） - 担保人身份证、持股大于等于25%的股东身份证件（如股东为非自然人 ，提供营业执照）及受益所有人身份证件 | M20: 银行流水、房产资料、 财务报表、完税凭证、 公司章程或验资报告； 租赁合同、协议或意向书； 以及AM尽职调查报告
H21: 注：公司申请支持企业名下招行/农行/工行的账号进行扣款授权，同时也可支持使用担保人名下（工农建招邮储）银行卡进行扣款授权（客户可根据自身需要二选其一）
C23: 产品基础参数参考： | H23: 附加品贷款要求： | K23: 经销商附加品和服务金额上限要求 “标准附加品”指：保值焕新服务/轮胎保障服务/严选置换保障/严选行车卫士
B24: 用途 | C24: 产品类别 | D24: 首付比例 | E24: 贷款期限 | F24: 贷款金额 | H24: 贷款类型 | I24: 总价（车价+附加品）金额上限 | J24: 附加品项目
B25: 个人 自用 | C25: 新优速贷 | D25: 20%起 （新能源新车15%起） | E25: 12-60期 | F25: 2.5-50万 | H25: 厂贴 | I25: 不超过 车辆市场指导价的115% | J25: - 购置税、 - 车辆保险、 - 经销商附加品和服务（保值焕新服务、车辆内外精品装饰、等） | K25: - 包含“标准附加品”的经销商附加品和服务的合计金额上限为“车辆发票价的18%”或“3.5万”两者孰低； - 不包含“标准附加品”的经销商附加品和服务的合计金额上限为“车辆发票价的15%”或“3万”两者孰低。
C26: 标准产品（即等额本息） | F26: 2.5万起
C27: 智慧贷 （12-36期尾款：总价*30%，48/60期尾款：总价*20%） | D27: 20%起 | F27: 2.5-50万 | H27: 非厂贴 （新通用） | K27: 车辆开票价的10%或者3万孰低
C28: 5050 （尾款：总价*50%） | D28: 0.5 | E28: 12期 | H28: 注： 1、双优贷类方案仅可附加购置税及保险费；1+4阶梯贷 以及 0首付方案不支持附加品贷 2、新能源个人新车自用申请 1）首付<20% 且融附加品的贷款金额上限：车辆开票价*85%+附加品总额*80% 2）≥20% 且融附加品的贷款金额上限：车辆开票价*80%+附加品总额*80% （等比） 举例：某车开票价20万、附加品合计2万，客户首付15%。该客户贷款金额为200000*85%+20000*80%=186000元 补充说明：当客户首付比例大于20%时，附加品贷款额与车辆贷款额一起等比计算。 例：某车开票价20万、附加品合计2万，客户首付30%。该客户贷款金额为（200000+20000）*70%=154000元
C29: X-433分段式 （每月偿还利息，每12个月偿还利息时再分别偿还贷款本金的40%、30%、30%） | D29: 20%起 | E29: 36期
C30: 6666分段式 （每月偿还利息，每6个月偿还利息时再偿还贷款本金的25%） | E30: 24期
C31: 433分段式 （每月偿还利息，每12个月偿还利息时再偿还总价的30%） | D31: 0.4 | E31: 24期
B32: 个体户 自用 | C32: 个体工商户 （适用城市范围详见“准入政策”页） | D32: 30%起 （新能源新车25%起） | E32: 12-60期 | F32: 2.5-30万
C33: 个体工商户升级 （适用城市范围详见“准入政策”页）
B34: 企业 自用 | C34: 新公牌易贷5050 | D34: 0.5 | E34: 12期 | F34: 额度上限：1台，且不超50万
C35: 新公牌易贷 | D35: 30%起 （新能源新车25%起） | E35: 12-60期 | F35: 2.5万起 （多台申请累计贷款额度上限170万）
B36: 企业 商用 | C36: 营运_租赁 | D36: 30%起 （新能源新车25%起） | E36: 12-36期 | F36: 2.5万起 （多台申请累计贷款额度上限170万）
C37: 营运_客运公司
C38: 注：促销产品如对期限/首付/贷款金额等有特殊要求，请以促销产品说明为准。
