Workbook
Name _25款世纪: '参数-车系车型 利率'!$W$2:$W$4
Name _5050车系: '参数-车系车型 利率'!$D$2:$D$7
Name GL8陆尊燃油版: '参数-车系车型 利率'!$AH$2:$AH$4
Name 昂科威Plus: '参数-车系车型 利率'!$AC$2:$AC$4
Name 昂科威S: '参数-车系车型 利率'!$AD$2:$AD$4
Name 厂贴双优贷车系: '参数-车系车型 利率'!$M$2:$M$12
Name 车系参数: '参数-车系车型 利率'!$P$2:$P$6
Name 阶梯贷车系参数: '参数-车系车型 利率'!$I$2:$I$3
Name 君越: '参数-车系车型 利率'!$AE$2:$AE$3
Name 陆尊_ES: '参数-车系车型 利率'!$X$2:$X$3
Name 陆尊_PHEV: '参数-车系车型 利率'!$Y$2:$Y$5
Name 全新GL8_陆尊_新能源: '参数-车系车型 利率'!$AG$2:$AG$4
Name 全新GL8陆上公务舱: '参数-车系车型 利率'!$AB$2:$AB$5
Name 威朗Pro: '参数-车系车型 利率'!$AA$2:$AA$11
Name 微蓝6_450KM: '参数-车系车型 利率'!$Z$2:$Z$3
Name 新君威: '参数-车系车型 利率'!$AF$2:$AF$5
Name 至境L7: '参数-车系车型 利率'!$U$2:$U$7
Name 至境世家: '参数-车系车型 利率'!$AI$2:$AI$5

Sheet 试算路径及方案简述
B9: 注：1）本试算工具仅供试算参考，因精度问题客户月供及利息与实际情况可能存在差异，请以《汽车（抵押）贷款合同》所附的《还款计划表》为准； 2）在提交申请和签约时，请注意比对申请系统与试算表的方案名称，以免因选错方案导致最终还款金额与试算金额出现较大差异。
C13: 厂贴方案说明 | L13: 非厂贴方案
C14: 厂贴方案 有效期 | D14: 厂贴车型 | F14: 厂贴比例 | H14: 厂贴方案简述 | I14: 试算页链接 | J14: 合同年化利率 | L14: 方案有效期 | M14: 适用车系 | N14: 非厂贴试算页链接 | O14: 说明 | P14: 合同 年化利率
C15: 申请截止至：2026/4/30 放款截止至：2026/5/31 | D15: 全新GL8 陆尊 新能源 | E15: 全系 | F15: MSRP* | G15: 0.022 | H15: 常规低息 (18-60期） 1+4定额首年免息（60期） 双优贷2.0（60期） 双优贷1.0（60期） | I15: 厂贴_常规贴息（个人） | J15: 常规 5.99% 1+4阶梯贷 7.98% 双优贷2.0 11.60% 双优贷1.0 9.70% | L15: 申请截止至：2026/4/30 放款截止至：2026/5/31 | M15: 别克品牌 所有新车 | N15: 新通用-非厂商贴息 | O15: 不支持经销商贴息 | P15: 7.98%(GL8系列60期方案适用） 8.98%
I16: 厂贴_常规贴息（公户） | N16: 新通用-经销商贴息 | O16: 经销商贴息100元起
D17: GL8陆尊燃油版(26MY) | E17: 智享版/尊享版/奢享版 | F17: MSRP* | G17: 0.0219 | I17: 厂贴_1+4阶梯贷 | N17: 双优贷1.0-非厂商贴息 | O17: 不支持经销商贴息 | P17: 0.097
I18: 厂贴_双优贷2.0 | N18: 双优贷1.0-经销商贴息 | O18: 经销商贴息100元起
I19: 厂贴_双优贷1.0 | N19: 双优贷2.0-非厂商贴息 | O19: 不支持经销商贴息 | P19: 0.116
D20: 全新GL8陆上公务舱 | E20: 先享版/智享版/福祉版/智享DG-YZ版 注：智享DG-YZ版仅可申请公户方案 | F20: MSRP* | G20: 0.0232 | H20: 常规低息 (18-60期） 双优贷2.0（60期） 双优贷1.0（60期） | I20: 厂贴_常规贴息（个人） | J20: 常规 5.99% 双优贷2.0 11.60% 双优贷1.0 9.70% | N20: 双优贷2.0-经销商贴息 | O20: 经销商贴息100元起
D21: 至境L7 | E21: 全系 | F21: MSRP* | G21: 0.0213 | I21: 厂贴_常规贴息（公户） | N21: 注：陆上公务舱智享DG-YZ版为企业客户专享车型，仅可申请公户方案
D22: 25款世纪 | E22: 全系(25MY） | F22: MSRP* | G22: 0.008 | H22: 常规低息 (12-60期） 双优贷2.0（60期） 双优贷1.0（60期） | I22: 厂贴_双优贷2.0
I23: 厂贴_双优贷1.0
D24: 至境世家 | E24: 尊享版/奢享版 纯电奢享版/纯电奢享版哑光灰 | F24: MSRP* | G24: 0.0161 | H24: 常规低息 (18-60期） 双优贷2.0（60期） 双优贷1.0（60期） *注：支持经销商贴息；常规低息方案客户利率不得低于2.99% | I24: 厂贴_常规贴息（个人）世家 | J24: 常规 5.99% 双优贷2.0 11.60% 双优贷1.0 9.70%
I25: 厂贴_常规贴息（公户）世家
I26: 厂贴_双优贷 世家
D27: 昂科威Plus | E27: 全系（24MY及之后） | F27: MSRP* | G27: 0.016 | H27: 常规低息 (18-60期) 5050低息（12期） 6666定额低息（24期） 双优贷2.0（60期） 双优贷1.0（60期） | I27: 厂贴_常规贴息（个人） | J27: 常规 5.99% 5050智慧式 5.99% 6666分段式 5.99% 双优贷2.0 11.60% 双优贷1.0 9.70%
D28: 昂科威S | E28: 全系(24MY/25MY/26MY) | F28: MSRP* | G28: 0.0153 | I28: 厂贴_常规贴息（公户）
D29: 君越 | E29: 全系(25MY/26MY） | F29: MSRP* | G29: 0.0164
D30: 新君威 | E30: 全系 | F30: MSRP* | G30: 0.0154 | I30: 厂贴_5050 6666
D31: 微蓝6_450KM | E31: 舒享PLUS版/越享PLUS版 | F31: MSRP* | G31: 0.0182 | H31: 常规低息 (36-60期) 5050低息（12期） 双优贷2.0（60期） 双优贷1.0（60期） | I31: 厂贴_双优贷2.0
D32: 威朗Pro | E32: 全系 | F32: MSRP* | G32: 0.007 | H32: 常规低息 (18-60期) 5050低息（12期） 双优贷2.0（60期） 双优贷1.0（60期） | I32: 厂贴_双优贷1.0
C34: 参考链接 | D34: 厂贴车型明细&贷款金额说明
D35: 产品基础参数&准入政策
D36: 新能源首付低于20%时 最高贷款金额测算

Sheet 厂贴车型明细&贷款金额说明
B2: 返回 | D2: 注意： 1、请注意E速通系统所选车型与DOSS系统上报车型保持一致，尤其要注意区分新旧款车型，若因车型不一致导致的贴息差额，需由经销商承担，在其他客户放款金额中扣除，后续会开具经销商贴息发票； 2、关于具体的贴息结算，请以厂商公告为准或者与区域营销中心MAC进行确认；对于特殊折扣车辆（如试驾车、集团采购等），不享受厂商贴息支持，具体可通过店内销售经理“经销商业务百事通”账号进行查询（操作方法见右图）； 3、贴息方式：厂商直接贴息（无需经销商承担贴息费用；不扣减放款金额）， 4、大额零售业务可参考“厂贴-常规贴息等额本息类（低息）”【商用：营运】模块进行测算
F6: 常规贴息 （个人&公户） | L6: 1+4阶梯贷 （个人） | M6: 双优贷2.0 （个人） | N6: 双优贷1.0 （个人） | O6: 5050智慧贷 (个人） | P6: 6666分段式 （个人）
B7: 车系 | C7: E速通系统车型 | D7: 市场指导价 | E7: 厂商贴息 上限 | F7: 12期 贷款金额下限 | G7: 18期 贷款金额下限 | H7: 24期 贷款金额下限 | I7: 36期 贷款金额下限 | J7: 48期 贷款金额下限 | K7: 60期 贷款金额下限 | L7: 60期 贷款金额(定额) | M7: 60期 贷款金额下限 | N7: 60期 贷款金额下限 | O7: 12期 贷款金额下限 | P7: 24期 贷款金额(定额)
B8: GL8陆尊燃油版(26MY) | C8: GL8陆尊燃油版 智享版 | D8: 309900 | E8: =D8*VLOOKUP($B$8,试算路径及方案简述!D:G,4,0) -> 6786.81 | F8: 无方案 | G8: 168600 | H8: 160000 | I8: 160000 | J8: 160000 | K8: 160000 | L8: 80000 | M8: 50000 | N8: 50000 | O8: 无方案 | P8: 无方案
C9: GL8陆尊燃油版 尊享版 | D9: 339900 | E9: =D9*VLOOKUP($B$8,试算路径及方案简述!D:G,4,0) -> 7443.81 | F9: 无方案 | G9: 185000 | H9: 160000 | I9: 160000 | J9: 160000 | K9: 160000 | M9: 50000 | N9: 50000 | O9: 无方案 | P9: 无方案
C10: GL8陆尊燃油版 奢享版 | D10: 369900 | E10: =D10*VLOOKUP($B$8,试算路径及方案简述!D:G,4,0) -> 8100.81 | F10: 无方案 | G10: 201300 | H10: 160000 | I10: 160000 | J10: 160000 | K10: 160000 | M10: 50000 | N10: 50000 | O10: 无方案 | P10: 无方案
B11: 全新GL8 陆尊 新能源 | C11: 全新GL8陆尊 智享版 新能源 | D11: 339900 | E11: =D11*VLOOKUP($B$11,试算路径及方案简述!D:G,4,0) -> 7477.8 | F11: 无方案 | G11: 185800 | H11: 180000 | I11: 180000 | J11: 180000 | K11: 180000 | L11: 80000 | M11: 50000 | N11: 50000 | O11: 无方案 | P11: 无方案
C12: 全新GL8陆尊 尊享版 新能源 | D12: 369900 | E12: =D12*VLOOKUP($B$11,试算路径及方案简述!D:G,4,0) -> 8137.8 | F12: 无方案 | G12: 202200 | H12: 180000 | I12: 180000 | J12: 180000 | K12: 180000 | M12: 50000 | N12: 50000 | O12: 无方案 | P12: 无方案
C13: 全新GL8陆尊 奢享版 新能源 | D13: 399900 | E13: =D13*VLOOKUP($B$11,试算路径及方案简述!D:G,4,0) -> 8797.8 | F13: 无方案 | G13: 218600 | H13: 180000 | I13: 180000 | J13: 180000 | K13: 180000 | M13: 50000 | N13: 50000 | O13: 无方案 | P13: 无方案
B14: 全新GL8陆上公务舱 | C14: 先享版 | D14: 229900 | E14: =D14*VLOOKUP($B$14,试算路径及方案简述!D:G,4,0) -> 5333.68 | F14: 无方案 | G14: 132500 | H14: 120000 | I14: 120000 | J14: 120000 | K14: 120000 | L14: 无方案 | M14: 50000 | N14: 50000 | O14: 无方案 | P14: 无方案
C15: 智享版 | D15: 249900 | E15: =D15*VLOOKUP($B$14,试算路径及方案简述!D:G,4,0) -> 5797.68 | F15: 无方案 | G15: 144000 | H15: 120000 | I15: 120000 | J15: 120000 | K15: 120000 | L15: 无方案 | M15: 50000 | N15: 50000 | O15: 无方案 | P15: 无方案
C16: 福祉版 | D16: 299900 | E16: =D16*VLOOKUP($B$14,试算路径及方案简述!D:G,4,0) -> 6957.68 | F16: 无方案 | G16: 173000 | H16: 120000 | I16: 120000 | J16: 120000 | K16: 120000 | L16: 无方案 | M16: 50000 | N16: 50000 | O16: 无方案 | P16: 无方案
C17: 智享DG-YZ版 | D17: 258900 | E17: =D17*VLOOKUP($B$14,试算路径及方案简述!D:G,4,0) -> 6006.48 | F17: 无方案 | G17: 149200 | H17: 120000 | I17: 120000 | J17: 120000 | K17: 120000 | L17: 无方案 | M17: 无方案 | N17: 无方案 | O17: 无方案 | P17: 无方案 | Q17: 注：陆上公务舱智享DG-YZ版为企业客户专享车型，仅可申请公户方案
B18: 25款世纪 | C18: 25款世纪 7座臻享版 | D18: 469900 | E18: =D18*VLOOKUP($B$18,试算路径及方案简述!D:G,4,0) -> 3759.2 | F18: 228210 | G18: 150000 | H18: 150000 | I18: 150000 | J18: 150000 | K18: 150000 | L18: 无方案 | M18: 50000 | N18: 50000 | O18: 无方案 | P18: 无方案
C19: 25款世纪_6座/7座蕴世版 | D19: 529900 | E19: =D19*VLOOKUP($B$18,试算路径及方案简述!D:G,4,0) -> 4239.2 | F19: 257350 | G19: 150000 | H19: 150000 | I19: 150000 | J19: 150000 | K19: 150000 | L19: 无方案 | M19: 50000 | N19: 50000 | O19: 无方案 | P19: 无方案
C20: 25款世纪_4座私享版 | D20: 689900 | E20: =D20*VLOOKUP($B$18,试算路径及方案简述!D:G,4,0) -> 5519.2 | F20: 335050 | G20: 150000 | H20: 150000 | I20: 150000 | J20: 150000 | K20: 150000 | L20: 无方案 | M20: 50000 | N20: 50000 | O20: 无方案 | P20: 无方案
B21: 至境L7 | C21: 至境L7 尊享版 增程式 新能源 | D21: 173900 | E21: =D21*VLOOKUP($B$21,试算路径及方案简述!D:G,4,0) -> 3704.07 | F21: 无方案 | G21: 92060 | H21: 90000 | I21: 90000 | J21: 90000 | K21: 90000 | L21: 无方案 | M21: 50000 | N21: 50000 | O21: 无方案 | P21: 无方案
C22: 至境L7 奢享版 增程式 新能源 | D22: 186900 | E22: =D22*VLOOKUP($B$21,试算路径及方案简述!D:G,4,0) -> 3980.97 | F22: 无方案 | G22: 98940 | H22: 90000 | I22: 90000 | J22: 90000 | K22: 90000 | L22: 无方案 | M22: 50000 | N22: 50000 | O22: 无方案 | P22: 无方案
C23: 至境L7 尊享逍遥智行版 增程式 新能源 | D23: 193900 | E23: =D23*VLOOKUP($B$21,试算路径及方案简述!D:G,4,0) -> 4130.07 | F23: 无方案 | G23: 102650 | H23: 90000 | I23: 90000 | J23: 90000 | K23: 90000 | L23: 无方案 | M23: 50000 | N23: 50000 | O23: 无方案 | P23: 无方案
C24: 至境L7 奢享逍遥智行版 增程式 新能源 | D24: 206900 | E24: =D24*VLOOKUP($B$21,试算路径及方案简述!D:G,4,0) -> 4406.97 | F24: 无方案 | G24: 109530 | H24: 90000 | I24: 90000 | J24: 90000 | K24: 90000 | L24: 无方案 | M24: 50000 | N24: 50000 | O24: 无方案 | P24: 无方案
C25: 至境L7 艾维亚 增程式 新能源 | D25: 219900 | E25: =D25*VLOOKUP($B$21,试算路径及方案简述!D:G,4,0) -> 4683.87 | F25: 无方案 | G25: 116410 | H25: 90000 | I25: 90000 | J25: 90000 | K25: 90000 | L25: 无方案 | M25: 50000 | N25: 50000 | O25: 无方案 | P25: 无方案
C26: 至境L7 艾维亚(20) 增程式 新能源 | D26: 223900 | E26: =D26*VLOOKUP($B$21,试算路径及方案简述!D:G,4,0) -> 4769.07 | F26: 无方案 | G26: 118530 | H26: 90000 | I26: 90000 | J26: 90000 | K26: 90000 | L26: 无方案 | M26: 50000 | N26: 50000 | O26: 无方案 | P26: 无方案
B27: 至境世家 | C27: 至境世家尊享版 新能源 | D27: 439900 | E27: =D27*VLOOKUP($B$27,试算路径及方案简述!D:G,4,0) -> 7082.39 | F27: 无方案 | G27: 292100 | H27: 220300 | I27: 160000 | J27: 160000 | K27: 160000 | L27: 无方案 | M27: 50000 | N27: 50000 | O27: 无方案 | P27: 无方案
C28: 至境世家奢享版 新能源 | D28: 469900 | E28: =D28*VLOOKUP($B$27,试算路径及方案简述!D:G,4,0) -> 7565.39 | F28: 无方案 | G28: 311948 | H28: 235300 | I28: 160000 | J28: 160000 | K28: 160000 | L28: 无方案 | M28: 50000 | N28: 50000 | O28: 无方案 | P28: 无方案
C29: 至境世家 纯电奢享版 | D29: 489900 | E29: =D29*VLOOKUP($B$27,试算路径及方案简述!D:G,4,0) -> 7887.39 | F29: 无方案 | G29: 325200 | H29: 245300 | I29: 160000 | J29: 160000 | K29: 160000 | L29: 无方案 | M29: 50000 | N29: 50000 | O29: 无方案 | P29: 无方案
C30: 至境世家 纯电奢享版哑光灰 | D30: 499900 | E30: =D30*VLOOKUP($B$27,试算路径及方案简述!D:G,4,0) -> 8048.39 | F30: 无方案 | G30: 331800 | H30: 250300 | I30: 160000 | J30: 160000 | K30: 160000 | L30: 无方案 | M30: 50000 | N30: 50000 | O30: 无方案 | P30: 无方案
B31: 昂科威Plus | C31: 昂科威Plus 28T 白金版 | D31: 229900 | E31: =D31*VLOOKUP($B$31,试算路径及方案简述!D:G,4,0) -> 3678.4 | F31: 无方案 | G31: 91420 | H31: 80000 | I31: 80000 | J31: 80000 | K31: 80000 | L31: 无方案 | M31: 50000 | N31: 50000 | O31: 73565 | P31: 90000
C32: 昂科威Plus 28T 四驱白金版 | D32: 239900 | E32: =D32*VLOOKUP($B$31,试算路径及方案简述!D:G,4,0) -> 3838.4 | F32: 无方案 | G32: 95400 | H32: 80000 | I32: 80000 | J32: 80000 | K32: 80000 | L32: 无方案 | M32: 50000 | N32: 50000 | O32: 76765
C33: 昂科威Plus 艾维亚 | D33: 259900 | E33: =D33*VLOOKUP($B$31,试算路径及方案简述!D:G,4,0) -> 4158.4 | F33: 无方案 | G33: 103300 | H33: 80000 | I33: 80000 | J33: 80000 | K33: 80000 | L33: 无方案 | M33: 50000 | N33: 50000 | O33: 83165
B34: 昂科威S | C34: 昂科威S 25T 白金版 | D34: 196900 | E34: =D34*VLOOKUP($B$34,试算路径及方案简述!D:G,4,0) -> 3012.57 | F34: 无方案 | G34: 74850 | H34: 70000 | I34: 70000 | J34: 70000 | K34: 70000 | L34: 无方案 | M34: 50000 | N34: 50000 | O34: 60250 | P34: 90000
C35: 昂科威S 25T 进享白金版 | D35: 204900 | E35: =D35*VLOOKUP($B$34,试算路径及方案简述!D:G,4,0) -> 3134.97 | F35: 无方案 | G35: 77910 | H35: 70000 | I35: 70000 | J35: 70000 | K35: 70000 | L35: 无方案 | M35: 50000 | N35: 50000 | O35: 62650
B36: 君越 | C36: 君越 28T 白金版 | D36: 209900 | E36: =D36*VLOOKUP($B$36,试算路径及方案简述!D:G,4,0) -> 3442.36 | F36: 无方案 | G36: 85550 | H36: 80000 | I36: 80000 | J36: 80000 | K36: 80000 | L36: 无方案 | M36: 50000 | N36: 50000 | O36: 68845 | P36: 90000
C37: 君越 白金版艾维亚 | D37: 239900 | E37: =D37*VLOOKUP($B$36,试算路径及方案简述!D:G,4,0) -> 3934.36 | F37: 无方案 | G37: 97700 | H37: 80000 | I37: 80000 | J37: 80000 | K37: 80000 | L37: 无方案 | M37: 50000 | N37: 50000 | O37: 78685
B38: 新君威 | C38: 新君威 25T 超享版 | D38: 159800 | E38: =D38*VLOOKUP($B$38,试算路径及方案简述!D:G,4,0) -> 2460.92 | F38: 无方案 | G38: 61160 | H38: 55000 | I38: 55000 | J38: 55000 | K38: 55000 | L38: 无方案 | M38: 50000 | N38: 50000 | O38: 49215 | P38: 70000
C39: 新君威 28T 纵享版 | D39: 175800 | E39: =D39*VLOOKUP($B$38,试算路径及方案简述!D:G,4,0) -> 2707.32 | F39: 无方案 | G39: 67250 | H39: 55000 | I39: 55000 | J39: 55000 | K39: 55000 | L39: 无方案 | M39: 50000 | N39: 50000 | O39: 54145
C40: 新君威 超享版曜黑竞速 | D40: 162800 | E40: =D40*VLOOKUP($B$38,试算路径及方案简述!D:G,4,0) -> 2507.12 | F40: 无方案 | G40: 62300 | H40: 55000 | I40: 55000 | J40: 55000 | K40: 55000 | L40: 无方案 | M40: 50000 | N40: 50000 | O40: 50140
C41: 新君威 纵享版曜黑竞速 | D41: 178800 | E41: =D41*VLOOKUP($B$38,试算路径及方案简述!D:G,4,0) -> 2753.52 | F41: 无方案 | G41: 68400 | H41: 55000 | I41: 55000 | J41: 55000 | K41: 55000 | L41: 无方案 | M41: 50000 | N41: 50000 | O41: 55070
B42: 微蓝6_450KM | C42: 微蓝6 450KM舒享PLUS版 纯电动 新能源 | D42: 112800 | E42: =D42*VLOOKUP($B$42,试算路径及方案简述!D:G,4,0) -> 2052.96 | F42: 无方案 | G42: 无方案 | H42: 无方案 | I42: 30000 | J42: 30000 | K42: 30000 | L42: 无方案 | M42: 50000 | N42: 50000 | O42: 30000 | P42: 无方案
C43: 微蓝6 450KM越享PLUS版 纯电动 新能源 | D43: 117800 | E43: =D43*VLOOKUP($B$42,试算路径及方案简述!D:G,4,0) -> 2143.96 | F43: 无方案 | G43: 无方案 | H43: 无方案 | I43: 30000 | J43: 30000 | K43: 30000 | L43: 无方案 | M43: 50000 | N43: 50000 | O43: 30000 | P43: 无方案
B44: 威朗Pro | C44: 威朗Pro 乐行版 | D44: 129900 | E44: =D44*VLOOKUP($B$44,试算路径及方案简述!D:G,4,0) -> 909.3 | F44: 无方案 | G44: 31000 | H44: 31000 | I44: 31000 | J44: 31000 | K44: 31000 | L44: 无方案 | M44: 50000 | N44: 50000 | O44: 30000 | P44: 无方案
...

Sheet 厂贴_1+4阶梯贷
A2: 第一步：选车系、车型，并修改贷款参数 | I2: 返回
A3: 车系* | B3: 全新GL8_陆尊_新能源 | D3: 请注意:原“新君威”车型不享受贴息，可在试算表 新君威 VIN查询 Sheet确认具体车辆是否可享受贴息
A4: 车型* | B4: 全新GL8陆尊 尊享版 新能源
A5: 市场指导价(MSRP) | B5: =VLOOKUP(B4,'厂贴车型明细&贷款金额说明'!C:D,2,0) -> 369900 | F5: 说明： 1、表格中蓝底白字的单元格，为可修改项。可直接输入或从下拉菜单中进行选择。 2、当某‘还款方式’的试算行多处显示 #VALUE! 或 *N/A 时，或K列/L列显示'无方案'时，即表示所选车型无此“还款方式”或 对应期限 的贴息方案 3、系统录入选择贷款方案时，注意选择带有“方案名称关键字”的方案名称 4、1+4阶梯贷方案不支持附加品贷
A6: 车辆开票价(TP)* | B6: 200000
B7: 0
A8: 总价 | B8: =IF((B6+B7)<=B5*115%,(B6+B7),"总价超限,请调整") -> 200000
A9: （固定）贷款金额* | B9: =VLOOKUP(B4,'参数-车系车型 利率'!B19:Q32,16,0) -> 80000
D11: *经销商贴息需填写在系统的‘经销商补贴金额’处
Q12: 贴息超限，请调整
A13: 第二步：查看试算结果
A14: 贷款方案 | B14: 首付比例 | C14: 首付金额 | D14: 首付比例不得低于： | E14: 0.2
A15: 首年0息 （定额1+4阶梯贷） | B15: =C15/B6 -> 0.6 | C15: =B6-B9 -> 120000 | M15: 提前还款测算参考：
L16: 还满12期提前还款测算参考：
B17: 期限 | C17: 客户试算月供 | D17: 客户试算总利息 | E17: 客户试算年化利率 | F17: 客户试算年化费率 | G17: 合同综合 年化利率 | H17: 厂商贴息 金额参考 | I17: 系统方案名称关键字 | L17: 提前还款期数 | M17: 12 | O17: 还满12期免提前还款手续费
B18: 1-12期 | C18: =ROUNDUP(PMT(0%/12,12,-B9*(VLOOKUP(B4,'参数-车系车型 利率'!B19:S37,18,0))),2) -> 298.67 | D18: 0 | E18: 0 | F18: 0 | G18: =VLOOKUP(B4,'参数-车系车型 利率'!B19:T37,19,0) -> 0.0523 | H18: =VLOOKUP(B4,'参数-车系车型 利率'!B19:T37,17,0) -> 6254.8 | I18: =VLOOKUP(B4,'参数-方案配置'!C4:L24,10,0) -> 个人申请：厂贴_常规贴息_60期8万定额贷_1+4阶梯贷 | L18: 剩余本金 | M18: =IF(M17<13,B9-C18*M17,B9-(C19*(M17-12)+C18*12-M20)) -> 76415.96
B19: 13-60期 | C19: =ROUNDUP(PMT(VLOOKUP(B4,'参数-车系车型 利率'!B19:P37,15,0)/12,48,-(B9-C18*12)),2) -> 1864.82 | D19: =C19*48-(B9-C18*12) -> 13095.4 | E19: =RATE(48,-C19,B9-(C18*12))*12 -> 0.079800116 | F19: =D19/(B9-C18*12)/4 -> 0.04284249 | L19: 可节省利息 | M19: =D19-M20 -> 13095.4
I20: 注：通过小管家报单的申请，请先任选一个方案提交到E速通，再修改为“1+4阶梯贷”方案后正式发送申请 | K20: 已还利息 | M20: =IF(M17<13,0,(B9*(E19/12)-C19)*((1+(E19/12))^(M17-12)-1)/(E19/12)+(C19)*(M17-12)) -> 0

Sheet 厂贴_常规贴息（个人）世家
A2: 第一步：选车系、车型，并修改贷款参数 | E2: 第二步：按需填写附加品贷款参数 | M2: 返回
A3: 车系* | B3: 至境世家 | E3: 附加品合计金额* （税、险、精品等） | F3: 0
A4: 车型* | B4: 至境世家 纯电奢享版哑光灰 | E4: 附加品贷款金额* | F4: 0 | H4: 说明： 1、表格中蓝底白字的单元格，为可修改项。可直接输入或从下拉菜单中进行选择。 2、当“车辆贷款金额下限”或“车辆贷款金额上限”数值项变为 红字且黄色高亮时，需调整第7行“车辆贷款金额”输入的数值 3、当“客户试算年化利率”数值项变为 红字且带删除线，需调整第7行“车辆贷款金额”及第4行“附加品贷款金额”输入的数值 4、系统录入选择贷款方案时，注意选择带有“方案名称关键字”的方案名称 5、24期/18期2.99%起方案的试算结果请查看本试算页第27、28行
A5: 市场指导价(MSRP) | B5: =VLOOKUP(B4,'厂贴车型明细&贷款金额说明'!C:D,2,0) -> 499900 | E5: 附加品首付比例 | F5: =(F3-F4)/F3 -> #DIV/0!
A6: 车辆开票价(TP)* | B6: 469900 | E6: 附加品首付比例不得低于20%
A7: 车辆贷款金额* | B7: 331800 | E7: 总价 (车价+附加品） | F7: =B6+F3 -> 469900
A8: 车辆首付比例： | B8: =(B6-B7)/B6 -> 0.29389232 | C8: 车辆首付比例不得低于： | D8: =VLOOKUP($B$3,'参数-车系车型 利率'!M:N,2,0) -> 0.15 | E8: 总价不得超过： | F8: =B5*115% -> 574885
A9: 经销商贴息 （选填，0元起） | B9: 0 | C9: *经销商贴息需填写在系统的‘经销商补贴金额’处
B10: 注：公牌/个体户类/商用申请 车辆首付30%起（陆尊PHEV、陆尚PHEV、陆尊新能源、至境L7、微蓝为25%起） | U10: 贴息超限，请调整
A11: 第二步：查看试算结果
A12: 贷款方案1 | B12: 贷款金额合计 （36-60期方案适用） | C12: 首付金额合计 | D12: 客户首付比例
A13: 低首付低利率 （等额本息类） | B13: =B7+F4 -> 331800 | C13: =F7-B7-F4 -> 138100 | D13: =C13/F7 -> 0.29389232
B15: 期限 | C15: 客户试算月供 | D15: 客户试算总利息 | E15: 客户试算年化利率 | F15: 客户试算年化费率 | G15: 客户试算总费率 | H15: 厂商贴息金额参考 | I15: 厂贴上限 | J15: 免息贴息金额 | K15: 车辆贷款金额 上限 | L15: 车辆贷款金额 下限 | M15: 系统方案名称关键字 | P15: 60期提前还款测算参考：
B16: 60期 | C16: =ROUNDUP(PMT(VLOOKUP(B4,'参数-车系车型 利率'!B:I,2,0)/12,60,-$B$7)-(H16)/60+(PMT(10%/12,60,-F4)-B9/60),2) -> 6278.95 | D16: =C16*60-B7-F4 -> 44937 | E16: =RATE(60,-C16,(B7+F4))*12 -> 0.051148571 | F16: =D16/(B7+F4)/5 -> 0.027086799 | G16: =D16/(B7+F4) -> 0.135434 | H16: =MIN($I$16,J16) -> 8048.39 | I16: =VLOOKUP($B$4,'厂贴车型明细&贷款金额说明'!C:E,3,0) -> 8048.39 | J16: =$B$7*VLOOKUP(B16,'参数-车系车型 利率'!$B$78:$C$83,2,0) -> 52991.778 | K16: =ROUNDUP(I16/VLOOKUP(B16,'参数-车系车型 利率'!B78:C83,2,0),0)-1 -> 50393 | L16: =VLOOKUP($B$4,'厂贴车型明细&贷款金额说明'!C:K,9,0) -> 160000 | M16: =VLOOKUP(B4,'参数-方案配置'!C:E,2,0) -> 个人申请：厂贴_5.99贴息 新优速贷/个体工商户升级 36-60期 | O16: 提前还款期数 | P16: 24 | R16: 还满24期免提前还款手续费
B17: 48期 | C17: =ROUNDUP(PMT(VLOOKUP(B4,'参数-车系车型 利率'!B:I,3,0)/12,48,-$B$7)-(H17)/48+(PMT(10%/12,48,-F4)-B9/48),2) -> 7623.14 | D17: =C17*48-B7-F4 -> 34110.72 | E17: =RATE(48,-C17,(B7+F4))*12 -> 0.048802899 | F17: =D17/(B7+F4)/4 -> 0.025701266 | G17: =D17/(B7+F4) -> 0.10280506 | H17: =MIN($I$16,J17) -> 8048.39 | J17: =$B$7*VLOOKUP(B17,'参数-车系车型 利率'!$B$78:$C$83,2,0) -> 42166.969 | K17: =ROUNDUP(I16/VLOOKUP(B17,'参数-车系车型 利率'!B78:C83,2,0),0)-1 -> 63330 | L17: =VLOOKUP($B$4,'厂贴车型明细&贷款金额说明'!C:K,8,0) -> 160000 | O17: 剩余本金 | P17: =B13-(C16*P16-P19) -> 209141.53
B18: 36期 | C18: =ROUNDUP(PMT(VLOOKUP(B4,'参数-车系车型 利率'!B:I,4,0)/12,36,-$B$7)-(H18)/36+(PMT(10%/12,36,-F4)-B9/36),2) -> 9868.93 | D18: =C18*36-B7-F4 -> 23481.48 | E18: =RATE(36,-C18,(B7+F4))*12 -> 0.044925847 | F18: =D18/(B7+F4)/3 -> 0.023589994 | G18: =D18/(B7+F4) -> 0.070769982 | H18: =MIN($I$16,J18) -> 8048.39 | J18: =$B$7*VLOOKUP(B18,'参数-车系车型 利率'!$B$78:$C$83,2,0) -> 31531.979 | K18: =ROUNDUP(I16/VLOOKUP(B18,'参数-车系车型 利率'!B78:C83,2,0),0)-1 -> 84690 | L18: =VLOOKUP($B$4,'厂贴车型明细&贷款金额说明'!C:K,7,0) -> 160000 | O18: 可节省利息 | P18: =D16-P19 -> 16900.671
B19: 24期 | C19: =ROUNDUP(PMT(VLOOKUP(B4,'参数-车系车型 利率'!B:I,5,0)/12,24,-$B$7)-H19/24,2) -> 14259.7 | D19: =C19*24-B7-F4 -> 10432.8 | E19: =RATE(24,-C19,(B7+F4))*12 -> 0.0299001 | F19: =D19/(B7+F4)/2 -> 0.015721519 | G19: =D19/(B7+F4) -> 0.031443038 | H19: =B7*0.032144 -> 10665.379 | J19: =$B$7*VLOOKUP(B19,'参数-车系车型 利率'!$B$78:$C$83,2,0) -> 21098.83 | K19: =IF(B4="至境世家尊享版 新能源",220000,235000) -> 235000 | L19: =VLOOKUP($B$4,'厂贴车型明细&贷款金额说明'!C:K,6,0) -> 250300 | M19: 个人申请：厂贴_5.99贴息 新优速贷/个体工商户升级 24期 固定2.99% | O19: 已还利息 | P19: =(B13*(E16/12)-C16)*((1+(E16/12))^(P16)-1)/(E16/12)+(C16)*P16 -> 28036.329
B20: 18期 | C20: =ROUNDUP(PMT(VLOOKUP(B4,'参数-车系车型 利率'!B:I,6,0)/12,18,-$B$7)-H20/18,2) -> 18872.73 | D20: =C20*18-B7-F4 -> 7909.14 | E20: =RATE(18,-C20,(B7+F4))*12 -> 0.029899179 | F20: =D20/(B7+F4)/1.5 -> 0.01589138 | G20: =D20/(B7+F4) -> 0.023837071 | H20: =B7*0.024253 -> 8047.1454 | J20: =$B$7*VLOOKUP(B20,'参数-车系车型 利率'!$B$78:$C$83,2,0) -> 15957.506 | K20: =IF(B4="至境世家尊享版 新能源",291000,311000) -> 311000 | L20: =VLOOKUP($B$4,'厂贴车型明细&贷款金额说明'!C:K,5,0) -> 331800 | M20: 个人申请：厂贴_5.99贴息 新优速贷/个体工商户升级 18期 固定2.99%
A23: 贷款方案2 | B23: 贷款金额合计 | C23: 首付金额合计 | D23: 客户首付比例
A24: 低首付低利率 （等额本息类） | B24: =B7+F4 -> 331800 | C24: =F7-B7-F4 -> 138100 | D24: =C24/F7 -> 0.29389232
B26: 期限 | C26: 客户试算月供 | D26: 客户试算总利息 | E26: 客户试算年化利率 | F26: 客户试算年化费率 | G26: 客户试算总费率 | H26: 厂商贴息金额参考 | I26: 厂贴上限 | J26: 免息贴息金额 | L26: 车辆贷款金额 下限 | M26: 系统方案名称关键字
B27: 24期 | C27: =ROUNDUP(PMT(VLOOKUP(B4,'参数-车系车型 利率'!B:I,5,0)/12,24,-$B$7)-(H27)/24+(PMT(10%/12,24,-F4)-B9/24),2) -> 14368.74 | D27: =C27*24-B7-F4 -> 13049.76 | E27: =RATE(24,-C27,(B7+F4))*12 -> 0.037312973 | F27: =D27/(B7+F4)/2 -> 0.019665099 | G27: =D27/(B7+F4) -> 0.039330199 | H27: =MIN($I$16,J27) -> 8048.39 | I27: =VLOOKUP($B$4,'厂贴车型明细&贷款金额说明'!C:E,3,0) -> 8048.39 | J27: =$B$7*VLOOKUP(B27,'参数-车系车型 利率'!$B$78:$C$83,2,0) -> 21098.83 | K27: =ROUNDUP(I27/VLOOKUP(B27,'参数-车系车型 利率'!B89:C94,2,0),0)-1 -> #N/A | L27: =VLOOKUP($B$4,'厂贴车型明细&贷款金额说明'!C:K,6,0) -> 250300 | M27: 个人申请：厂贴_5.99贴息 新优速贷/个体工商户升级 24期
B28: 18期 | C28: =ROUNDUP(PMT(VLOOKUP(B4,'参数-车系车型 利率'!B:I,6,0)/12,18,-$B$7)-(H28)/18+(PMT(10%/12,18,-F4)-B9/18),2) -> 18872.66 | D28: =C28*18-B7-F4 -> 7907.88 | E28: =RATE(18,-C28,(B7+F4))*12 -> 0.029894449 | F28: =D28/(B7+F4)/1.5 -> 0.015888849 | G28: =D28/(B7+F4) -> 0.023833273 | H28: =MIN($I$16,J28) -> 8048.39 | J28: =$B$7*VLOOKUP(B28,'参数-车系车型 利率'!$B$78:$C$83,2,0) -> 15957.506 | K28: =ROUNDUP(I24/VLOOKUP(B28,'参数-车系车型 利率'!B86:C91,2,0),0)-1 -> #N/A | L28: =VLOOKUP($B$4,'厂贴车型明细&贷款金额说明'!C:K,5,0) -> 331800 | M28: =IF(B4="至境世家尊享版 新能源","个人申请：厂贴_5.99贴息 新优速贷/个体工商户升级 18期","个人申请：厂贴_5.99贴息 新优速贷 18期") -> 个人申请：厂贴_5.99贴息 新优速贷 18期

Sheet 厂贴_常规贴息（公户）世家
A2: 第一步：选车系、车型，并修改贷款参数 | M2: 返回
A3: 车系* | B3: 至境世家
A4: 车型* | B4: 至境世家 纯电奢享版哑光灰 | H4: 说明： 1、表格中蓝底白字的单元格，为可修改项。可直接输入或从下拉菜单中进行选择。 2、当“贷款金额下限”或“贷款金额上限”数值项变为 红字且黄色高亮时，需调整第9行“贷款金额”输入的数值 3、当“客户试算年化利率”数值项变为 红字且带删除线，需调整第9行“贷款金额”输入的数值 4、系统录入选择贷款方案时，注意选择带有“方案名称关键字”的方案名称 5、24期/18期 2.99%起方案的试算结果请查看本试算页第28、29行
A5: 市场指导价(MSRP) | B5: =VLOOKUP(B4,'厂贴车型明细&贷款金额说明'!C:D,2,0) -> 499900
A6: 车辆开票价(TP)* | B6: 469900
A7: 附加品金额* | B7: 0
A8: 总价 (车价+附加品） | B8: =B6+B7 -> 469900 | D8: 总价上限： | E8: =B5*115% -> 574885
A9: 贷款金额* | B9: 250300
A10: 经销商贴息 （低息-选填） | B10: 0 | C10: *经销商贴息需填写在系统的‘经销商补贴金额’处
U11: 贴息超限，请调整
A12: 第二步：查看试算结果
A13: 贷款方案1 | B13: 首付比例 | C13: 首付金额
A14: 低首付低利率 （等额本息类） | B14: =C14/B8 -> 0.46733348 | C14: =B8-B9 -> 219600 | D14: 注：公牌/个体户类/商用申请 首付30%起（新能源车为25%起）
B16: 期限 | C16: 客户试算月供 | D16: 客户试算总利息 | E16: 客户试算年化利率 | F16: 客户试算年化费率 | G16: 客户试算总费率 | H16: 厂商贴息金额参考 | I16: 厂贴上限 | J16: 免息贴息金额 | K16: 贷款金额 上限 | L16: 车辆贷款金额 下限 | M16: 系统方案名称关键字 | P16: 60期提前还款测算参考：
B17: 60期 | C17: =ROUNDUP(PMT(VLOOKUP(B4,'参数-车系车型 利率'!B:I,2,0)/12,60,-$B$9)-(H17+B10)/60,2) -> 4703.7 | D17: =C17*60-B9 -> 31922 | E17: =RATE(60,-C17,(B9))*12 -> 0.048273763 | F17: =D17/(B9)/5 -> 0.025506992 | G17: =D17/(B9) -> 0.12753496 | H17: =MIN($I$17,J17) -> 8048.39 | I17: =VLOOKUP($B$4,'厂贴车型明细&贷款金额说明'!C:E,3,0) -> 8048.39 | J17: =$B$9*VLOOKUP(B17,'参数-车系车型 利率'!$B$78:$C$83,2,0) -> 39975.413 | K17: =ROUNDUP(I17/VLOOKUP(B17,'参数-车系车型 利率'!B78:C83,2,0),0)-1 -> 50393 | L17: =VLOOKUP($B$4,'厂贴车型明细&贷款金额说明'!C:K,9,0) -> 160000 | M17: =VLOOKUP(B4,'参数-方案配置'!C:H,6,0) -> 企业申请：厂贴_5.99贴息 新公牌易贷/个体工商户 36-60期 企业商用：厂贴_5.99贴息 营运租赁 36期 | O17: 提前还款期数 | P17: 24 | R17: 还满24期免提前还款手续费
B18: 48期 | C18: =ROUNDUP(PMT(VLOOKUP(B4,'参数-车系车型 利率'!B:I,3,0)/12,48,-$B$9)-(H18+B10)/48,2) -> 5709.49 | D18: =C18*48-B9 -> 23755.52 | E18: =RATE(48,-C18,(B9))*12 -> 0.045157706 | F18: =D18/(B9)/4 -> 0.023727048 | G18: =D18/(B9) -> 0.09490819 | H18: =MIN($I$17,J18) -> 8048.39 | J18: =$B$9*VLOOKUP(B18,'参数-车系车型 利率'!$B$78:$C$83,2,0) -> 31809.501 | K18: =ROUNDUP(I17/VLOOKUP(B18,'参数-车系车型 利率'!B78:C83,2,0),0)-1 -> 63330 | L18: =VLOOKUP($B$4,'厂贴车型明细&贷款金额说明'!C:K,8,0) -> 160000 | O18: 剩余本金 | P18: =B9-(C17*P17-P20) -> 157348.83
B19: 36期 | C19: =ROUNDUP(PMT(VLOOKUP(B4,'参数-车系车型 利率'!B:I,4,0)/12,36,-$B$9)-(H19+B10)/36,2) -> 7389.92 | D19: =C19*36-B9 -> 15737.12 | E19: =RATE(36,-C19,(B9))*12 -> 0.040005977 | F19: =D19/(B9)/3 -> 0.020957677 | G19: =D19/(B9) -> 0.062873032 | H19: =MIN($I$17,J19) -> 8048.39 | J19: =$B$9*VLOOKUP(B19,'参数-车系车型 利率'!$B$78:$C$83,2,0) -> 23786.782 | K19: =ROUNDUP(I17/VLOOKUP(B19,'参数-车系车型 利率'!B78:C83,2,0),0)-1 -> 84690 | L19: =VLOOKUP($B$4,'厂贴车型明细&贷款金额说明'!C:K,7,0) -> 160000 | O19: 可节省利息 | P19: =D17-P20 -> 11984.373
B20: 24期 | C20: =ROUNDUP(PMT(VLOOKUP(B4,'参数-车系车型 利率'!B:I,5,0)/12,24,-$B$9)-H20/24,2) -> 10757.09 | D20: =C20*24-B9 -> 7870.16 | E20: =RATE(24,-C20,(B9))*12 -> 0.029899978 | F20: =D20/(B9)/2 -> 0.015721454 | G20: =D20/B9 -> 0.031442909 | H20: =B9*0.032144 -> 8045.6432 | J20: =$B$9*VLOOKUP(B20,'参数-车系车型 利率'!$B$78:$C$83,2,0) -> 15916.327 | K20: =IF(B5="至境世家尊享版 新能源",220000,235000) -> 235000 | L20: =VLOOKUP($B$4,'厂贴车型明细&贷款金额说明'!C:K,6,0) -> 250300 | M20: 企业申请：厂贴_5.99贴息 新公牌易贷/个体工商户 24期 固定2.99% 企业商用：厂贴_5.99贴息 营运租赁 24期 固定2.99% | O20: 已还利息 | P20: =(B9*(E17/12)-C17)*((1+(E17/12))^(P17)-1)/(E17/12)+(C17)*P17 -> 19937.627
B21: 18期 | C21: =ROUNDUP(PMT(VLOOKUP(B4,'参数-车系车型 利率'!B:I,6,0)/12,18,-$B$9)-H21/18,2) -> 14237.02 | D21: =C21*18-B9 -> 5966.36 | E21: =RATE(18,-C21,(B9))*12 -> 0.029898887 | F21: =D21/(B9)/1.5 -> 0.015891224 | G21: =D21/B9 -> 0.023836836 | H21: =B9*0.024253 -> 6070.5259 | J21: =$B$9*VLOOKUP(B21,'参数-车系车型 利率'!$B$78:$C$83,2,0) -> 12037.866 | K21: =IF(B5="至境世家尊享版 新能源",291000,311000) -> 311000 | L21: =VLOOKUP($B$4,'厂贴车型明细&贷款金额说明'!C:K,5,0) -> 331800 | M21: 企业申请：厂贴_5.99贴息 新公牌易贷/个体工商户 18期 固定2.99% 企业商用：厂贴_5.99贴息 营运租赁 18期 固定2.99%
A24: 贷款方案2 | B24: 首付比例 | C24: 首付金额
A25: 低首付低利率 （等额本息类） | B25: =C25/B8 -> 0.46733348 | C25: =B8-B9 -> 219600 | D25: 注：公牌/个体户类/商用申请 首付30%起（新能源车为25%起）
B27: 期限 | C27: 客户试算月供 | D27: 客户试算总利息 | E27: 客户试算年化利率 | F27: 客户试算年化费率 | G27: 客户试算总费率 | H27: 厂商贴息金额参考 | I27: 厂贴上限 | J27: 免息贴息金额 | L27: 贷款金额 下限 | M27: 系统方案名称关键字
B28: 24期 | C28: =ROUNDUP(PMT(VLOOKUP(B4,'参数-车系车型 利率'!B:I,5,0)/12,24,-$B$9)-(H28+B10)/24,2) -> 10756.98 | D28: =C28*24-B9 -> 7867.52 | E28: =RATE(24,-C28,(B9))*12 -> 0.029890042 | F28: =D28/(B9)/2 -> 0.015716181 | G28: =D28/B9 -> 0.031432361 | H28: =MIN($I$17,J28) -> 8048.39 | I28: =VLOOKUP($B$4,'厂贴车型明细&贷款金额说明'!C:E,3,0) -> 8048.39 | J28: =$B$9*VLOOKUP(B28,'参数-车系车型 利率'!$B$78:$C$83,2,0) -> 15916.327 | K28: =ROUNDUP(I28/VLOOKUP(B28,'参数-车系车型 利率'!B89:C94,2,0),0)-1 -> #N/A | L28: =VLOOKUP($B$4,'厂贴车型明细&贷款金额说明'!C:K,6,0) -> 250300 | M28: 企业申请：厂贴_5.99贴息 新公牌易贷/个体工商户 24期 企业商用：厂贴_5.99贴息 营运租赁 24期
B29: 18期 | C29: =ROUNDUP(PMT(VLOOKUP(B4,'参数-车系车型 利率'!B:I,6,0)/12,18,-$B$9)-(H29+B10)/18,2) -> 14127.14 | D29: =C29*18-B9 -> 3988.52 | E29: =RATE(18,-C29,(B9))*12 -> 0.020033686 | F29: =D29/(B9)/1.5 -> 0.010623305 | G29: =D29/B9 -> 0.015934958 | H29: =MIN($I$17,J29) -> 8048.39 | J29: =$B$9*VLOOKUP(B29,'参数-车系车型 利率'!$B$78:$C$83,2,0) -> 12037.866 | L29: =VLOOKUP($B$4,'厂贴车型明细&贷款金额说明'!C:K,5,0) -> 331800 | M29: =VLOOKUP(B4,'参数-方案配置'!C:I,7,0) -> 企业申请：厂贴_5.99贴息 新公牌易贷 18期 企业商用：厂贴_5.99贴息 营运租赁 18期

Sheet 厂贴_双优贷 世家
A2: 第一步：选车系、车型，并修改贷款参数 | J2: 返回 | L2: 可申请的最低首付比例： | M2: 0.2
A3: 车系* | B3: 至境世家 | L3: 裸车提车支出包装： | M3: 699
A4: 车型* | B4: 至境世家尊享版 新能源 | L4: 车辆开票价： | M4: =B6 -> 439900
A5: 市场指导价(MSRP) | B5: =VLOOKUP(B4,'厂贴车型明细&贷款金额说明'!C:D,2,0) -> 439900 | L5: 需至少打包的附加品金额： | M5: =(M4*M2-M3)/(1-M2)+1 -> 109102.25 | N5: 需符合附加品上限要求
A6: 车辆开票价(TP)* | B6: 439900 | F6: 说明： 1、表格中蓝底白字的单元格，为可修改项。可直接输入或从下拉菜单中进行选择。 2、当“贷款金额下限”或“贷款金额上限数值项变为 红字且黄色高亮时，需调整第9行“贷款金额”输入的数值 3、系统录入选择贷款方案时，注意选择带有“方案名称关键字”的方案名称 4、双优贷2.0及双优贷1.0方案仅可附加购置税及保险费 5、双优贷1.0方案试算结果请查看本试算页第28行 | L6: 贷款金额为： | M6: =M4-M3 -> 439201
A7: 附加品金额* （仅限购置税&保费） | B7: 0
A8: 总价 | B8: =B6+B7 -> 439900 | D8: 总价上限： | E8: =B5*115% -> 505885
A9: 贷款金额* | B9: 239000 | D9: *请将贷款金额调整至低于车辆开票价
A10: 经销商贴息 （选填，0元起） | B10: 0 | C10: *经销商贴息需填写在系统的‘经销商补贴金额’处
B11: 0 | D11: *经销商贴息需填写在系统的‘经销商补贴金额’处 | L11: 60期月供支出包装: | M11: 2399
L12: 计算得出贷款金额为： | M12: =PV(11.6%/12,60,-(M11+H18/60)) -> 114188.53 | R12: 贴息超限，请调整
A13: 第二步：查看试算结果
A14: 贷款方案1 | B14: 首付比例 | C14: 首付金额 | D14: 首付比例不得低于： | E14: =VLOOKUP($B$3,'参数-车系车型 利率'!M:N,2,0) -> 0.15
A15: 双优贷2.0 （等额本息类） | B15: =C15/B8 -> 0.4566947 | C15: =B8-B9 -> 200900 | D15: 注：新能源车为15%起
B17: 期限 | C17: 客户试算月供 | D17: 客户试算总利息 | E17: 客户试算年化利率 | F17: 客户试算年化费率 | G17: 客户试算总费率 | H17: 厂商贴息金额参考 | I17: 贷款金额下限 | J17: 系统方案名称关键字 | M17: 提前还款测算参考：
B18: 60期 | C18: =PMT(E18/12,60,-$B$9) -> 5151.2612 | D18: =C18*60-B9 -> 70075.67 | E18: =ROUNDUP(RATE(60,-C19,B9)*12,4) -> 0.1062 | F18: =D18/$B$9/5 -> 0.058640728 | G18: =D18/$B$9 -> 0.29320364 | H18: =VLOOKUP($B$4,'厂贴车型明细&贷款金额说明'!C:E,3,0) -> 7082.39 | I18: =VLOOKUP(B4,'厂贴车型明细&贷款金额说明'!C:N,11,0) -> 50000 | J18: =VLOOKUP(B4,'参数-方案配置'!C:K,8,0) -> 个人申请：厂贴_双优贷2.0_新优速贷_60期 | L18: 提前还款期数 | M18: 30 | O18: 还满30期免提前还款手续费
C19: =ROUNDUP(PMT(VLOOKUP(B4,'参数-车系车型 利率'!B:N,13,0)/12,60,-$B$9)-(H18+B10)/60,2) -> 5150.2 | L19: 剩余本金 | M19: =B9-(C18*M18-M21) -> 135202.52
L20: 可节省利息 | M20: =D18-M21 -> 19335.319
L21: 已还利息 | M21: =(B9*(E18/12)-C18)*((1+(E18/12))^(M18)-1)/(E18/12)+(C18)*M18 -> 50740.351
A24: 贷款方案2 | B24: 首付比例 | C24: 首付金额 | D24: 首付比例不得低于： | E24: =VLOOKUP($B$3,'参数-车系车型 利率'!M:N,2,0) -> 0.15
A25: 双优贷1.0 （等额本息类） | B25: =C15/B8 -> 0.4566947 | C25: =B8-B9 -> 200900 | D25: 注：新能源车为15%起
B27: 期限 | C27: 客户试算月供 | D27: 客户试算总利息 | E27: 客户试算年化利率 | F27: 客户试算年化费率 | G27: 客户试算总费率 | H27: 厂商贴息金额参考 | I27: 贷款金额下限 | J27: 系统方案名称关键字 | M27: 提前还款测算参考：
B28: 60期 | C28: =PMT(E28/12,60,-$B$9) -> 4925.366 | D28: =C28*60-B9 -> 56521.96 | E28: =ROUNDUP(RATE(60,-C29,B9)*12,4) -> 0.0869 | F28: =D28/$B$9/5 -> 0.047298711 | G28: =D28/$B$9 -> 0.23649356 | H28: =VLOOKUP($B$4,'厂贴车型明细&贷款金额说明'!C:E,3,0) -> 7082.39 | I28: =VLOOKUP(B4,'厂贴车型明细&贷款金额说明'!C:N,12,0) -> 50000 | J28: =VLOOKUP(B4,'参数-方案配置'!C:K,9,0) -> 个人申请：厂贴_双优贷1.0_新优速贷_60期 | L28: 提前还款期数 | M28: 12 | O28: 还满30期免提前还款手续费
C29: =ROUNDUP(PMT(VLOOKUP(B4,'参数-车系车型 利率'!B:Q,14,0)/12,60,-$B$9)-(H18+B10)/60,2) -> 4924.8 | L29: 剩余本金 | M29: =B9-(C28*M28-M31) -> 199100.38
L30: 可节省利息 | M30: =D28-M31 -> 37317.187
L31: 已还利息 | M31: =(B9*(E28/12)-C28)*((1+(E28/12))^(M28)-1)/(E28/12)+(C28)*M28 -> 19204.773

Sheet 厂贴_常规贴息（个人）
A2: 第一步：选车系、车型，并修改贷款参数 | E2: 第二步：按需填写附加品贷款参数（注：不适用12期方案） | M2: 返回
A3: 车系* | B3: 至境L7 | E3: 附加品合计金额* （税、险、精品等） | F3: 0
A4: 车型* | B4: GL8陆尊燃油版 尊享版 | E4: 附加品贷款金额* | F4: 0 | H4: 说明： 1、表格中蓝底白字的单元格，为可修改项。可直接输入或从下拉菜单中进行选择。 2、当“车辆贷款金额下限”数值项变为 红字且黄色高亮时，需调整第7行“车辆贷款金额”输入的数值 3、当某‘还款方式’的试算行多处显示 #VALUE! 或 *N/A 时，或K列/L列显示'无方案'时，即表示所选车型无此“还款方式”或 对应期限 的贴息方案（注：陆上公务舱'智享DG-YZ版'为企业客户专享车型，仅可申请公户方案） 4、系统录入选择贷款方案时，注意选择带有“方案名称关键字”的方案名称 5、12期厂贴 常规贴息方案不支持附加品贷，试算12期方案时应确保第3行‘附加品合计金额’及第4行‘附加品贷款金额’项数值为0
A5: 市场指导价(MSRP) | B5: =VLOOKUP(B4,'厂贴车型明细&贷款金额说明'!C:D,2,0) -> 339900 | E5: 附加品首付比例 | F5: =(F3-F4)/F3 -> #DIV/0!
A6: 车辆开票价(TP)* | B6: 339900 | E6: 附加品首付比例不得低于20%
A7: 车辆贷款金额* | B7: 185000 | E7: 总价 (车价+附加品） | F7: =B6+F3 -> 339900
A8: 车辆首付比例： | B8: =(B6-B7)/B6 -> 0.45572227 | C8: 车辆首付比例不得低于： | D8: =VLOOKUP($B$3,'参数-车系车型 利率'!M:N,2,0) -> 0.15 | E8: 总价不得超过： | F8: =B5*115% -> 390885
A9: 经销商贴息 （低息-选填） | B9: 0 | D9: *经销商贴息需填写在系统的‘经销商补贴金额’处
B10: 注：公牌/个体户类/商用申请 车辆首付30%起（陆尊PHEV、陆尚PHEV、陆尊新能源、至境L7、微蓝为25%起） | U10: 贴息超限，请调整
A11: 第二步：查看试算结果
A12: 贷款方案 | B12: 贷款金额合计 | C12: 首付金额合计 | D12: 客户首付比例 | E12: =VLOOKUP($B$3,'参数-车系车型 利率'!M:N,2,0) -> 0.15
A13: 低首付低利率 （等额本息类） | B13: =B7+F4 -> 185000 | C13: =F7-B7-F4 -> 154900 | D13: =C13/F7 -> 0.45572227
B15: 期限 | C15: 客户试算月供 | D15: 客户试算总利息 | E15: 客户试算年化利率 | F15: 客户试算年化费率 | G15: 客户试算总费率 | H15: 厂商贴息金额参考 | I15: 厂贴上限 | J15: 免息贴息金额 | K15: 厂贴免息贷款额 上限参考 | L15: 车辆贷款金额 下限 | M15: 系统方案名称关键字 | P15: 60期提前还款测算参考：
B16: 60期 | C16: =ROUNDUP(PMT(VLOOKUP(B4,'参数-车系车型 利率'!B:I,2,0)/12,60,-$B$7)-(H16+B9)/60,2)+(PMT(10%/12,60,-F4)) -> 3451.65 | D16: =C16*60-B7-F4 -> 22099 | E16: =RATE(60,-C16,(B7+F4))*12 -> 0.045319868 | F16: =D16/(B7+F4)/5 -> 0.023890811 | G16: =D16/(B7+F4) -> 0.11945405 | H16: =MIN($I$16,J16) -> 7443.81 | I16: =VLOOKUP($B$4,'厂贴车型明细&贷款金额说明'!C:E,3,0) -> 7443.81 | J16: =$B$7*VLOOKUP(B16,'参数-车系车型 利率'!$B$78:$C$83,2,0) -> 29546.35 | K16: =ROUNDUP(I16/VLOOKUP(B16,'参数-车系车型 利率'!B78:C83,2,0),0)-1 -> 46608 | L16: =VLOOKUP($B$4,'厂贴车型明细&贷款金额说明'!C:K,9,0) -> 160000 | M16: =VLOOKUP(B4,'参数-方案配置'!C:E,2,0) -> 个人申请：厂贴_5.99贴息 新优速贷/个体工商户升级 18期/24-60期 | O16: 提前还款期数 | P16: 24 | R16: 还满24期免提前还款手续费
B17: 48期 | C17: =ROUNDUP(PMT(VLOOKUP(B4,'参数-车系车型 利率'!B:I,3,0)/12,48,-$B$7)-(H17+B9)/48,2)+(PMT(10%/12,48,-F4)) -> 4188.81 | D17: =C17*48-B7-F4 -> 16062.88 | E17: =RATE(48,-C17,(B7+F4))*12 -> 0.041410253 | F17: =D17/(B7+F4)/4 -> 0.021706595 | G17: =D17/(B7+F4) -> 0.086826378 | H17: =MIN($I$16,J17) -> 7443.81 | J17: =$B$7*VLOOKUP(B17,'参数-车系车型 利率'!$B$78:$C$83,2,0) -> 23510.817 | K17: =ROUNDUP(I16/VLOOKUP(B17,'参数-车系车型 利率'!B78:C83,2,0),0)-1 -> 58573 | L17: =VLOOKUP($B$4,'厂贴车型明细&贷款金额说明'!C:K,8,0) -> 160000 | O17: 剩余本金 | P17: =B13-(C16*P16-P19) -> 115978.1
B18: 36期 | C18: =ROUNDUP(PMT(VLOOKUP(B4,'参数-车系车型 利率'!B:I,4,0)/12,36,-$B$7)-(H18+B9)/36,2)+(PMT(10%/12,36,-F4)) -> 5420.45 | D18: =C18*36-B7-F4 -> 10136.2 | E18: =RATE(36,-C18,(B7+F4))*12 -> 0.034946924 | F18: =D18/(B7+F4)/3 -> 0.018263423 | G18: =D18/(B7+F4) -> 0.05479027 | H18: =MIN($I$16,J18) -> 7443.81 | J18: =$B$7*VLOOKUP(B18,'参数-车系车型 利率'!$B$78:$C$83,2,0) -> 17581.122 | K18: =ROUNDUP(I16/VLOOKUP(B18,'参数-车系车型 利率'!B78:C83,2,0),0)-1 -> 78328 | L18: =VLOOKUP($B$4,'厂贴车型明细&贷款金额说明'!C:K,7,0) -> 160000 | O18: 可节省利息 | P18: =D16-P19 -> 8281.299
B19: 24期 | C19: =ROUNDUP(PMT(VLOOKUP(B4,'参数-车系车型 利率'!B:I,5,0)/12,24,-$B$7)-(H19+B9)/24,2)+(PMT(10%/12,24,-F4)) -> 7888.33 | D19: =C19*24-B7-F4 -> 4319.92 | E19: =RATE(24,-C19,(B7+F4))*12 -> 0.022258764 | F19: =D19/(B7+F4)/2 -> 0.011675459 | G19: =D19/(B7+F4) -> 0.023350919 | H19: =MIN($I$16,J19) -> 7443.81 | J19: =$B$7*VLOOKUP(B19,'参数-车系车型 利率'!$B$78:$C$83,2,0) -> 11763.965 | K19: =ROUNDUP(I16/VLOOKUP(B19,'参数-车系车型 利率'!B78:C83,2,0),0)-1 -> 117061 | L19: =VLOOKUP($B$4,'厂贴车型明细&贷款金额说明'!C:K,6,0) -> 160000 | O19: 已还利息 | P19: =(B13*(E16/12)-C16)*((1+(E16/12))^(P16)-1)/(E16/12)+(C16)*P16 -> 13817.701
B20: 18期 | C20: =ROUNDUP(PMT(VLOOKUP(B4,'参数-车系车型 利率'!B:I,6,0)/12,18,-$B$7)-(H20+B9)/18,2)+(PMT(10%/12,18,-F4)) -> 10358.49 | D20: =C20*18-B7-F4 -> 1452.82 | E20: =RATE(18,-C20,(B7+F4))*12 -> 0.0098965658 | F20: =D20/(B7+F4)/1.5 -> 0.0052353874 | G20: =D20/(B7+F4) -> 0.0078530811 | H20: =MIN($I$16,J20) -> 7443.81 | J20: =$B$7*VLOOKUP(B20,'参数-车系车型 利率'!$B$78:$C$83,2,0) -> 8897.3439 | K20: =ROUNDUP(I16/VLOOKUP(B20,'参数-车系车型 利率'!B78:C83,2,0),0)-1 -> 154777 | L20: =VLOOKUP($B$4,'厂贴车型明细&贷款金额说明'!C:K,5,0) -> 185000
B21: 12期 | C21: =ROUNDUP(PMT(VLOOKUP(B4,'参数-车系车型 利率'!B:I,7,0)/12,12,-$B$7)-(H21+B9)/12,2) -> #VALUE! | D21: =C21*12-B7 -> #VALUE! | E21: =RATE(12,-C21,B7)*12 -> #VALUE! | F21: =D21/$B$7/1 -> #VALUE! | G21: =D21/$B$7 -> #VALUE! | H21: =MIN($I$21,J21) -> #N/A | I21: =B5*(VLOOKUP(B3,'参数-车系车型 利率'!C89:D89,2,0)) -> #N/A | J21: =$B$7*VLOOKUP(B3,'参数-车系车型 利率'!C89:E89,3,0) -> #N/A | K21: =ROUNDUP(I21/VLOOKUP(B3,'参数-车系车型 利率'!C89:E89,3,0),0)-1 -> #N/A | L21: =VLOOKUP($B$4,'厂贴车型明细&贷款金额说明'!C:K,4,0) -> 无方案 | M21: =VLOOKUP(B4,'参数-方案配置'!C:G,5,0) -> 无方案

Sheet 厂贴_常规贴息(停用)
A2: 第一步：选车系、车型，并修改贷款参数 | M2: 返回 | O2: 可申请的最低首付比例： | P2: 0.2
A3: 车系* | B3: 陆尊_PHEV | O3: 裸车提车支出包装： | P3: 2999
A4: 车型* | B4: GL8 陆尊 PHEV 尊享版 新能源 | O4: 车辆开票价： | P4: =B6 -> 120000
A5: 市场指导价(MSRP) | B5: =VLOOKUP(B4,'厂贴车型明细&贷款金额说明'!C:D,2,0) -> #N/A | O5: 需至少打包的附加品金额： | P5: =(P4*P2-P3)/(1-P2)+1 -> 26252.25 | Q5: 需符合附加品上限要求
A6: 车辆开票价(TP)* | B6: 120000 | F6: 说明： 1、表格中蓝底白字的单元格，为可修改项。可直接输入或从下拉菜单中进行选择。 2、当“贷款金额下限”或“贷款金额上限数值项变为 红字且黄色高亮时，需调整第9行“贷款金额”输入的数值 3、当某‘还款方式’的试算行多处显示 #VALUE! 或 *N/A 时，或K列/L列显示'无方案'时，即表示所选车型无此“还款方式”或 对应期限 的贴息方案 4、系统录入选择贷款方案时，注意选择带有“方案名称关键字”的方案名称 | O6: 贷款金额为： | P6: =P4-P3 -> 117001
A7: 附加品金额* | B7: 0
A8: 总价 | B8: =IF((B6+B7)<=B5*115%,(B6+B7),"总价超限,请调整") -> #N/A | D8: 总价上限： | E8: =B5*115% -> #N/A | O8: 60期月供支出包装: | P8: 2399
A9: 贷款金额* | B9: 197800 | O9: 计算得出贷款金额为： | P9: =PV(VLOOKUP(B4,'参数-车系车型 利率'!B:I,2,0)/12,60,-(P8+H18/60)) -> #N/A
A11: 经销商贴息 （低息-选填） | B11: 0 | D11: *经销商贴息需填写在系统的‘经销商补贴金额’处
U12: 贴息超限，请调整
A13: 第二步：查看试算结果
A14: 贷款方案 | B14: 首付比例 | C14: 首付金额 | D14: 首付不得低于： | E14: =VLOOKUP($B$3,'参数-车系车型 利率'!P2:Q8,2,0) -> 0.2
A15: 低首付低利率 （等额本息类） | B15: =C15/B8 -> #N/A | C15: =B8-B9 -> #N/A | D15: 注：公牌/个体户类/商用申请 首付30%起（陆尊PHEV、陆尚PHEV、微蓝为25%起）
B17: 期限 | C17: 客户试算月供 | D17: 客户试算总利息 | E17: 客户试算年化利率 | F17: 客户试算年化费率 | G17: 客户试算总费率 | H17: 厂商贴息金额参考 | I17: 厂贴上限 | J17: 免息贴息金额 | K17: 厂贴免息贷款额 上限参考 | L17: 贷款金额下限 | M17: 方案名称关键字 | P17: 60期提前还款测算参考：
B18: 60期 | C18: =ROUNDUP(PMT(VLOOKUP(B4,'参数-车系车型 利率'!B:I,2,0)/12,60,-$B$9)-(H18+B11)/60,2) -> #N/A | D18: =C18*60-B9 -> #N/A | E18: =RATE(60,-C18,B9)*12 -> #N/A | F18: =D18/$B$9/5 -> #N/A | G18: =D18/$B$9 -> #N/A | H18: =MIN($I$18,J18) -> #N/A | I18: =VLOOKUP($B$4,'厂贴车型明细&贷款金额说明'!C:E,3,0) -> #N/A | J18: =$B$9*VLOOKUP(B18,'参数-车系车型 利率'!$B$78:$C$83,2,0) -> 31590.638 | K18: =ROUNDUP(I18/VLOOKUP(B18,'参数-车系车型 利率'!B78:C83,2,0),0)-1 -> #N/A | L18: =VLOOKUP($B$4,'厂贴车型明细&贷款金额说明'!C:K,9,0) -> #N/A | M18: =VLOOKUP(B4,'参数-方案配置'!C:E,2,0) -> 个人申请：厂贴_5.99贴息 新优速贷/个体工商户升级 24-60期 | O18: 提前还款期数 | P18: 24 | R18: 还满24期免提前还款手续费
B19: 48期 | C19: =ROUNDUP(PMT(VLOOKUP(B4,'参数-车系车型 利率'!B:I,3,0)/12,48,-$B$9)-(H19+B11)/48,2) -> #N/A | D19: =C19*48-B9 -> #N/A | E19: =RATE(48,-C19,B9)*12 -> #N/A | F19: =D19/$B$9/4 -> #N/A | G19: =D19/$B$9 -> #N/A | H19: =MIN($I$18,J19) -> #N/A | J19: =$B$9*VLOOKUP(B19,'参数-车系车型 利率'!$B$78:$C$83,2,0) -> 25137.512 | K19: =ROUNDUP(I18/VLOOKUP(B19,'参数-车系车型 利率'!B78:C83,2,0),0)-1 -> #N/A | L19: =VLOOKUP($B$4,'厂贴车型明细&贷款金额说明'!C:K,8,0) -> #N/A | O19: 剩余本金 | P19: =B9-(C18*P18-P21) -> #N/A
B20: 36期 | C20: =ROUNDUP(PMT(VLOOKUP(B4,'参数-车系车型 利率'!B:I,4,0)/12,36,-$B$9)-(H20+B11)/36,2) -> #N/A | D20: =C20*36-B9 -> #N/A | E20: =RATE(36,-C20,B9)*12 -> #N/A | F20: =D20/$B$9/3 -> #N/A | G20: =D20/$B$9 -> #N/A | H20: =MIN($I$18,J20) -> #N/A | J20: =$B$9*VLOOKUP(B20,'参数-车系车型 利率'!$B$78:$C$83,2,0) -> 18797.545 | K20: =ROUNDUP(I18/VLOOKUP(B20,'参数-车系车型 利率'!B78:C83,2,0),0)-1 -> #N/A | L20: =VLOOKUP($B$4,'厂贴车型明细&贷款金额说明'!C:K,7,0) -> #N/A | O20: 可节省利息 | P20: =D18-P21 -> #N/A
B21: 24期 | C21: =ROUNDUP(PMT(VLOOKUP(B4,'参数-车系车型 利率'!B:I,5,0)/12,24,-$B$9)-(H21+B11)/24,2) -> #N/A | D21: =C21*24-B9 -> #N/A | E21: =RATE(24,-C21,B9)*12 -> #N/A | F21: =D21/$B$9/2 -> #N/A | G21: =D21/$B$9 -> #N/A | H21: =MIN($I$18,J21) -> #N/A | J21: =$B$9*VLOOKUP(B21,'参数-车系车型 利率'!$B$78:$C$83,2,0) -> 12577.904 | K21: =ROUNDUP(I18/VLOOKUP(B21,'参数-车系车型 利率'!B78:C83,2,0),0)-1 -> #N/A | L21: =VLOOKUP($B$4,'厂贴车型明细&贷款金额说明'!C:K,6,0) -> #N/A | O21: 已还利息 | P21: =(B9*(E18/12)-C18)*((1+(E18/12))^(P18)-1)/(E18/12)+(C18)*P18 -> #N/A
B22: 18期 | C22: =ROUNDUP(PMT(VLOOKUP(B4,'参数-车系车型 利率'!B:I,5,0)/12,18,-$B$9)-(H21+B11)/18,2) -> #N/A | D22: =C22*18-B9 -> #N/A | E22: =RATE(18,-C22,B9)*12 -> #N/A | F22: =D22/$B$9/1.5 -> #N/A | G22: =D22/$B$9 -> #N/A | H22: =MIN($I$18,J22) -> #N/A | J22: =$B$9*VLOOKUP(B22,'参数-车系车型 利率'!$B$78:$C$83,2,0) -> 9512.9439 | K22: =ROUNDUP(I18/VLOOKUP(B22,'参数-车系车型 利率'!B78:C83,2,0),0)-1 -> #N/A | L22: =VLOOKUP($B$4,'厂贴车型明细&贷款金额说明'!C:K,5,0) -> #N/A
B23: 12期 | C23: =ROUNDUP(PMT(VLOOKUP(B4,'参数-车系车型 利率'!B:I,7,0)/12,12,-$B$9)-(H23+B11)/12,2) -> #VALUE! | D23: =C23*12-B9 -> #VALUE! | E23: =RATE(12,-C23,B9)*12 -> #VALUE! | F23: =D23/$B$9/1 -> #VALUE! | G23: =D23/$B$9 -> #VALUE! | H23: =MIN($I$18,J23) -> #N/A | J23: =$B$9*VLOOKUP(B23,'参数-车系车型 利率'!$B$78:$C$83,2,0) -> 6476.961 | K23: =ROUNDUP(I18/VLOOKUP(B23,'参数-车系车型 利率'!B78:C83,2,0),0)-1 -> #N/A | L23: =VLOOKUP($B$4,'厂贴车型明细&贷款金额说明'!C:K,4,0) -> #N/A
A25: 还款方式-2 | B25: 首付金额 | C25: 首付比例 | D25: 首付不得低于： | E25: 0.2 | P25: GL8 陆尊 PHEV 七座奢享版 新能源 | Q25: 119999
A26: 智慧贷 （低息） 首付20%起 留尾款享更低月供 | B26: =B8-B9 -> #N/A | C26: =B26/B8 -> #N/A | D26: 25款世纪贷款金额上限： | E26: 500000 | H26: 12期-智慧贷7030-0息0月供 （贷款金额=尾款）总价上限参考： | M26: =I29/VLOOKUP(B4,'参数-车系车型 利率'!B:I,7,0)/30% -> #N/A
B28: 期限 | C28: 客户试算月供 | D28: 客户总利息 | E28: 尾款 (与末期月供一起支付） | F28: 客户试算年化利率 | H28: 客户试算年化费率 | I28: 厂贴上限 | J28: 免息贴息金额 | K28: 厂商贴息金额参考 | L28: 贷款金额下限 | M28: 方案名称关键字 | O28: 60期智慧贷还满24期提前还款测算参考：
B29: 60期 | C29: =ROUNDUP(PMT(VLOOKUP(B4,'参数-车系车型 利率'!B:I,2,0)/12,60,-B9,E29)-(K29+B11)/60,2) -> #N/A | D29: =C29*60-(B9-E29) -> #N/A | E29: =B8*20% -> #N/A | F29: =RATE(60,-C29,B9,-E29)*12 -> #N/A | H29: =D29/$B$9/5 -> #N/A | I29: =VLOOKUP($B$4,'厂贴车型明细&贷款金额说明'!C:G,3,0) -> #N/A | J29: =IF($B$3="新君威",($B$9-$E$29)*VLOOKUP(B29,'参数-车系车型 利率'!$K$78:$L$83,2,0)+($E$29*VLOOKUP($B$4,'参数-车系车型 利率'!B:I,2,0)*5),($B$9-$E$29)*VLOOKUP(B29,'参数-车系车型 利率'!$B$78:$C$83,2,0)+($E$29*VLOOKUP($B$4,'参数-车系车型 利率'!B:I,2,0)*5)) -> #N/A | K29: =MIN($I$29,J29) -> #N/A | L29: =VLOOKUP($B$4,'厂贴车型明细&贷款金额说明'!C:K,14,0) -> #N/A | M29: =VLOOKUP(B4,'参数-方案配置'!C:G,4,0) -> 无方案 | O29: 提前还款期数 | P29: 24 | R29: 从24期开始填写（同期结清）
B30: 48期 | C30: =ROUNDUP(PMT(VLOOKUP(B4,'参数-车系车型 利率'!B:I,3,0)/12,48,-B9,E29)-(K30+B11)/48,2) -> #N/A | D30: =C30*48-(B9-E29) -> #N/A | F30: =RATE(48,-C30,B9,-E29)*12 -> #N/A | H30: =D30/$B$9/4 -> #N/A | J30: =IF($B$3="新君威",($B$9-$E$29)*VLOOKUP(B30,'参数-车系车型 利率'!$K$78:$L$83,2,0)+($E$29*VLOOKUP($B$4,'参数-车系车型 利率'!B:I,3,0)*4),($B$9-$E$29)*VLOOKUP(B30,'参数-车系车型 利率'!$B$78:$C$83,2,0)+($E$29*VLOOKUP($B$4,'参数-车系车型 利率'!B:I,3,0)*4)) -> #N/A | K30: =MIN($I$29,J30) -> #N/A | O30: 剩余本金 | P30: =B9-(C29*P29-P32) -> #N/A
B31: 36期 | C31: =ROUNDUP(PMT(VLOOKUP(B4,'参数-车系车型 利率'!B:I,4,0)/12,36,-B9,E31)-(K31+B11)/36,2) -> #N/A | D31: =C31*36-(B9-E31) -> #N/A | E31: =B8*30% -> #N/A | F31: =RATE(36,-C31,B9,-E31)*12 -> #N/A | H31: =D31/$B$9/3 -> #N/A | J31: =IF($B$3="新君威",($B$9-$E$29)*VLOOKUP(B31,'参数-车系车型 利率'!$K$78:$L$83,2,0)+($E$31*VLOOKUP($B$4,'参数-车系车型 利率'!B:I,4,0)*3),($B$9-$E$31)*VLOOKUP(B31,'参数-车系车型 利率'!$B$78:$C$83,2,0)+($E$31*VLOOKUP($B$4,'参数-车系车型 利率'!B:I,4,0)*3)) -> #N/A | K31: =MIN($I$29,J31) -> #N/A | L31: =VLOOKUP($B$4,'厂贴车型明细&贷款金额说明'!C:K,13,0) -> #N/A | M31: =VLOOKUP(B4,'参数-方案配置'!C:G,5,0) -> 无方案 | O31: 可节省利息 | P31: =D29-P32 -> #N/A
B32: 24期 | C32: =ROUNDUP(PMT(VLOOKUP(B4,'参数-车系车型 利率'!B:I,5,0)/12,24,-B9,E31)-(K32+B11)/24,2) -> #N/A | D32: =C32*24-(B9-E31) -> #N/A | F32: =RATE(24,-C32,B9,-E31)*12 -> #N/A | H32: =D32/$B$9/2 -> #N/A | J32: =IF($B$3="新君威",($B$9-$E$31)*VLOOKUP(B32,'参数-车系车型 利率'!$K$78:$L$83,2,0)+($E$31*VLOOKUP($B$4,'参数-车系车型 利率'!B:I,5,0)*2),($B$9-$E$31)*VLOOKUP(B32,'参数-车系车型 利率'!$B$78:$C$83,2,0)+($E$31*VLOOKUP($B$4,'参数-车系车型 利率'!B:I,5,0)*2)) -> #N/A | K32: =MIN($I$29,J32) -> #N/A | L32: =VLOOKUP($B$4,'厂贴车型明细&贷款金额说明'!C:K,12,0) -> #N/A | O32: 已还利息 | P32: =(B9*(F29/12)-C29)*((1+(F29/12))^(P29)-1)/(F29/12)+(C29)*P29 -> #N/A
B33: 18期 | C33: =ROUNDUP(PMT(VLOOKUP(B4,'参数-车系车型 利率'!B:I,6,0)/12,18,-B9,E31)-(K33+B11)/18,2) -> #VALUE! | D33: =C33*18-(B9-E31) -> #VALUE! | F33: =RATE(18,-C33,B9,-E31)*12 -> #VALUE! | H33: =D33/$B$9/1.5 -> #VALUE! | J33: =IF($B$3="新君威",($B$9-$E$31)*VLOOKUP(B33,'参数-车系车型 利率'!$K$78:$L$83,2,0)+($E$31*VLOOKUP($B$4,'参数-车系车型 利率'!B:I,6,0)*2),($B$9-$E$31)*VLOOKUP(B33,'参数-车系车型 利率'!$B$78:$C$83,2,0)+($E$31*VLOOKUP($B$4,'参数-车系车型 利率'!B:I,6,0)*1.5)) -> #N/A | K33: =MIN($I$29,J33) -> #N/A | L33: =VLOOKUP($B$4,'厂贴车型明细&贷款金额说明'!C:K,11,0) -> #N/A
B34: 12期 | C34: =ROUNDUP(PMT(VLOOKUP(B4,'参数-车系车型 利率'!B:I,7,0)/12,12,-B9,E31)-(K34+B11)/12,2) -> #VALUE! | D34: =C34*12-(B9-E31) -> #VALUE! | F34: =RATE(12,-C34,B9,-E31)*12 -> #VALUE! | H34: =D34/$B$9/1 -> #VALUE! | J34: =IF($B$3="新君威",($B$9-$E$31)*VLOOKUP(B34,'参数-车系车型 利率'!$K$78:$L$83,2,0)+($E$31*VLOOKUP($B$4,'参数-车系车型 利率'!B:I,7,0)*1),($B$9-$E$31)*VLOOKUP(B34,'参数-车系车型 利率'!$B$78:$C$83,2,0)+($E$31*VLOOKUP($B$4,'参数-车系车型 利率'!B:I,7,0)*1)) -> #N/A | K34: =MIN($I$29,J34) -> #N/A | L34: =VLOOKUP($B$4,'厂贴车型明细&贷款金额说明'!C:K,10,0) -> #N/A
E35: 注：请注意复核贷款金额需大于等于尾款

Sheet 厂贴_新公牌易贷5050
A2: 第一步：选车系、车型，并修改贷款参数 | L2: 返回
A3: 车系* | B3: 陆尊 | D3: 请注意:原“新君威”车型不享受贴息，可在试算表 新君威 VIN查询 Sheet确认具体车辆是否可享受贴息
A4: 车型* | B4: 全新GL8 ES 陆尊 智享版
A5: 市场指导价(MSRP) | B5: =VLOOKUP(B4,'厂贴车型明细&贷款金额说明'!C:D,2,0) -> #N/A
A6: 车辆开票价(TP)* | B6: =K18*2 -> #N/A | F6: 说明： 1、表格中蓝底白字的单元格，为可修改项。可直接输入或从下拉菜单中进行选择。 2、当“贷款金额下限”或“贷款金额上限数值项变为 红字且黄色高亮时，需调整第6、7行输入的数值，需确保总价不低于‘贷款金额下限’的2倍 3、当某‘还款方式’的试算行多处显示 #VALUE! 或 *N/A 时，或K列/L列显示'无方案'时，即表示所选车型无此“还款方式”或 对应期限 的贴息方案 4、系统录入选择贷款方案时，注意选择带有“车型+方案名称关键字”的方案名称
A7: 附加品金额* | B7: 0
A8: 总价 | B8: =IF((B6+B7)<=B5*115%,(B6+B7),"总价超限,请调整") -> #N/A | D8: 总价上限： | E8: =B5*115% -> #N/A
A9: 贷款金额* | B9: 163000
A11: 经销商贴息 （低息-选填） | B11: 0 | D11: *经销商贴息需填写在系统的‘经销商补贴金额’处
A13: 第二步：查看试算结果 | D13: =VLOOKUP($B$3,'参数-车系车型 利率'!P2:Q4,2,0) -> #N/A
A14: 还款方式 | B14: 贷款金额* (=总价*50%） | C14: 首付金额 | D14: 首付比例
A15: 5050 （低息） 半付半贷 12期超低月供 | B15: =B8*50% -> #N/A | C15: =B8-B15 -> #N/A | D15: =C15/B8 -> #N/A
B17: 期限 | C17: 客户试算月供 | D17: 客户试算总利息 | E17: 尾款 (与末期月供一起支付） | F17: 客户试算年化利率 | G17: 客户试算年化费率 | H17: 厂贴上限 | I17: 免息贴息金额 | J17: 厂商贴息金额参考 | K17: 贷款金额下限 | L17: 方案名称关键字
B18: 12期 | C18: =ROUNDUP(PMT(8.48%/12,12,-B15,E18)-(J18+B11)/12,2) -> #N/A | D18: =C18*12-(B15-E18) -> #N/A | E18: =B8/2 -> #N/A | F18: =RATE(12,-C18,B15,-E18)*12 -> #N/A | G18: =D18/B15/1 -> #N/A | H18: =VLOOKUP($B$4,R:S,2,0) -> 11085.2 | J18: =MIN(H18,I18) -> 11085.2 | K18: =VLOOKUP($B$4,'厂贴车型明细&贷款金额说明'!C:L,15,0) -> #N/A | L18: =VLOOKUP(B4,'参数-方案配置'!C:H,6,0) -> 企业申请：厂贴_5.99贴息 新公牌易贷/个体工商户 18期/24-60期 企业商用：厂贴_5.99贴息 营运租赁 18期/24-36期
S22: 厂商贴息金额
R23: 全新GL8 ES 陆尊 智享版 | S23: 11085.2
R24: 全新GL8 ES 陆尊 尊享版 | S24: 12433.4
R25: GL8 陆尊 PHEV 智享版 新能源 | S25: 12508.3
R26: GL8 陆尊 PHEV 尊享版 新能源 | S26: 13631.8
R27: GL8 陆尊 PHEV 六座奢享版 新能源 | S27: 14755.3
R28: GL8 陆尊 PHEV 七座奢享版 新能源 | S28: 14755.3

Sheet 厂贴_员工车
A2: 第一步：选车系、车型，并修改贷款参数 | L2: 返回 | N2: 可申请的最低首付比例： | O2: 0.2
A3: 车系* | B3: 微蓝6_450KM | N3: 裸车提车支出包装： | O3: 699
A4: 车型* | B4: 微蓝6 450KM舒享PLUS版 纯电动 新能源 | N4: 车辆开票价： | O4: =B6 -> 100000
A5: 市场指导价(MSRP) | B5: =VLOOKUP(B4,'厂贴车型明细&贷款金额说明'!C:D,2,0) -> 112800 | N5: 需至少打包的附加品金额： | O5: =(O4*O2-O3)/(1-O2)+1 -> 24127.25 | P5: 需符合附加品上限要求
A6: 车辆开票价(TP)* | B6: 100000 | F6: 说明： 1、表格中蓝底白字的单元格，为可修改项。可直接输入或从下拉菜单中进行选择。 2、当“贷款金额下限”或“贷款金额上限数值项变为 红字且黄色高亮时，需调整第9行“贷款金额”输入的数值 3、当某‘还款方式’的试算行多处显示 #VALUE! 或 *N/A 时，或K列/L列显示'无方案'时，即表示所选车型无此“还款方式”或 对应期限 的贴息方案 4、系统录入选择贷款方案时，注意选择带有“车型+方案名称关键字”的方案名称 | N6: 贷款金额为： | O6: =O4-O3 -> 99301
A7: 附加品金额* | B7: 0
A8: 总价 | B8: =IF((B6+B7)<=B5*115%,(B6+B7),"总价超限,请调整") -> 100000 | D8: 总价上限： | E8: =B6*115% -> 115000 | N8: 60期月供支出包装: | O8: 2399
A9: 贷款金额* | B9: 30000 | N9: 计算得出贷款金额为： | O9: =PV(6.88%/12,60,-(O8+G18/60)) -> 123234.31
A11: 经销商贴息 （低息-选填） | B11: 0 | D11: *经销商贴息需填写在E速通系统的‘经销商补贴金额’处
T12: 贴息超限，请调整
A13: 第二步：查看试算结果
A14: 还款方式-1 | B14: 首付金额 | C14: 首付比例 | D14: 首付不得低于： | E14: =VLOOKUP($B$3,'参数-车系车型 利率'!P2:Q7,2,0) -> 0.2
A15: 等额本息类 （低息） | B15: =B8-B9 -> 70000 | C15: =B15/B8 -> 0.7
B17: 期限 | C17: 客户试算月供 | D17: 客户试算总利息 | E17: 客户试算年化利率 | F17: 客户试算年化费率 | G17: 厂商贴息金额参考 | H17: 厂贴上限 | I17: 免息贴息金额 | J17: 厂贴免息贷款额上限 | K17: 贷款金额下限 | L17: 方案名称关键字 | N17: 60期等额本息还满24期提前还款测算参考：
B18: 60期 | C18: =ROUNDUP(PMT(VLOOKUP(B4,'参数-车系车型 利率'!B:O,14,0)/12,60,-$B$9)-(G18+B11)/60,2) -> 598.78 | D18: =C18*60-B9 -> 5926.8 | E18: =RATE(60,-C18,B9)*12 -> 0.07334367 | F18: =D18/$B$9/5 -> 0.039512 | G18: =MIN($H$18,I18) -> 2052.96 | H18: =VLOOKUP($B$4,'厂贴车型明细&贷款金额说明'!C:E,3,0) -> 2052.96 | I18: =$B$9*VLOOKUP(B18,'参数-车系车型 利率'!$B$78:$G$83,6,0) -> 5539.9061 | J18: =ROUNDUP(H18/VLOOKUP(B18,'参数-车系车型 利率'!B78:G83,6,0),0) -> 11118 | K18: =VLOOKUP($B$3,O23:T26,2,0) -> 30000 | L18: =VLOOKUP(B4,'参数-方案配置'!C:K,14,0) -> #REF! | N18: 提前还款期数 | O18: 24 | Q18: 从24期开始填写（同期结清）
B19: 48期 | C19: =ROUNDUP(PMT(VLOOKUP(B4,'参数-车系车型 利率'!B:O,14,0)/12,48,-$B$9)-(G19+B11)/48,2) -> 713.8 | D19: =C19*48-B9 -> 4262.4 | E19: =RATE(48,-C19,B9)*12 -> 0.066697719 | F19: =D19/$B$9/4 -> 0.03552 | G19: =MIN($H$18,I19) -> 2052.96 | I19: =$B$9*VLOOKUP(B19,'参数-车系车型 利率'!$B$78:$G$83,6,0) -> 4401.1604 | J19: =ROUNDUP(H18/VLOOKUP(B19,'参数-车系车型 利率'!B78:G83,6,0),0) -> 13994 | K19: =VLOOKUP($B$3,O23:T26,3,0) -> 30000 | N19: 剩余本金 | O19: =B9-(C18*O18-O21) -> 19296.682
B20: 36期 | C20: =ROUNDUP(PMT(VLOOKUP(B4,'参数-车系车型 利率'!B:O,14,0)/12,36,-$B$9)-(G20+B11)/36,2) -> 906.77 | D20: =C20*36-B9 -> 2643.72 | E20: =RATE(36,-C20,B9)*12 -> 0.055659716 | F20: =D20/$B$9/3 -> 0.029374667 | G20: =MIN($H$18,I20) -> 2052.96 | I20: =$B$9*VLOOKUP(B20,'参数-车系车型 利率'!$B$78:$G$83,6,0) -> 3287.9257 | J20: =ROUNDUP(H18/VLOOKUP(B20,'参数-车系车型 利率'!B78:G83,6,0),0) -> 18732 | K20: =VLOOKUP($B$3,O23:T26,4,0) -> 30000 | N20: 可节省利息 | O20: =D18-O21 -> 2259.3975
B21: 24期 | C21: =ROUNDUP(PMT(VLOOKUP(B4,'参数-车系车型 利率'!B:O,14,0)/12,24,-$B$9)-(G21+B11)/24,2) -> 1294.66 | D21: =C21*24-B9 -> 1071.84 | E21: =RATE(24,-C21,B9)*12 -> 0.033931633 | F21: =D21/$B$9/2 -> 0.017864 | G21: =MIN($H$18,I21) -> 2052.96 | I21: =$B$9*VLOOKUP(B21,'参数-车系车型 利率'!$B$78:$G$83,6,0) -> 2196.7566 | J21: =ROUNDUP(H18/VLOOKUP(B21,'参数-车系车型 利率'!B78:G83,6,0),0) -> 28037 | K21: =VLOOKUP($B$3,O23:T26,5,0) -> 无方案 | N21: 已还利息 | O21: =(B9*(E18/12)-C18)*((1+(E18/12))^(O18)-1)/(E18/12)+(C18)*O18 -> 3667.4025
B22: 18期 | C22: =ROUNDUP(PMT(VLOOKUP(B4,'参数-车系车型 利率'!B:O,14,0)/12,18,-$B$9)-(G22+B11)/18,2) -> 1705.34 | D22: =C22*18-B9 -> 696.12 | E22: =RATE(18,-C22,B9)*12 -> 0.029110479 | F22: =D22/$B$9/1.5 -> 0.015469333 | G22: =MIN($H$18,I22) -> 1660.1703 | I22: =$B$9*VLOOKUP(B22,'参数-车系车型 利率'!$B$78:$G$83,6,0) -> 1660.1703 | J22: =ROUNDUP(H18/VLOOKUP(B22,'参数-车系车型 利率'!B78:G83,6,0),0) -> 37098 | K22: =VLOOKUP($B$3,O23:T26,6,0) -> 无方案 | P22: 60期 | Q22: 48期 | R22: 36期 | S22: 24期 | T22: 18期 | U22: 12期
B23: 12期 | C23: =ROUNDUP(PMT(VLOOKUP(B4,'参数-车系车型 利率'!B:O,14,0)/12,12,-$B$9)-(G23+B11)/12,2) -> 2539.15 | D23: =C23*12-B9 -> 469.8 | E23: =RATE(12,-C23,B9)*12 -> 0.02878434 | F23: =D23/$B$9/1 -> 0.01566 | G23: =MIN($H$18,I23) -> 1129.7872 | I23: =$B$9*VLOOKUP(B23,'参数-车系车型 利率'!$B$78:$G$83,6,0) -> 1129.7872 | J23: =ROUNDUP(H18/VLOOKUP(B23,'参数-车系车型 利率'!B78:G83,6,0),0)+1 -> 54515 | K23: =VLOOKUP($B$3,O23:U26,7,0) -> 无方案 | O23: 微蓝6_450KM | P23: 30000 | Q23: 30000 | R23: 30000 | S23: 无方案 | T23: 无方案 | U23: 无方案
O24: 昂科拉Plus | P24: 25000 | Q24: 25000 | R24: 25000 | S24: 25000 | T24: 25000 | U24: 25000
O25: 昂扬 | P25: 25000 | Q25: 25000 | R25: 25000 | S25: 25000 | T25: 25000 | U25: 25000
A26: 主机厂员工适用要求： | O26: 威朗Pro | P26: 25000 | Q26: 25000 | R26: 25000 | S26: 25000 | T26: 25000 | U26: 25000
A27: 申请人资格：通用汽车（中国）公司、上海汽车集团本部、上汽财务、上汽通用汽车、上汽通用五菱以及上汽通用汽车金融有限责任公司在职的正式员工（不包括退休及试用期员工，劳务派遣制员工是否符合准入资格，以上述公司内部具体认定为准） 购车限制： ①通用汽车（中国）公司，上海汽车集团本部，上汽财务，上汽通用汽车，上汽通用五菱员工：仅可购买上汽通用和上汽通用五菱的所有新车 ②SAIC-GMAC员工：可购买所有厂牌的任意新车及二手车 贷前资料要求：提供《工作证》+《购车申请表》（注：上汽通用汽车主机厂员工必须提供，样式如右图） 支持申请免抵押（以后台审批结果为准）

Sheet 参数-方案配置
D2: 常规贴息
B3: 车系 | C3: E速通系统促销车型 | D3: 48-60期 | E3: 5050 | F3: 6666 | G3: 常规贴息低息12期 | H3: 临时拆分 公户方案 | I3: 临时拆分 公户方案 | J3: 双优贷2.0 | K3: 双优贷1.0 | L3: 1+4
B4: 全新GL8_ES 陆尊 | C4: 全新GL8 ES 陆尊 智享版 | D4: 个人申请：厂贴_5.99贴息 新优速贷/个体工商户升级 18期/24-60期 | E4: 无方案 | F4: 无方案 | G4: 无方案 | H4: 企业申请：厂贴_5.99贴息 新公牌易贷/个体工商户 18期/24-60期 企业商用：厂贴_5.99贴息 营运租赁 18期/24-36期 | I4: 无方案 | J4: 个人申请：厂贴_双优贷2.0_新优速贷_60期 | K4: 个人申请：厂贴_双优贷1.0_新优速贷_60期 | L4: 个人申请：厂贴_常规贴息_60期8万定额贷_1+4阶梯贷
C5: 全新GL8 ES 陆尊 尊享版 | D5: 个人申请：厂贴_5.99贴息 新优速贷/个体工商户升级 18期/24-60期 | E5: 无方案 | F5: 无方案 | G5: 无方案 | H5: 企业申请：厂贴_5.99贴息 新公牌易贷/个体工商户 18期/24-60期 企业商用：厂贴_5.99贴息 营运租赁 18期/24-36期 | I5: 无方案 | J5: 个人申请：厂贴_双优贷2.0_新优速贷_60期 | K5: 个人申请：厂贴_双优贷1.0_新优速贷_60期 | L5: 个人申请：厂贴_常规贴息_60期8万定额贷_1+4阶梯贷
B6: GL8陆尊燃油版 | C6: GL8陆尊燃油版 智享版 | D6: 个人申请：厂贴_5.99贴息 新优速贷/个体工商户升级 18期/24-60期 | E6: 无方案 | F6: 无方案 | G6: 无方案 | H6: 企业申请：厂贴_5.99贴息 新公牌易贷/个体工商户 18期/24-60期 企业商用：厂贴_5.99贴息 营运租赁 18期/24-36期 | I6: 无方案 | J6: 个人申请：厂贴_双优贷2.0_新优速贷_60期 | K6: 个人申请：厂贴_双优贷1.0_新优速贷_60期 | L6: 个人申请：厂贴_常规贴息_60期8万定额贷_1+4阶梯贷
C7: GL8陆尊燃油版 尊享版 | D7: 个人申请：厂贴_5.99贴息 新优速贷/个体工商户升级 18期/24-60期 | E7: 无方案 | F7: 无方案 | G7: 无方案 | H7: 企业申请：厂贴_5.99贴息 新公牌易贷/个体工商户 18期/24-60期 企业商用：厂贴_5.99贴息 营运租赁 18期/24-36期 | I7: 无方案 | J7: 个人申请：厂贴_双优贷2.0_新优速贷_60期 | K7: 个人申请：厂贴_双优贷1.0_新优速贷_60期 | L7: 个人申请：厂贴_常规贴息_60期8万定额贷_1+4阶梯贷
C8: GL8陆尊燃油版 奢享版 | D8: 个人申请：厂贴_5.99贴息 新优速贷/个体工商户升级 18期/24-60期 | E8: 无方案 | F8: 无方案 | G8: 无方案 | H8: 企业申请：厂贴_5.99贴息 新公牌易贷/个体工商户 18期/24-60期 企业商用：厂贴_5.99贴息 营运租赁 18期/24-36期 | I8: 无方案 | J8: 个人申请：厂贴_双优贷2.0_新优速贷_60期 | K8: 个人申请：厂贴_双优贷1.0_新优速贷_60期 | L8: 个人申请：厂贴_常规贴息_60期8万定额贷_1+4阶梯贷
B9: GL8 陆尊_PHEV | C9: GL8 陆尊 PHEV 智享版 新能源 | D9: 个人申请：厂贴_5.99贴息 新优速贷/个体工商户升级 24-60期 | E9: 无方案 | F9: 无方案 | G9: 无方案 | H9: 企业申请：厂贴_5.99贴息 新公牌易贷/个体工商户 24-60期 企业商用：厂贴_5.99贴息 营运租赁 24-36期 | I9: 无方案 | J9: 个人申请：厂贴_双优贷2.0_新优速贷_60期 | K9: 个人申请：厂贴_双优贷1.0_新优速贷_60期 | L9: 个人申请：厂贴_常规贴息_60期10万定额贷_1+4阶梯贷
C10: GL8 陆尊 PHEV 尊享版 新能源 | D10: 个人申请：厂贴_5.99贴息 新优速贷/个体工商户升级 24-60期 | E10: 无方案 | F10: 无方案 | G10: 无方案 | H10: 企业申请：厂贴_5.99贴息 新公牌易贷/个体工商户 24-60期 企业商用：厂贴_5.99贴息 营运租赁 24-36期 | I10: 无方案 | J10: 个人申请：厂贴_双优贷2.0_新优速贷_60期 | K10: 个人申请：厂贴_双优贷1.0_新优速贷_60期 | L10: 个人申请：厂贴_常规贴息_60期10万定额贷_1+4阶梯贷
C11: GL8 陆尊 PHEV 六座奢享版 新能源 | D11: 个人申请：厂贴_5.99贴息 新优速贷/个体工商户升级 24-60期 | E11: 无方案 | F11: 无方案 | G11: 无方案 | H11: 企业申请：厂贴_5.99贴息 新公牌易贷/个体工商户 24-60期 企业商用：厂贴_5.99贴息 营运租赁 24-36期 | I11: 无方案 | J11: 个人申请：厂贴_双优贷2.0_新优速贷_60期 | K11: 个人申请：厂贴_双优贷1.0_新优速贷_60期 | L11: 个人申请：厂贴_常规贴息_60期10万定额贷_1+4阶梯贷
C12: GL8 陆尊 PHEV 七座奢享版 新能源 | D12: 个人申请：厂贴_5.99贴息 新优速贷/个体工商户升级 24-60期 | E12: 无方案 | F12: 无方案 | G12: 无方案 | H12: 企业申请：厂贴_5.99贴息 新公牌易贷/个体工商户 24-60期 企业商用：厂贴_5.99贴息 营运租赁 24-36期 | I12: 无方案 | J12: 个人申请：厂贴_双优贷2.0_新优速贷_60期 | K12: 个人申请：厂贴_双优贷1.0_新优速贷_60期 | L12: 个人申请：厂贴_常规贴息_60期10万定额贷_1+4阶梯贷
B13: 全新GL8 陆尊 新能源 | C13: 全新GL8陆尊 智享版 新能源 | D13: 个人申请：厂贴_5.99贴息 新优速贷/个体工商户升级 18期/24-60期 | E13: 无方案 | F13: 无方案 | G13: 无方案 | H13: 企业申请：厂贴_5.99贴息 新公牌易贷/个体工商户 18期/24-60期 企业商用：厂贴_5.99贴息 营运租赁 18期/24-36期 | I13: 无方案 | J13: 个人申请：厂贴_双优贷2.0_新优速贷_60期 | K13: 个人申请：厂贴_双优贷1.0_新优速贷_60期 | L13: 个人申请：厂贴_常规贴息_60期8万定额贷_1+4阶梯贷
C14: 全新GL8陆尊 尊享版 新能源 | D14: 个人申请：厂贴_5.99贴息 新优速贷/个体工商户升级 18期/24-60期 | E14: 无方案 | F14: 无方案 | G14: 无方案 | H14: 企业申请：厂贴_5.99贴息 新公牌易贷/个体工商户 18期/24-60期 企业商用：厂贴_5.99贴息 营运租赁 18期/24-36期 | I14: 无方案 | J14: 个人申请：厂贴_双优贷2.0_新优速贷_60期 | K14: 个人申请：厂贴_双优贷1.0_新优速贷_60期 | L14: 个人申请：厂贴_常规贴息_60期8万定额贷_1+4阶梯贷
C15: 全新GL8陆尊 奢享版 新能源 | D15: 个人申请：厂贴_5.99贴息 新优速贷/个体工商户升级 18期/24-60期 | E15: 无方案 | F15: 无方案 | G15: 无方案 | H15: 企业申请：厂贴_5.99贴息 新公牌易贷/个体工商户 18期/24-60期 企业商用：厂贴_5.99贴息 营运租赁 18期/24-36期 | I15: 无方案 | J15: 个人申请：厂贴_双优贷2.0_新优速贷_60期 | K15: 个人申请：厂贴_双优贷1.0_新优速贷_60期 | L15: 个人申请：厂贴_常规贴息_60期8万定额贷_1+4阶梯贷
B16: GL8 陆尚_PHEV | C16: GL8 陆尚 尊享版 | D16: 个人申请：厂贴_5.99贴息 新优速贷/个体工商户升级 18期/24-60期 | E16: 无方案 | F16: 无方案 | G16: 无方案 | H16: 企业申请：厂贴_5.99贴息 新公牌易贷/个体工商户 18期/24-60期 企业商用：厂贴_5.99贴息 营运租赁 18期/24-36期 | I16: 无方案 | J16: 个人申请：厂贴_双优贷2.0_新优速贷_60期 | K16: 个人申请：厂贴_双优贷1.0_新优速贷_60期 | L16: 个人申请：厂贴_常规贴息_60期8万定额贷_1+4阶梯贷
C17: GL8 陆尚 智享版 | D17: 个人申请：厂贴_5.99贴息 新优速贷/个体工商户升级 18期/24-60期 | E17: 无方案 | F17: 无方案 | G17: 无方案 | H17: 企业申请：厂贴_5.99贴息 新公牌易贷/个体工商户 18期/24-60期 企业商用：厂贴_5.99贴息 营运租赁 18期/24-36期 | I17: 无方案 | J17: 个人申请：厂贴_双优贷2.0_新优速贷_60期 | K17: 个人申请：厂贴_双优贷1.0_新优速贷_60期 | L17: 个人申请：厂贴_常规贴息_60期8万定额贷_1+4阶梯贷
B18: 全新GL8陆上公务舱 | C18: 先享版 | D18: 个人申请：厂贴_5.99贴息 新优速贷/个体工商户升级 18期/24-60期 | E18: 无方案 | F18: 无方案 | G18: 无方案 | H18: 企业申请：厂贴_5.99贴息 新公牌易贷/个体工商户 18期/24-60期 企业商用：厂贴_5.99贴息 营运租赁 18期/24-36期 | I18: 无方案 | J18: 个人申请：厂贴_双优贷2.0_新优速贷_60期 | K18: 个人申请：厂贴_双优贷1.0_新优速贷_60期 | L18: 无方案
C19: 智享版 | D19: 个人申请：厂贴_5.99贴息 新优速贷/个体工商户升级 18期/24-60期 | E19: 无方案 | F19: 无方案 | G19: 无方案 | H19: 企业申请：厂贴_5.99贴息 新公牌易贷/个体工商户 18期/24-60期 企业商用：厂贴_5.99贴息 营运租赁 18期/24-36期 | I19: 无方案 | J19: 个人申请：厂贴_双优贷2.0_新优速贷_60期 | K19: 个人申请：厂贴_双优贷1.0_新优速贷_60期
C20: 福祉版 | D20: 个人申请：厂贴_5.99贴息 新优速贷/个体工商户升级 18期/24-60期 | E20: 无方案 | F20: 无方案 | G20: 无方案 | H20: 企业申请：厂贴_5.99贴息 新公牌易贷/个体工商户 18期/24-60期 企业商用：厂贴_5.99贴息 营运租赁 18期/24-36期 | I20: 无方案 | J20: 个人申请：厂贴_双优贷2.0_新优速贷_60期 | K20: 个人申请：厂贴_双优贷1.0_新优速贷_60期
C21: 智享DG-YZ版 | D21: 个人申请：厂贴_5.99贴息 新优速贷/个体工商户升级 18期/24-60期 | E21: 无方案 | F21: 无方案 | G21: 无方案 | H21: 企业申请：厂贴_5.99贴息 新公牌易贷/个体工商户 18期/24-60期 企业商用：厂贴_5.99贴息 营运租赁 18期/24-36期 | I21: 无方案 | J21: 无方案 | K21: 无方案
B22: 25款世纪 | C22: 25款世纪_4座私享版 | D22: 个人申请：厂贴_5.99贴息 新优速贷 18-60期 | E22: 无方案 | F22: 无方案 | G22: 个人申请：厂贴_5.99贴息 新优速贷 12期 | H22: 企业申请：厂贴_5.99贴息 新公牌易贷 18-60期 企业商用：厂贴_5.99贴息_营运租赁 18-36期 | I22: 企业申请：厂贴_5.99贴息 新公牌易贷 12期 企业商用：厂贴_5.99贴息_营运租赁 12期 | J22: 个人申请：厂贴_双优贷2.0_新优速贷_60期 | K22: 个人申请：厂贴_双优贷1.0_新优速贷_60期 | L22: 无方案
C23: 25款世纪 7座臻享版 | D23: 个人申请：厂贴_5.99贴息 新优速贷/个体工商户升级 18-60期 | E23: 无方案 | F23: 无方案 | G23: 个人申请：厂贴_5.99贴息 新优速贷/个体工商户升级 12期 | H23: 企业申请：厂贴_5.99贴息 新公牌易贷 18-60期 企业商用：厂贴_5.99贴息_营运租赁 18-36期 | I23: 企业申请：厂贴_5.99贴息 新公牌易贷 12期 企业商用：厂贴_5.99贴息_营运租赁 12期 | J23: 个人申请：厂贴_双优贷2.0_新优速贷_60期 | K23: 个人申请：厂贴_双优贷1.0_新优速贷_60期 | L23: 无方案
C24: 25款世纪_6座/7座蕴世版 | D24: 个人申请：厂贴_5.99贴息 新优速贷/个体工商户升级 18-60期 | E24: 无方案 | F24: 无方案 | G24: 个人申请：厂贴_5.99贴息 新优速贷/个体工商户升级 12期 | H24: 企业申请：厂贴_5.99贴息 新公牌易贷 18-60期 企业商用：厂贴_5.99贴息_营运租赁 18-36期 | I24: 企业申请：厂贴_5.99贴息 新公牌易贷 12期 企业商用：厂贴_5.99贴息_营运租赁 12期 | J24: 个人申请：厂贴_双优贷2.0_新优速贷_60期 | K24: 个人申请：厂贴_双优贷1.0_新优速贷_60期 | L24: 无方案
B25: 至境L7 | C25: 至境L7 尊享版 增程式 新能源 | D25: 个人申请：厂贴_5.99贴息 新优速贷/个体工商户升级 18期/24-60期 | E25: 无方案 | F25: 无方案 | G25: 无方案 | H25: 企业申请：厂贴_5.99贴息 新公牌易贷/个体工商户 18期/24-60期 企业商用：厂贴_5.99贴息 营运租赁 18期/24-36期 | I25: 无方案 | J25: 个人申请：厂贴_双优贷2.0_新优速贷_60期 | K25: 个人申请：厂贴_双优贷1.0_新优速贷_60期 | L25: 无方案
C26: 至境L7 奢享版 增程式 新能源 | D26: 个人申请：厂贴_5.99贴息 新优速贷/个体工商户升级 18期/24-60期 | E26: 无方案 | F26: 无方案 | G26: 无方案 | H26: 企业申请：厂贴_5.99贴息 新公牌易贷/个体工商户 18期/24-60期 企业商用：厂贴_5.99贴息 营运租赁 18期/24-36期 | I26: 无方案 | J26: 个人申请：厂贴_双优贷2.0_新优速贷_60期 | K26: 个人申请：厂贴_双优贷1.0_新优速贷_60期 | L26: 无方案
C27: 至境L7 尊享逍遥智行版 增程式 新能源 | D27: 个人申请：厂贴_5.99贴息 新优速贷/个体工商户升级 18期/24-60期 | E27: 无方案 | F27: 无方案 | G27: 无方案 | H27: 企业申请：厂贴_5.99贴息 新公牌易贷/个体工商户 18期/24-60期 企业商用：厂贴_5.99贴息 营运租赁 18期/24-36期 | I27: 无方案 | J27: 个人申请：厂贴_双优贷2.0_新优速贷_60期 | K27: 个人申请：厂贴_双优贷1.0_新优速贷_60期 | L27: 无方案
C28: 至境L7 奢享逍遥智行版 增程式 新能源 | D28: 个人申请：厂贴_5.99贴息 新优速贷/个体工商户升级 18期/24-60期 | E28: 无方案 | F28: 无方案 | G28: 无方案 | H28: 企业申请：厂贴_5.99贴息 新公牌易贷/个体工商户 18期/24-60期 企业商用：厂贴_5.99贴息 营运租赁 18期/24-36期 | I28: 无方案 | J28: 个人申请：厂贴_双优贷2.0_新优速贷_60期 | K28: 个人申请：厂贴_双优贷1.0_新优速贷_60期 | L28: 无方案
C29: 至境L7 艾维亚 增程式 新能源 | D29: 个人申请：厂贴_5.99贴息 新优速贷/个体工商户升级 18期/24-60期 | E29: 无方案 | F29: 无方案 | G29: 无方案 | H29: 企业申请：厂贴_5.99贴息 新公牌易贷/个体工商户 18期/24-60期 企业商用：厂贴_5.99贴息 营运租赁 18期/24-36期 | I29: 无方案 | J29: 个人申请：厂贴_双优贷2.0_新优速贷_60期 | K29: 个人申请：厂贴_双优贷1.0_新优速贷_60期 | L29: 无方案
C30: 至境L7 艾维亚(20) 增程式 新能源 | D30: 个人申请：厂贴_5.99贴息 新优速贷/个体工商户升级 18期/24-60期 | E30: 无方案 | F30: 无方案 | G30: 无方案 | H30: 企业申请：厂贴_5.99贴息 新公牌易贷/个体工商户 18期/24-60期 企业商用：厂贴_5.99贴息 营运租赁 18期/24-36期 | I30: 无方案 | J30: 个人申请：厂贴_双优贷2.0_新优速贷_60期 | K30: 个人申请：厂贴_双优贷1.0_新优速贷_60期 | L30: 无方案
B31: 至境世家 | C31: 至境世家尊享版 新能源 | D31: 个人申请：厂贴_5.99贴息 新优速贷/个体工商户升级 36-60期 | H31: 企业申请：厂贴_5.99贴息 新公牌易贷/个体工商户 36-60期 企业商用：厂贴_5.99贴息 营运租赁 36期 | I31: 企业申请：厂贴_5.99贴息 新公牌易贷/个体工商户 18期 企业商用：厂贴_5.99贴息 营运租赁 18期 | J31: 个人申请：厂贴_双优贷2.0_新优速贷_60期 | K31: 个人申请：厂贴_双优贷1.0_新优速贷_60期 | L31: 无方案
C32: 至境世家奢享版 新能源 | D32: 个人申请：厂贴_5.99贴息 新优速贷/个体工商户升级 36-60期 | H32: 企业申请：厂贴_5.99贴息 新公牌易贷/个体工商户 36-60期 企业商用：厂贴_5.99贴息 营运租赁 36期 | I32: 企业申请：厂贴_5.99贴息 新公牌易贷 18期 企业商用：厂贴_5.99贴息 营运租赁 18期 | J32: 个人申请：厂贴_双优贷2.0_新优速贷_60期 | K32: 个人申请：厂贴_双优贷1.0_新优速贷_60期 | L32: 无方案
C33: 至境世家 纯电奢享版 | D33: 个人申请：厂贴_5.99贴息 新优速贷/个体工商户升级 36-60期 | H33: 企业申请：厂贴_5.99贴息 新公牌易贷/个体工商户 36-60期 企业商用：厂贴_5.99贴息 营运租赁 36期 | I33: 企业申请：厂贴_5.99贴息 新公牌易贷 18期 企业商用：厂贴_5.99贴息 营运租赁 18期 | J33: 个人申请：厂贴_双优贷2.0_新优速贷_60期 | K33: 个人申请：厂贴_双优贷1.0_新优速贷_60期 | L33: 无方案
C34: 至境世家 纯电奢享版哑光灰 | D34: 个人申请：厂贴_5.99贴息 新优速贷/个体工商户升级 36-60期 | H34: 企业申请：厂贴_5.99贴息 新公牌易贷/个体工商户 36-60期 企业商用：厂贴_5.99贴息 营运租赁 36期 | I34: 企业申请：厂贴_5.99贴息 新公牌易贷 18期 企业商用：厂贴_5.99贴息 营运租赁 18期 | J34: 个人申请：厂贴_双优贷2.0_新优速贷_60期 | K34: 个人申请：厂贴_双优贷1.0_新优速贷_60期 | L34: 无方案
B35: 昂科威Plus | C35: 昂科威Plus 28T 白金版 | D35: 个人申请：厂贴_5.99贴息 新优速贷/个体工商户升级 18期/24-60期 | E35: 个人申请：厂贴_5.99贴息_5050_12期 | F35: 个人申请：厂贴_5.99贴息_6666_24期9万定额贷 | G35: 无方案 | H35: 企业申请：厂贴_5.99贴息 新公牌易贷/个体工商户 18期/24-60期 企业商用：厂贴_5.99贴息 营运租赁 18期/24-36期 | I35: 无方案 | J35: 个人申请：厂贴_双优贷2.0_新优速贷_60期 | K35: 个人申请：厂贴_双优贷1.0_新优速贷_60期 | L35: 无方案
C36: 昂科威Plus 28T 四驱白金版 | D36: 个人申请：厂贴_5.99贴息 新优速贷/个体工商户升级 18期/24-60期 | E36: 个人申请：厂贴_5.99贴息_5050_12期 | F36: 个人申请：厂贴_5.99贴息_6666_24期9万定额贷 | G36: 无方案 | H36: 企业申请：厂贴_5.99贴息 新公牌易贷/个体工商户 18期/24-60期 企业商用：厂贴_5.99贴息 营运租赁 18期/24-36期 | I36: 无方案 | J36: 个人申请：厂贴_双优贷2.0_新优速贷_60期 | K36: 个人申请：厂贴_双优贷1.0_新优速贷_60期 | L36: 无方案
C37: 昂科威Plus 艾维亚 | D37: 个人申请：厂贴_5.99贴息 新优速贷/个体工商户升级 18期/24-60期 | E37: 个人申请：厂贴_5.99贴息_5050_12期 | F37: 个人申请：厂贴_5.99贴息_6666_24期9万定额贷 | G37: 无方案 | H37: 企业申请：厂贴_5.99贴息 新公牌易贷/个体工商户 18期/24-60期 企业商用：厂贴_5.99贴息 营运租赁 18期/24-36期 | I37: 无方案 | J37: 个人申请：厂贴_双优贷2.0_新优速贷_60期 | K37: 个人申请：厂贴_双优贷1.0_新优速贷_60期 | L37: 无方案
B38: 昂科威S | C38: 昂科威S 25T 白金版 | D38: 个人申请：厂贴_5.99贴息 新优速贷/个体工商户升级 18期/24-60期 | E38: 个人申请：厂贴_5.99贴息_5050_12期 | F38: 个人申请：厂贴_5.99贴息_6666_24期9万定额贷 | G38: 无方案 | H38: 企业申请：厂贴_5.99贴息 新公牌易贷/个体工商户 18期/24-60期 企业商用：厂贴_5.99贴息 营运租赁 18期/24-36期 | I38: 无方案 | J38: 个人申请：厂贴_双优贷2.0_新优速贷_60期 | K38: 个人申请：厂贴_双优贷1.0_新优速贷_60期 | L38: 无方案
C39: 昂科威S 25T 先锋版 | D39: 个人申请：厂贴_5.99贴息 新优速贷/个体工商户升级 18期/24-60期 | E39: 个人申请：厂贴_5.99贴息_5050_12期 | F39: 个人申请：厂贴_5.99贴息_6666_24期9万定额贷 | G39: 无方案 | H39: 企业申请：厂贴_5.99贴息 新公牌易贷/个体工商户 18期/24-60期 企业商用：厂贴_5.99贴息 营运租赁 18期/24-36期 | I39: 无方案 | J39: 个人申请：厂贴_双优贷2.0_新优速贷_60期 | K39: 个人申请：厂贴_双优贷1.0_新优速贷_60期 | L39: 无方案
C40: 昂科威S 25T 炫黑风尚版 | D40: 个人申请：厂贴_5.99贴息 新优速贷/个体工商户升级 18期/24-60期 | E40: 个人申请：厂贴_5.99贴息_5050_12期 | F40: 个人申请：厂贴_5.99贴息_6666_24期9万定额贷 | G40: 无方案 | H40: 企业申请：厂贴_5.99贴息 新公牌易贷/个体工商户 18期/24-60期 企业商用：厂贴_5.99贴息 营运租赁 18期/24-36期 | I40: 无方案 | J40: 个人申请：厂贴_双优贷2.0_新优速贷_60期 | K40: 个人申请：厂贴_双优贷1.0_新优速贷_60期 | L40: 无方案
C41: 昂科威S 25T 进享白金版 | D41: 个人申请：厂贴_5.99贴息 新优速贷/个体工商户升级 18期/24-60期 | E41: 个人申请：厂贴_5.99贴息_5050_12期 | F41: 个人申请：厂贴_5.99贴息_6666_24期9万定额贷 | G41: 无方案 | H41: 企业申请：厂贴_5.99贴息 新公牌易贷/个体工商户 18期/24-60期 企业商用：厂贴_5.99贴息 营运租赁 18期/24-36期 | I41: 无方案 | J41: 个人申请：厂贴_双优贷2.0_新优速贷_60期 | K41: 个人申请：厂贴_双优贷1.0_新优速贷_60期 | L41: 无方案
...

Sheet 参数-车系车型 利率
D1: 5050车系 | I1: 阶梯贷车系参数 | M1: 厂贴双优贷车系参数 | P1: 车系参数 | Q1: 最低首付比例 | R1: 智慧贷 | U1: 至境L7 | V1: 陆尚 PHEV | W1: _25款世纪 | X1: 陆尊 ES | Y1: 陆尊_PHEV | Z1: 微蓝6_450KM | AA1: 威朗Pro | AB1: 全新GL8陆上公务舱 | AC1: 昂科威Plus | AD1: 昂科威S | AE1: 君越 | AF1: 新君威 | AG1: 全新GL8 陆尊 新能源 | AH1: GL8陆尊燃油版 | AI1: 至境世家
A2: 常规贴息 | D2: 昂科威Plus | E2: 0.2 | I2: 全新GL8_陆尊_新能源 | M2: GL8陆尊燃油版 | N2: 0.2 | P2: 全新GL8_陆尊_新能源 | Q2: 0.15 | R2: 0.2 | U2: 至境L7 尊享版 增程式 新能源 | V2: GL8 陆尚 智享版 | W2: 25款世纪 7座臻享版 | X2: 全新GL8 ES 陆尊 智享版 | Y2: GL8 陆尊 PHEV 智享版 新能源 | Z2: 微蓝6 450KM舒享PLUS版 纯电动 新能源 | AA2: 威朗Pro 乐行版 | AB2: 先享版 | AC2: 昂科威Plus 28T 白金版 | AD2: 昂科威S 25T 白金版 | AE2: 君越 28T 白金版 | AF2: 新君威 25T 超享版 | AG2: 全新GL8陆尊 智享版 新能源 | AH2: GL8陆尊燃油版 智享版 | AI2: 至境世家尊享版 新能源
A3: 0.0723 | D3: 昂科威S | E3: 0.2 | I3: GL8陆尊燃油版 | M3: 全新GL8_陆尊_新能源 | N3: 0.15 | P3: 全新GL8陆上公务舱 | Q3: 0.2 | R3: 0.2 | U3: 至境L7 奢享版 增程式 新能源 | V3: GL8 陆尚 尊享版 | W3: 25款世纪_6座/7座蕴世版 | X3: 全新GL8 ES 陆尊 尊享版 | Y3: GL8 陆尊 PHEV 尊享版 新能源 | Z3: 微蓝6 450KM越享PLUS版 纯电动 新能源 | AA3: 威朗Pro 乐享版 | AB3: 智享版 | AC3: 昂科威Plus 28T 四驱白金版 | AD3: 昂科威S 25T 进享白金版 | AE3: 君越 白金版艾维亚 | AF3: 新君威 28T 纵享版 | AG3: 全新GL8陆尊 尊享版 新能源 | AH3: GL8陆尊燃油版 尊享版 | AI3: 至境世家奢享版 新能源
